Workbook

Sheet Valuation
B2: lululemon athletica inc. (NASDAQ: LULU) | E2: Lululemon | F2: Fiscal years ending nearest Jan. 31 / early Feb.; USD millions except per-share data | K2: Forecast
B3: Model date | C3: 2026-05-27 | F3: FY2021 | G3: FY2022 | H3: FY2023 | I3: FY2024 | J3: FY2025 | K3: FY2026 | L3: FY2027 | M3: FY2028 | N3: FY2029 | O3: FY2030 | P3: FY2031 | Q3: FY2032 | R3: FY2033 | S3: FY2034 | T3: FY2035
B4: Price | C4: 131.88 | E4: Revenue | F4: 6256.617 | G4: 8110.518 | H4: 9619.278 | I4: 10588.126 | J4: 11102.6 | K4: =J4*(1+K5) -> 0 | L4: =K4*(1+L5) -> 0 | M4: =L4*(1+M5) -> 0 | N4: =M4*(1+N5) -> 0 | O4: =N4*(1+O5) -> 0 | P4: =O4*(1+P5) -> 0 | Q4: =P4*(1+Q5) -> 0 | R4: =Q4*(1+R5) -> 0 | ... T4: =S4*(1+T5) -> 0
B5: Quote date | C5: 2026-05-27 9:35 AM EDT - market open | E5: Revenue Growth | G5: =G4/F4-1 -> 0 | H5: =H4/G4-1 -> 0 | I5: =I4/H4-1 -> 0 | J5: =J4/I4-1 -> 0 | K5: 0.029 | L5: 0.04 | M5: 0.05 | N5: 0.05 | O5: 0.045 | P5: 0.04 | Q5: 0.035 | R5: 0.03 | S5: 0.028 | T5: 0.025
B6: Current shares, mm | C6: 114.43 | E6: Cost of Revenue | F6: 2648.052 | G6: 3618.178 | H6: 4009.873 | I6: 4317.315 | J6: 4818.468 | K6: =K4-K8 -> 0 | L6: =L4-L8 -> 0 | M6: =M4-M8 -> 0 | N6: =N4-N8 -> 0 | O6: =O4-O8 -> 0 | P6: =P4-P8 -> 0 | Q6: =Q4-Q8 -> 0 | R6: =R4-R8 -> 0 | ... T6: =T4-T8 -> 0
B7: Market cap, $m | C7: =C4*C6 -> 0 | E7: Gross Margin | F7: =F8/F4 -> 0 | G7: =G8/G4 -> 0 | H7: =H8/H4 -> 0 | I7: =I8/I4 -> 0 | J7: =J8/J4 -> 0 | K7: 0.55 | L7: 0.555 | M7: 0.56 | N7: 0.565 | O7: 0.57 | P7: 0.573 | Q7: 0.575 | R7: 0.576 | S7: 0.577 | T7: 0.578
B8: Cash + restricted cash, $m | C8: 1807.202 | E8: Gross Profit | F8: 3608.565 | G8: 4492.34 | H8: 5609.405 | I8: 6270.811 | J8: 6284.132 | K8: =K4*K7 -> 0 | L8: =L4*L7 -> 0 | M8: =M4*M7 -> 0 | N8: =N4*N7 -> 0 | O8: =O4*O7 -> 0 | P8: =P4*P7 -> 0 | Q8: =Q4*Q7 -> 0 | R8: =R4*R7 -> 0 | ... T8: =T4*T7 -> 0
B9: Financial debt, $m | C9: 0 | E9: SG&A | F9: 2225.034 | G9: 2757.447 | H9: 3397.218 | I9: 3762.379 | J9: 4066.556 | K9: =K8-K11 -> 0 | L9: =L8-L11 -> 0 | M9: =M8-M11 -> 0 | N9: =N8-N11 -> 0 | O9: =O8-O11 -> 0 | P9: =P8-P11 -> 0 | Q9: =Q8-Q11 -> 0 | R9: =R8-R11 -> 0 | ... T9: =T8-T11 -> 0
B10: Operating lease liabilities, $m | C10: 1798.441 | E10: Operating Margin | F10: =F11/F4 -> 0 | G10: =G11/G4 -> 0 | H10: =H11/H4 -> 0 | I10: =I11/I4 -> 0 | J10: =J11/J4 -> 0 | K10: 0.18 | L10: 0.188 | M10: 0.195 | N10: 0.202 | O10: 0.207 | P10: 0.211 | Q10: 0.213 | R10: 0.214 | S10: 0.215 | T10: 0.215
B11: Enterprise value incl. leases, $m | C11: =C7+C9+C10-C8 -> 0 | E11: Operating Income | F11: 1333.355 | G11: 1328.408 | H11: 2132.676 | I11: 2505.697 | J11: 2210.615 | K11: =K4*K10 -> 0 | L11: =L4*L10 -> 0 | M11: =M4*M10 -> 0 | N11: =N4*N10 -> 0 | O11: =O4*O10 -> 0 | P11: =P4*P10 -> 0 | Q11: =Q4*Q10 -> 0 | R11: =R4*R10 -> 0 | ... T11: =T4*T10 -> 0
B12: StockAnalysis market cap, $m | C12: 15140 | E12: Pretax Income | F12: 1333.869 | G12: 1332.571 | H12: 2175.735 | I12: 2576.077 | J12: 2238.967 | K12: =K11 -> 0 | L12: =L11 -> 0 | M12: =M11 -> 0 | N12: =N11 -> 0 | O12: =O11 -> 0 | P12: =P11 -> 0 | Q12: =Q11 -> 0 | R12: =R11 -> 0 | ... T12: =T11 -> 0
B13: SEC common shares outstanding, mm | C13: 110.483 | E13: Tax Rate | F13: =F14/F12 -> 0 | G13: =G14/G12 -> 0 | H13: =H14/H12 -> 0 | I13: =I14/I12 -> 0 | J13: =J14/J12 -> 0 | K13: 0.295 | L13: 0.295 | M13: 0.295 | N13: 0.295 | O13: 0.295 | P13: 0.295 | Q13: 0.295 | R13: 0.295 | S13: 0.295 | T13: 0.295
B14: Diluted avg shares FY2025, mm | C14: 119.068 | E14: Income Tax Expense | F14: 358.547 | G14: 477.771 | H14: 625.545 | I14: 761.461 | J14: 659.784 | K14: =K12*K13 -> 0 | L14: =L12*L13 -> 0 | M14: =M12*M13 -> 0 | N14: =N12*N13 -> 0 | O14: =O12*O13 -> 0 | P14: =P12*P13 -> 0 | Q14: =Q12*Q13 -> 0 | R14: =R12*R13 -> 0 | ... T14: =T12*T13 -> 0
B15: Market data note | C15: StockAnalysis current quote/shares; SEC common-share count excludes dilution and differs from market-data share basis. | E15: Net Margin | F15: =F16/F4 -> 0 | G15: =G16/G4 -> 0 | H15: =H16/H4 -> 0 | I15: =I16/I4 -> 0 | J15: =J16/J4 -> 0 | K15: =K16/K4 -> 0 | L15: =L16/L4 -> 0 | M15: =M16/M4 -> 0 | ... T15: =T16/T4 -> 0
E16: Net Income | F16: 975.322 | G16: 854.8 | H16: 1550.19 | I16: 1814.616 | J16: 1579.183 | K16: =K12-K14 -> 0 | L16: =L12-L14 -> 0 | M16: =M12-M14 -> 0 | N16: =N12-N14 -> 0 | O16: =O12-O14 -> 0 | P16: =P12-P14 -> 0 | Q16: =Q12-Q14 -> 0 | R16: =R12-R14 -> 0 | ... T16: =T12-T14 -> 0
E17: Diluted EPS | F17: 7.49 | G17: 6.68 | H17: 12.2 | I17: 14.64 | J17: 13.26 | K17: =K16/K18 -> 0 | L17: =L16/L18 -> 0 | M17: =M16/M18 -> 0 | N17: =N16/N18 -> 0 | O17: =O16/O18 -> 0 | P17: =P16/P18 -> 0 | Q17: =Q16/Q18 -> 0 | R17: =R16/R18 -> 0 | ... T17: =T16/T18 -> 0
E18: Diluted Shares | F18: 130.295 | G18: 128.017 | H18: 127.06 | I18: 123.935 | J18: 119.068 | K18: =J18*0.985 -> 0 | L18: =K18*0.985 -> 0 | M18: =L18*0.985 -> 0 | N18: =M18*0.985 -> 0 | O18: =N18*0.985 -> 0 | P18: =O18*0.985 -> 0 | Q18: =P18*0.985 -> 0 | R18: =Q18*0.985 -> 0 | ... T18: =S18*0.985 -> 0
E19: Cash + Restricted Cash | F19: 1259.871 | G19: 1154.867 | H19: 2243.971 | I19: 1984.336 | J19: 1807.202 | K19: =J19 -> 0 | L19: =J19 -> 0 | M19: =J19 -> 0 | N19: =J19 -> 0 | O19: =J19 -> 0 | P19: =J19 -> 0 | Q19: =J19 -> 0 | R19: =J19 -> 0 | S19: =J19 -> 0 | T19: =J19 -> 0
E20: Inventory | F20: 966.481 | G20: 1447.367 | H20: 1323.602 | I20: 1442.081 | J20: 1700.753 | K20: =K4*0.145 -> 0 | L20: =L4*0.145 -> 0 | M20: =M4*0.145 -> 0 | N20: =N4*0.145 -> 0 | O20: =O4*0.145 -> 0 | P20: =P4*0.145 -> 0 | Q20: =Q4*0.145 -> 0 | R20: =R4*0.145 -> 0 | ... T20: =T4*0.145 -> 0
E21: Financial Debt | F21: 0 | G21: 0 | H21: 0 | I21: 0 | J21: 0 | K21: =C9 -> 0 | L21: =C9 -> 0 | M21: =C9 -> 0 | N21: =C9 -> 0 | O21: =C9 -> 0 | P21: =C9 -> 0 | Q21: =C9 -> 0 | R21: =C9 -> 0 | S21: =C9 -> 0 | T21: =C9 -> 0
E22: Operating Lease Liability | F22: 881.052 | G22: 1070.334 | H22: 1403.282 | I22: 1575.791 | J22: 1798.441 | K22: =C10 -> 0 | L22: =C10 -> 0 | M22: =C10 -> 0 | N22: =C10 -> 0 | O22: =C10 -> 0 | P22: =C10 -> 0 | Q22: =C10 -> 0 | R22: =C10 -> 0 | S22: =C10 -> 0 | T22: =C10 -> 0
E23: Stockholders Equity | F23: 2740.046 | G23: 3148.799 | H23: 4232.081 | I23: 4324.047 | J23: 4961.84 | K23: =J23 -> 0 | L23: =J23 -> 0 | M23: =J23 -> 0 | N23: =J23 -> 0 | O23: =J23 -> 0 | P23: =J23 -> 0 | Q23: =J23 -> 0 | R23: =J23 -> 0 | S23: =J23 -> 0 | T23: =J23 -> 0
E24: Operating Cash Flow | F24: 1389.108 | G24: 966.463 | H24: 2296.164 | I24: 2272.713 | J24: 1602.477 | K24: =K27+K25 -> 0 | L24: =L27+L25 -> 0 | M24: =M27+M25 -> 0 | N24: =N27+N25 -> 0 | O24: =O27+O25 -> 0 | P24: =P27+P25 -> 0 | Q24: =Q27+Q25 -> 0 | R24: =R27+R25 -> 0 | ... T24: =T27+T25 -> 0
E25: Capex | F25: 394.502 | G25: 638.657 | H25: 651.865 | I25: 689.232 | J25: 680.802 | K25: =K4*0.060 -> 0 | L25: =L4*0.060 -> 0 | M25: =M4*0.060 -> 0 | N25: =N4*0.060 -> 0 | O25: =O4*0.060 -> 0 | P25: =P4*0.060 -> 0 | Q25: =Q4*0.060 -> 0 | R25: =R4*0.060 -> 0 | ... T25: =T4*0.060 -> 0
E26: FCF Margin | F26: =F27/F4 -> 0 | G26: =G27/G4 -> 0 | H26: =H27/H4 -> 0 | I26: =I27/I4 -> 0 | J26: =J27/J4 -> 0 | K26: 0.095 | L26: 0.105 | M26: 0.115 | N26: 0.125 | O26: 0.13 | P26: 0.133 | Q26: 0.135 | R26: 0.137 | S26: 0.138 | T26: 0.14
E27: Free Cash Flow | F27: 994.606 | G27: 327.806 | H27: 1644.299 | I27: 1583.481 | J27: 921.675 | K27: =K4*K26 -> 0 | L27: =L4*L26 -> 0 | M27: =M4*M26 -> 0 | N27: =N4*N26 -> 0 | O27: =O4*O26 -> 0 | P27: =P4*P26 -> 0 | Q27: =Q4*Q26 -> 0 | R27: =R4*R26 -> 0 | ... T27: =T4*T26 -> 0
E28: SBC | F28: 69.137 | G28: 78.075 | H28: 93.56 | I28: 90.011 | J28: 62.203 | K28: =K4*0.006 -> 0 | L28: =L4*0.006 -> 0 | M28: =M4*0.006 -> 0 | N28: =N4*0.006 -> 0 | O28: =O4*0.006 -> 0 | P28: =P4*0.006 -> 0 | Q28: =Q4*0.006 -> 0 | R28: =R4*0.006 -> 0 | ... T28: =T4*0.006 -> 0
E29: D&A | F29: 224.206 | G29: 291.791 | H29: 379.384 | I29: 446.524 | J29: 496.228 | K29: =K4*0.045 -> 0 | L29: =L4*0.045 -> 0 | M29: =M4*0.045 -> 0 | N29: =N4*0.045 -> 0 | O29: =O4*0.045 -> 0 | P29: =P4*0.045 -> 0 | Q29: =Q4*0.045 -> 0 | R29: =R4*0.045 -> 0 | ... T29: =T4*0.045 -> 0
E32: Valuation Outputs
E33: EV / Revenue FY2025 | F33: =C11/J4 -> 0
E34: EV / EBIT FY2025 | F34: =C11/J11 -> 0
E35: EV / FCF FY2025 | F35: =C11/J27 -> 0
E36: P / E FY2025 | F36: =C4/J17 -> 0
E37: Base DCF implied price | F37: ='Scenarios'!C5 -> 0
E38: Base DCF 10Y price CAGR | F38: ='Scenarios'!D5 -> 0
E39: Margin of safety / (premium) | F39: ='Scenarios'!C5/C4-1 -> 0
E40: Reverse check | F40: Current quote requires roughly base-case recovery in FCF margins, not just FY2026 guide stabilization.
E42: Forecast framing
E43: FY2026 revenue starts at the midpoint of management guide: $11.35B-$11.50B.
E44: Base case assumes Americas stabilizes, international remains the growth engine, gross margin recovers gradually after tariff/de minimis pressure, and FCF margin normalizes to 14.0% by FY2035.
...

Sheet WACC
A1: WACC / Required Return Inputs
A2: Risk-free rate | B2: 0.0456 | C2: FRED DGS10 / public U.S. 10-year Treasury cross-check near model date; using 4.56% rounded official close input.
A3: Equity risk premium | B3: 0.05 | C3: Rounded U.S. ERP assumption; consistent with common Damodaran/Kroll-style public ERP framing for 2026.
A4: Beta | B4: 0.9 | C4: StockAnalysis current beta snapshot.
A5: Company-specific risk premium | B5: 0.01 | C5: Judgmental premium for Americas product reset, tariff/de minimis uncertainty, and category fragmentation.
A6: Cost of equity | B6: =B2+B3*B4+B5 -> 0 | C6: CAPM plus company-specific premium.
A7: Pre-tax debt/lease cost | B7: 0.0525 | C7: No financial debt; cost assigned to operating lease liability / debt-like store obligations.
A8: Tax rate | B8: 0.295 | C8: Normalized near FY2025 effective tax rate; management guided FY2026 Q1 tax pressure higher, but base model normalizes.
A9: After-tax debt/lease cost | B9: =B7*(1-B8) -> 0 | C9: Formula.
A10: Market cap | B10: =Valuation!C7 -> 0 | C10: Price x current shares from StockAnalysis current snapshot.
A11: Debt + leases | B11: =Valuation!C9+Valuation!C10 -> 0 | C11: Financial debt plus operating lease liabilities.
A12: Equity weight | B12: =B10/(B10+B11) -> 0 | C12: Formula.
A13: Debt/lease weight | B13: =B11/(B10+B11) -> 0 | C13: Formula.
A14: WACC / required return | B14: =B12*B6+B13*B9 -> 0 | C14: Used as cross-check; scenarios round discount rates around this output.
A15: Base scenario discount rate | B15: 0.1 | C15: Rounded required return used in base DCF.

Sheet Scenarios
B2: Bull / Base / Bear Scenario DCFs
B3: Scenario | C3: Implied Price | D3: 10Y Price CAGR | E3: FY2026 Rev Growth | F3: 10Y Rev CAGR | G3: Terminal FCF Margin | H3: Discount Rate | I3: Terminal Growth | J3: Notes
B4: Bear | C4: =C28 -> 0 | D4: =C29 -> 0 | E4: =D11 -> 0 | F4: =(M12/D12)^(1/9)-1 -> 0 | G4: =M16 -> 0 | H4: =C21 -> 0 | I4: =C22 -> 0 | J4: Americas stays weak, tariffs/dupes pressure gross margin, inventory cash drag persists.
B5: Base | C5: =C50 -> 0 | D5: =C51 -> 0 | E5: =D33 -> 0 | F5: =(M34/D34)^(1/9)-1 -> 0 | G5: =M38 -> 0 | H5: =C43 -> 0 | I5: =C44 -> 0 | J5: FY2026 starts at management guide midpoint; Americas stabilizes and margins partially recover.
B6: Bull | C6: =C72 -> 0 | D6: =C73 -> 0 | E6: =D55 -> 0 | F6: =(M56/D56)^(1/9)-1 -> 0 | G6: =M60 -> 0 | H6: =C65 -> 0 | I6: =C66 -> 0 | J6: Product cadence improves, international remains strong, and normalized FCF margin returns to pre-reset levels.
B9: Bear Scenario
B10: Metric | D10: FY2026 | E10: FY2027 | F10: FY2028 | G10: FY2029 | H10: FY2030 | I10: FY2031 | J10: FY2032 | K10: FY2033 | L10: FY2034 | M10: FY2035
B11: Revenue Growth | D11: 0.01 | E11: 0.015 | F11: 0.025 | G11: 0.03 | H11: 0.03 | I11: 0.03 | J11: 0.025 | K11: 0.022 | L11: 0.02 | M11: 0.02
B12: Revenue | D12: =Valuation!J4*(1+D11) -> 0 | E12: =D12*(1+E11) -> 0 | F12: =E12*(1+F11) -> 0 | G12: =F12*(1+G11) -> 0 | H12: =G12*(1+H11) -> 0 | I12: =H12*(1+I11) -> 0 | J12: =I12*(1+J11) -> 0 | K12: =J12*(1+K11) -> 0 | L12: =K12*(1+L11) -> 0 | M12: =L12*(1+M11) -> 0
B13: Gross Margin | D13: 0.535 | E13: 0.538 | F13: 0.542 | G13: 0.545 | H13: 0.548 | I13: 0.55 | J13: 0.55 | K13: 0.55 | L13: 0.55 | M13: 0.55
B14: Operating Margin | D14: 0.16 | E14: 0.162 | F14: 0.168 | G14: 0.172 | H14: 0.175 | I14: 0.176 | J14: 0.176 | K14: 0.176 | L14: 0.176 | M14: 0.176
B15: Operating Income | D15: =D12*D14 -> 0 | E15: =E12*E14 -> 0 | F15: =F12*F14 -> 0 | G15: =G12*G14 -> 0 | H15: =H12*H14 -> 0 | I15: =I12*I14 -> 0 | J15: =J12*J14 -> 0 | K15: =K12*K14 -> 0 | ... M15: =M12*M14 -> 0
B16: FCF Margin | D16: 0.07 | E16: 0.075 | F16: 0.085 | G16: 0.092 | H16: 0.097 | I16: 0.1 | J16: 0.1 | K16: 0.1 | L16: 0.1 | M16: 0.1
B17: Free Cash Flow | D17: =D12*D16 -> 0 | E17: =E12*E16 -> 0 | F17: =F12*F16 -> 0 | G17: =G12*G16 -> 0 | H17: =H12*H16 -> 0 | I17: =I12*I16 -> 0 | J17: =J12*J16 -> 0 | K17: =K12*K16 -> 0 | ... M17: =M12*M16 -> 0
B18: Discount Factor | D18: =1/(1+$C$21)^1 -> 0 | E18: =1/(1+$C$21)^2 -> 0 | F18: =1/(1+$C$21)^3 -> 0 | G18: =1/(1+$C$21)^4 -> 0 | H18: =1/(1+$C$21)^5 -> 0 | I18: =1/(1+$C$21)^6 -> 0 | J18: =1/(1+$C$21)^7 -> 0 | K18: =1/(1+$C$21)^8 -> 0 | L18: =1/(1+$C$21)^9 -> 0 | M18: =1/(1+$C$21)^10 -> 0
B19: PV of FCF | D19: =D17*D18 -> 0 | E19: =E17*E18 -> 0 | F19: =F17*F18 -> 0 | G19: =G17*G18 -> 0 | H19: =H17*H18 -> 0 | I19: =I17*I18 -> 0 | J19: =J17*J18 -> 0 | K19: =K17*K18 -> 0 | ... M19: =M17*M18 -> 0
B20: DCF Assumptions
B21: Discount Rate | C21: 0.11
B22: Terminal Growth | C22: 0.015
B23: PV of Explicit FCF | C23: =SUM(D19:M19) -> 0
B24: Terminal Value | C24: =M17*(1+C22)/(C21-C22) -> 0
B25: PV of Terminal Value | C25: =C24*M18 -> 0
B26: Enterprise Value | C26: =C23+C25 -> 0
B27: Equity Value | C27: =C26+Valuation!$C$8-Valuation!$C$9-Valuation!$C$10 -> 0
B28: Implied Price | C28: =C27/Valuation!$C$6 -> 0
B29: 10Y Price CAGR | C29: =(C28/Valuation!$C$4)^(1/10)-1 -> 0
B30: Source / setup note | C30: Americas stays weak, tariffs/dupes pressure gross margin, inventory cash drag persists.
B31: Base Scenario
B32: Metric | D32: FY2026 | E32: FY2027 | F32: FY2028 | G32: FY2029 | H32: FY2030 | I32: FY2031 | J32: FY2032 | K32: FY2033 | L32: FY2034 | M32: FY2035
B33: Revenue Growth | D33: 0.029 | E33: 0.04 | F33: 0.05 | G33: 0.05 | H33: 0.045 | I33: 0.04 | J33: 0.035 | K33: 0.03 | L33: 0.028 | M33: 0.025
B34: Revenue | D34: =Valuation!J4*(1+D33) -> 0 | E34: =D34*(1+E33) -> 0 | F34: =E34*(1+F33) -> 0 | G34: =F34*(1+G33) -> 0 | H34: =G34*(1+H33) -> 0 | I34: =H34*(1+I33) -> 0 | J34: =I34*(1+J33) -> 0 | K34: =J34*(1+K33) -> 0 | L34: =K34*(1+L33) -> 0 | M34: =L34*(1+M33) -> 0
B35: Gross Margin | D35: 0.55 | E35: 0.555 | F35: 0.56 | G35: 0.565 | H35: 0.57 | I35: 0.573 | J35: 0.575 | K35: 0.576 | L35: 0.577 | M35: 0.578
B36: Operating Margin | D36: 0.18 | E36: 0.188 | F36: 0.195 | G36: 0.202 | H36: 0.207 | I36: 0.211 | J36: 0.213 | K36: 0.214 | L36: 0.215 | M36: 0.215
B37: Operating Income | D37: =D34*D36 -> 0 | E37: =E34*E36 -> 0 | F37: =F34*F36 -> 0 | G37: =G34*G36 -> 0 | H37: =H34*H36 -> 0 | I37: =I34*I36 -> 0 | J37: =J34*J36 -> 0 | K37: =K34*K36 -> 0 | ... M37: =M34*M36 -> 0
B38: FCF Margin | D38: 0.095 | E38: 0.105 | F38: 0.115 | G38: 0.125 | H38: 0.13 | I38: 0.133 | J38: 0.135 | K38: 0.137 | L38: 0.138 | M38: 0.14
B39: Free Cash Flow | D39: =D34*D38 -> 0 | E39: =E34*E38 -> 0 | F39: =F34*F38 -> 0 | G39: =G34*G38 -> 0 | H39: =H34*H38 -> 0 | I39: =I34*I38 -> 0 | J39: =J34*J38 -> 0 | K39: =K34*K38 -> 0 | ... M39: =M34*M38 -> 0
B40: Discount Factor | D40: =1/(1+$C$43)^1 -> 0 | E40: =1/(1+$C$43)^2 -> 0 | F40: =1/(1+$C$43)^3 -> 0 | G40: =1/(1+$C$43)^4 -> 0 | H40: =1/(1+$C$43)^5 -> 0 | I40: =1/(1+$C$43)^6 -> 0 | J40: =1/(1+$C$43)^7 -> 0 | K40: =1/(1+$C$43)^8 -> 0 | L40: =1/(1+$C$43)^9 -> 0 | M40: =1/(1+$C$43)^10 -> 0
B41: PV of FCF | D41: =D39*D40 -> 0 | E41: =E39*E40 -> 0 | F41: =F39*F40 -> 0 | G41: =G39*G40 -> 0 | H41: =H39*H40 -> 0 | I41: =I39*I40 -> 0 | J41: =J39*J40 -> 0 | K41: =K39*K40 -> 0 | ... M41: =M39*M40 -> 0
B42: DCF Assumptions
B43: Discount Rate | C43: 0.1
...

Sheet Actuals Source Audit
A1: Line item | B1: Fiscal period | C1: Model value | D1: Unit / currency | E1: Primary source value | F1: Primary source | G1: Filing/ref | H1: Secondary source 1 value | I1: Secondary source 1 | J1: Secondary source 2 value | K1: Secondary source 2 | L1: Resolution note | M1: Model row/cell
A2: Revenue | B2: FY2021 | C2: 6256.617 | D2: USD mm | E2: 6256.617 | F2: SEC companyfacts / 10-K XBRL | G2: SEC 2025 Form 10-K, accession 0001397187-25-000013, filed 2025-03-27, FY ended 2025-02-02 | H2: 6257 | I2: StockAnalysis annual financials / balance sheet / cash flow pages | J2: 6257 | K2: Macrotrends annual company metric page | L2: No material discrepancy; secondary figures are rounded to nearest $m. | M2: Valuation!F4:J4
A3: Revenue | B3: FY2022 | C3: 8110.518 | D3: USD mm | E3: 8110.518 | F3: SEC companyfacts / 10-K XBRL | G3: SEC 2025 Form 10-K, accession 0001397187-25-000013, filed 2025-03-27, FY ended 2025-02-02 | H3: 8111 | I3: StockAnalysis annual financials / balance sheet / cash flow pages | J3: 8111 | K3: Macrotrends annual company metric page | L3: No material discrepancy; secondary figures are rounded to nearest $m. | M3: Valuation!F4:J4
A4: Revenue | B4: FY2023 | C4: 9619.278 | D4: USD mm | E4: 9619.278 | F4: SEC companyfacts / 10-K XBRL | G4: SEC 2026 Form 10-K, accession 0001397187-26-000020, filed 2026-03-17, FY ended 2026-02-01 | H4: 9619 | I4: StockAnalysis annual financials / balance sheet / cash flow pages | J4: 9619 | K4: Macrotrends annual company metric page | L4: No material discrepancy; secondary figures are rounded to nearest $m. | M4: Valuation!F4:J4
A5: Revenue | B5: FY2024 | C5: 10588.126 | D5: USD mm | E5: 10588.126 | F5: SEC companyfacts / 10-K XBRL | G5: SEC 2026 Form 10-K, accession 0001397187-26-000020, filed 2026-03-17, FY ended 2026-02-01 | H5: 10588 | I5: StockAnalysis annual financials / balance sheet / cash flow pages | J5: 10588 | K5: Macrotrends annual company metric page | L5: No material discrepancy; secondary figures are rounded to nearest $m. | M5: Valuation!F4:J4
A6: Revenue | B6: FY2025 | C6: 11102.6 | D6: USD mm | E6: 11102.6 | F6: SEC companyfacts / 10-K XBRL | G6: SEC 2026 Form 10-K, accession 0001397187-26-000020, filed 2026-03-17, FY ended 2026-02-01 | H6: 11103 | I6: StockAnalysis annual financials / balance sheet / cash flow pages | J6: 11103 | K6: Macrotrends annual company metric page | L6: No material discrepancy; secondary figures are rounded to nearest $m. | M6: Valuation!F4:J4
A7: Gross Profit | B7: FY2021 | C7: 3608.565 | D7: USD mm | E7: 3608.565 | F7: SEC companyfacts / 10-K XBRL | G7: SEC 2025 Form 10-K, accession 0001397187-25-000013, filed 2025-03-27, FY ended 2025-02-02 | H7: 3609 | I7: StockAnalysis annual financials / balance sheet / cash flow pages | J7: 3609 | K7: Macrotrends annual company metric page | L7: No material discrepancy; secondary figures are rounded to nearest $m. | M7: Valuation!F8:J8
A8: Gross Profit | B8: FY2022 | C8: 4492.34 | D8: USD mm | E8: 4492.34 | F8: SEC companyfacts / 10-K XBRL | G8: SEC 2025 Form 10-K, accession 0001397187-25-000013, filed 2025-03-27, FY ended 2025-02-02 | H8: 4492 | I8: StockAnalysis annual financials / balance sheet / cash flow pages | J8: 4492 | K8: Macrotrends annual company metric page | L8: No material discrepancy; secondary figures are rounded to nearest $m. | M8: Valuation!F8:J8
A9: Gross Profit | B9: FY2023 | C9: 5609.405 | D9: USD mm | E9: 5609.405 | F9: SEC companyfacts / 10-K XBRL | G9: SEC 2026 Form 10-K, accession 0001397187-26-000020, filed 2026-03-17, FY ended 2026-02-01 | H9: 5609 | I9: StockAnalysis annual financials / balance sheet / cash flow pages | J9: 5609 | K9: Macrotrends annual company metric page | L9: No material discrepancy; secondary figures are rounded to nearest $m. | M9: Valuation!F8:J8
A10: Gross Profit | B10: FY2024 | C10: 6270.811 | D10: USD mm | E10: 6270.811 | F10: SEC companyfacts / 10-K XBRL | G10: SEC 2026 Form 10-K, accession 0001397187-26-000020, filed 2026-03-17, FY ended 2026-02-01 | H10: 6271 | I10: StockAnalysis annual financials / balance sheet / cash flow pages | J10: 6271 | K10: Macrotrends annual company metric page | L10: No material discrepancy; secondary figures are rounded to nearest $m. | M10: Valuation!F8:J8
A11: Gross Profit | B11: FY2025 | C11: 6284.132 | D11: USD mm | E11: 6284.132 | F11: SEC companyfacts / 10-K XBRL | G11: SEC 2026 Form 10-K, accession 0001397187-26-000020, filed 2026-03-17, FY ended 2026-02-01 | H11: 6284 | I11: StockAnalysis annual financials / balance sheet / cash flow pages | J11: 6284 | K11: Macrotrends annual company metric page | L11: No material discrepancy; secondary figures are rounded to nearest $m. | M11: Valuation!F8:J8
A12: Operating Income | B12: FY2021 | C12: 1333.355 | D12: USD mm | E12: 1333.355 | F12: SEC companyfacts / 10-K XBRL | G12: SEC 2025 Form 10-K, accession 0001397187-25-000013, filed 2025-03-27, FY ended 2025-02-02 | H12: 1333 | I12: StockAnalysis annual financials / balance sheet / cash flow pages | J12: 1333 | K12: Macrotrends annual company metric page | L12: No material discrepancy; secondary figures are rounded to nearest $m. | M12: Valuation!F11:J11
A13: Operating Income | B13: FY2022 | C13: 1328.408 | D13: USD mm | E13: 1328.408 | F13: SEC companyfacts / 10-K XBRL | G13: SEC 2025 Form 10-K, accession 0001397187-25-000013, filed 2025-03-27, FY ended 2025-02-02 | H13: 1328 | I13: StockAnalysis annual financials / balance sheet / cash flow pages | J13: 1328 | K13: Macrotrends annual company metric page | L13: No material discrepancy; secondary figures are rounded to nearest $m. | M13: Valuation!F11:J11
... A21: Net Income | B21: FY2025 | C21: 1579.183 | D21: USD mm | E21: 1579.183 | F21: SEC companyfacts / 10-K XBRL | G21: SEC 2026 Form 10-K, accession 0001397187-26-000020, filed 2026-03-17, FY ended 2026-02-01 | H21: 1579 | I21: StockAnalysis annual financials / balance sheet / cash flow pages | J21: 1579 | K21: Macrotrends annual company metric page | L21: No material discrepancy; secondary figures are rounded to nearest $m. | M21: Valuation!F16:J16
A22: Diluted EPS | B22: FY2021 | C22: 7.49 | D22: USD/sh | E22: 7.49 | F22: SEC companyfacts / 10-K XBRL | G22: SEC 2025 Form 10-K, accession 0001397187-25-000013, filed 2025-03-27, FY ended 2025-02-02 | H22: 7.49 | I22: StockAnalysis annual financials / balance sheet / cash flow pages | J22: n/a | K22: Not applicable / not published in same table | L22: No material discrepancy; secondary figures are rounded to nearest $m. | M22: Valuation!F17:J17
A23: Diluted EPS | B23: FY2022 | C23: 6.68 | D23: USD/sh | E23: 6.68 | F23: SEC companyfacts / 10-K XBRL | G23: SEC 2025 Form 10-K, accession 0001397187-25-000013, filed 2025-03-27, FY ended 2025-02-02 | H23: 6.68 | I23: StockAnalysis annual financials / balance sheet / cash flow pages | J23: n/a | K23: Not applicable / not published in same table | L23: No material discrepancy; secondary figures are rounded to nearest $m. | M23: Valuation!F17:J17
A24: Diluted EPS | B24: FY2023 | C24: 12.2 | D24: USD/sh | E24: 12.2 | F24: SEC companyfacts / 10-K XBRL | G24: SEC 2026 Form 10-K, accession 0001397187-26-000020, filed 2026-03-17, FY ended 2026-02-01 | H24: 12.2 | I24: StockAnalysis annual financials / balance sheet / cash flow pages | J24: n/a | K24: Not applicable / not published in same table | L24: No material discrepancy; secondary figures are rounded to nearest $m. | M24: Valuation!F17:J17
A25: Diluted EPS | B25: FY2024 | C25: 14.64 | D25: USD/sh | E25: 14.64 | F25: SEC companyfacts / 10-K XBRL | G25: SEC 2026 Form 10-K, accession 0001397187-26-000020, filed 2026-03-17, FY ended 2026-02-01 | H25: 14.64 | I25: StockAnalysis annual financials / balance sheet / cash flow pages | J25: n/a | K25: Not applicable / not published in same table | L25: No material discrepancy; secondary figures are rounded to nearest $m. | M25: Valuation!F17:J17
A26: Diluted EPS | B26: FY2025 | C26: 13.26 | D26: USD/sh | E26: 13.26 | F26: SEC companyfacts / 10-K XBRL | G26: SEC 2026 Form 10-K, accession 0001397187-26-000020, filed 2026-03-17, FY ended 2026-02-01 | H26: 13.26 | I26: StockAnalysis annual financials / balance sheet / cash flow pages | J26: n/a | K26: Not applicable / not published in same table | L26: No material discrepancy; secondary figures are rounded to nearest $m. | M26: Valuation!F17:J17
A27: Diluted Shares | B27: FY2021 | C27: 130.295 | D27: shares mm | E27: 130.295 | F27: SEC companyfacts / 10-K XBRL | G27: SEC 2025 Form 10-K, accession 0001397187-25-000013, filed 2025-03-27, FY ended 2025-02-02 | H27: 130 | I27: StockAnalysis annual financials / balance sheet / cash flow pages | J27: n/a | K27: Not applicable / not published in same table | L27: No material discrepancy; secondary figures are rounded to nearest $m. | M27: Valuation!F18:J18
A28: Diluted Shares | B28: FY2022 | C28: 128.017 | D28: shares mm | E28: 128.017 | F28: SEC companyfacts / 10-K XBRL | G28: SEC 2025 Form 10-K, accession 0001397187-25-000013, filed 2025-03-27, FY ended 2025-02-02 | H28: 128 | I28: StockAnalysis annual financials / balance sheet / cash flow pages | J28: n/a | K28: Not applicable / not published in same table | L28: No material discrepancy; secondary figures are rounded to nearest $m. | M28: Valuation!F18:J18
A29: Diluted Shares | B29: FY2023 | C29: 127.06 | D29: shares mm | E29: 127.06 | F29: SEC companyfacts / 10-K XBRL | G29: SEC 2026 Form 10-K, accession 0001397187-26-000020, filed 2026-03-17, FY ended 2026-02-01 | H29: 127 | I29: StockAnalysis annual financials / balance sheet / cash flow pages | J29: n/a | K29: Not applicable / not published in same table | L29: No material discrepancy; secondary figures are rounded to nearest $m. | M29: Valuation!F18:J18
A30: Diluted Shares | B30: FY2024 | C30: 123.935 | D30: shares mm | E30: 123.935 | F30: SEC companyfacts / 10-K XBRL | G30: SEC 2026 Form 10-K, accession 0001397187-26-000020, filed 2026-03-17, FY ended 2026-02-01 | H30: 124 | I30: StockAnalysis annual financials / balance sheet / cash flow pages | J30: n/a | K30: Not applicable / not published in same table | L30: No material discrepancy; secondary figures are rounded to nearest $m. | M30: Valuation!F18:J18
A31: Diluted Shares | B31: FY2025 | C31: 119.068 | D31: shares mm | E31: 119.068 | F31: SEC companyfacts / 10-K XBRL | G31: SEC 2026 Form 10-K, accession 0001397187-26-000020, filed 2026-03-17, FY ended 2026-02-01 | H31: 119 | I31: StockAnalysis annual financials / balance sheet / cash flow pages | J31: n/a | K31: Not applicable / not published in same table | L31: No material discrepancy; secondary figures are rounded to nearest $m. | M31: Valuation!F18:J18
A32: Cash + Restricted Cash | B32: FY2021 | C32: 1259.871 | D32: USD mm | E32: 1259.871 | F32: SEC companyfacts / 10-K XBRL | G32: SEC 2025 Form 10-K, accession 0001397187-25-000013, filed 2025-03-27, FY ended 2025-02-02 | H32: 1260 | I32: StockAnalysis annual financials / balance sheet / cash flow pages | J32: 1260 | K32: Macrotrends annual company metric page | L32: No material discrepancy; secondary figures are rounded to nearest $m. | M32: Valuation!F19:J19
A33: Cash + Restricted Cash | B33: FY2022 | C33: 1154.867 | D33: USD mm | E33: 1154.867 | F33: SEC companyfacts / 10-K XBRL | G33: SEC 2025 Form 10-K, accession 0001397187-25-000013, filed 2025-03-27, FY ended 2025-02-02 | H33: 1155 | I33: StockAnalysis annual financials / balance sheet / cash flow pages | J33: 1155 | K33: Macrotrends annual company metric page | L33: No material discrepancy; secondary figures are rounded to nearest $m. | M33: Valuation!F19:J19
A34: Cash + Restricted Cash | B34: FY2023 | C34: 2243.971 | D34: USD mm | E34: 2243.971 | F34: SEC companyfacts / 10-K XBRL | G34: SEC 2026 Form 10-K, accession 0001397187-26-000020, filed 2026-03-17, FY ended 2026-02-01 | H34: 2244 | I34: StockAnalysis annual financials / balance sheet / cash flow pages | J34: 2244 | K34: Macrotrends annual company metric page | L34: No material discrepancy; secondary figures are rounded to nearest $m. | M34: Valuation!F19:J19
A35: Cash + Restricted Cash | B35: FY2024 | C35: 1984.336 | D35: USD mm | E35: 1984.336 | F35: SEC companyfacts / 10-K XBRL | G35: SEC 2026 Form 10-K, accession 0001397187-26-000020, filed 2026-03-17, FY ended 2026-02-01 | H35: 1984 | I35: StockAnalysis annual financials / balance sheet / cash flow pages | J35: 1984 | K35: Macrotrends annual company metric page | L35: No material discrepancy; secondary figures are rounded to nearest $m. | M35: Valuation!F19:J19
A36: Cash + Restricted Cash | B36: FY2025 | C36: 1807.202 | D36: USD mm | E36: 1807.202 | F36: SEC companyfacts / 10-K XBRL | G36: SEC 2026 Form 10-K, accession 0001397187-26-000020, filed 2026-03-17, FY ended 2026-02-01 | H36: 1807 | I36: StockAnalysis annual financials / balance sheet / cash flow pages | J36: 1807 | K36: Macrotrends annual company metric page | L36: No material discrepancy; secondary figures are rounded to nearest $m. | M36: Valuation!F19:J19
A37: Operating Lease Liability | B37: FY2021 | C37: 881.052 | D37: USD mm | E37: 881.052 | F37: SEC companyfacts / 10-K XBRL | G37: SEC 2025 Form 10-K, accession 0001397187-25-000013, filed 2025-03-27, FY ended 2025-02-02 | H37: 881.05 | I37: StockAnalysis annual financials / balance sheet / cash flow pages | J37: n/a | K37: Not applicable / not published in same table | L37: Treated as debt-like in EV bridge; no financial debt reported in source facts. | M37: Valuation!F22:J22
A38: Operating Lease Liability | B38: FY2022 | C38: 1070.334 | D38: USD mm | E38: 1070.334 | F38: SEC companyfacts / 10-K XBRL | G38: SEC 2025 Form 10-K, accession 0001397187-25-000013, filed 2025-03-27, FY ended 2025-02-02 | H38: 1070 | I38: StockAnalysis annual financials / balance sheet / cash flow pages | J38: n/a | K38: Not applicable / not published in same table | L38: Treated as debt-like in EV bridge; no financial debt reported in source facts. | M38: Valuation!F22:J22
A39: Operating Lease Liability | B39: FY2023 | C39: 1403.282 | D39: USD mm | E39: 1403.282 | F39: SEC companyfacts / 10-K XBRL | G39: SEC 2026 Form 10-K, accession 0001397187-26-000020, filed 2026-03-17, FY ended 2026-02-01 | H39: 1403 | I39: StockAnalysis annual financials / balance sheet / cash flow pages | J39: n/a | K39: Not applicable / not published in same table | L39: Treated as debt-like in EV bridge; no financial debt reported in source facts. | M39: Valuation!F22:J22
A40: Operating Lease Liability | B40: FY2024 | C40: 1575.791 | D40: USD mm | E40: 1575.791 | F40: SEC companyfacts / 10-K XBRL | G40: SEC 2026 Form 10-K, accession 0001397187-26-000020, filed 2026-03-17, FY ended 2026-02-01 | H40: 1576 | I40: StockAnalysis annual financials / balance sheet / cash flow pages | J40: n/a | K40: Not applicable / not published in same table | L40: Treated as debt-like in EV bridge; no financial debt reported in source facts. | M40: Valuation!F22:J22
A41: Operating Lease Liability | B41: FY2025 | C41: 1798.441 | D41: USD mm | E41: 1798.441 | F41: SEC companyfacts / 10-K XBRL | G41: SEC 2026 Form 10-K, accession 0001397187-26-000020, filed 2026-03-17, FY ended 2026-02-01 | H41: 1798 | I41: StockAnalysis annual financials / balance sheet / cash flow pages | J41: n/a | K41: Not applicable / not published in same table | L41: Treated as debt-like in EV bridge; no financial debt reported in source facts. | M41: Valuation!F22:J22
A42: Operating Cash Flow | B42: FY2021 | C42: 1389.108 | D42: USD mm | E42: 1389.108 | F42: SEC companyfacts / 10-K XBRL | G42: SEC 2025 Form 10-K, accession 0001397187-25-000013, filed 2025-03-27, FY ended 2025-02-02 | H42: 1389 | I42: StockAnalysis annual financials / balance sheet / cash flow pages | J42: n/a | K42: Not applicable / not published in same table | L42: No material discrepancy; secondary figures are rounded to nearest $m. | M42: Valuation!F24:J24
A43: Operating Cash Flow | B43: FY2022 | C43: 966.463 | D43: USD mm | E43: 966.463 | F43: SEC companyfacts / 10-K XBRL | G43: SEC 2025 Form 10-K, accession 0001397187-25-000013, filed 2025-03-27, FY ended 2025-02-02 | H43: 966.46 | I43: StockAnalysis annual financials / balance sheet / cash flow pages | J43: n/a | K43: Not applicable / not published in same table | L43: No material discrepancy; secondary figures are rounded to nearest $m. | M43: Valuation!F24:J24
A44: Operating Cash Flow | B44: FY2023 | C44: 2296.164 | D44: USD mm | E44: 2296.164 | F44: SEC companyfacts / 10-K XBRL | G44: SEC 2026 Form 10-K, accession 0001397187-26-000020, filed 2026-03-17, FY ended 2026-02-01 | H44: 2296 | I44: StockAnalysis annual financials / balance sheet / cash flow pages | J44: n/a | K44: Not applicable / not published in same table | L44: No material discrepancy; secondary figures are rounded to nearest $m. | M44: Valuation!F24:J24
A45: Operating Cash Flow | B45: FY2024 | C45: 2272.713 | D45: USD mm | E45: 2272.713 | F45: SEC companyfacts / 10-K XBRL | G45: SEC 2026 Form 10-K, accession 0001397187-26-000020, filed 2026-03-17, FY ended 2026-02-01 | H45: 2273 | I45: StockAnalysis annual financials / balance sheet / cash flow pages | J45: n/a | K45: Not applicable / not published in same table | L45: No material discrepancy; secondary figures are rounded to nearest $m. | M45: Valuation!F24:J24
A46: Operating Cash Flow | B46: FY2025 | C46: 1602.477 | D46: USD mm | E46: 1602.477 | F46: SEC companyfacts / 10-K XBRL | G46: SEC 2026 Form 10-K, accession 0001397187-26-000020, filed 2026-03-17, FY ended 2026-02-01 | H46: 1602 | I46: StockAnalysis annual financials / balance sheet / cash flow pages | J46: n/a | K46: Not applicable / not published in same table | L46: No material discrepancy; secondary figures are rounded to nearest $m. | M46: Valuation!F24:J24
A47: Capex | B47: FY2021 | C47: 394.502 | D47: USD mm | E47: 394.502 | F47: SEC companyfacts / 10-K XBRL | G47: SEC 2025 Form 10-K, accession 0001397187-25-000013, filed 2025-03-27, FY ended 2025-02-02 | H47: 394.5 | I47: StockAnalysis annual financials / balance sheet / cash flow pages | J47: n/a | K47: Not applicable / not published in same table | L47: No material discrepancy; secondary figures are rounded to nearest $m. | M47: Valuation!F25:J25
...

Sheet Questions
A1: ID | B1: Question | C1: Why it matters / evidence to watch
A2: Q1 | B2: Is the Americas slowdown product-cycle specific or structural? | C2: Base case assumes stabilization; bear case is right if comps remain negative despite newness and marketing reset.
A3: Q2 | B3: Can international growth stay above corporate average without over-storing or margin drag? | C3: International is the main visible growth offset to North America; watch region comps and store economics.
A4: Q3 | B4: How much of FY2025-FY2026 margin pressure is tariff/de minimis timing versus enduring price/value pressure? | C4: A temporary tariff hit supports recovery; enduring consumer value pressure caps gross margin.
A5: Q4 | B5: Does inventory growth normalize relative to sales? | C5: FY2025 FCF was weak because working capital/inventory absorbed cash; DCF recovery depends on cash conversion.
A6: Q5 | B6: Are buybacks creating value or only masking EPS pressure? | C6: Share count is falling quickly; repurchases are attractive only if brand earnings power is intact.
A7: Q6 | B7: How much operating lease leverage should be capitalized in valuation? | C7: This model includes operating leases as debt-like obligations; excluding them materially increases EV/DCF equity value.
A8: Q7 | B8: Can gross margin return toward prior 58%+ levels while pricing remains competitive? | C8: Bull case requires product desirability and mix to offset tariffs and promotions.
A9: Q8 | B9: What level of steady-state FCF margin is realistic for a mature global apparel retailer? | C9: Base case fades to 14%; bear is 10%; bull is 16%. This is the main valuation lever.
A10: Q9 | B10: What would invalidate the base DCF? | C10: FY2026 revenue below guide midpoint, further Americas comp deterioration, or no FCF conversion improvement by FY2027.
A11: Q10 | B11: What would upgrade the case? | C11: Clean inventory, accelerating international comps, gross margin recapture, and sustained high-return buybacks.

Sheet Sources
A1: Source type | B1: Source / URL | C1: Usage | D1: Date checked
A2: Primary filing | B2: https://www.sec.gov/Archives/edgar/data/1397187/000139718726000020/lulu-20260201.htm | C2: FY2025 Form 10-K; latest annual actuals, balance sheet, cash flow, lease liabilities, share count. | D2: 2026-05-27
A3: Primary filing | B3: https://www.sec.gov/Archives/edgar/data/1397187/000139718725000013/lulu-20250202.htm | C3: Prior Form 10-K / comparative data for historical actuals. | D3: 2026-05-27
A4: SEC XBRL | B4: https://data.sec.gov/api/xbrl/companyfacts/CIK0001397187.json | C4: Programmatic companyfacts extraction for all hardcoded historical actuals. | D4: 2026-05-27
A5: Company release | B5: https://corporate.lululemon.com/media/press-releases/2026/03-17-2026-200620717 | C5: Q4/FY2025 results and FY2026 guidance framing. | D5: 2026-05-27
A6: Market / secondary | B6: https://stockanalysis.com/stocks/lulu/ | C6: Current quote, market cap, shares out, beta, analyst snapshot. | D6: 2026-05-27
A7: Secondary financials | B7: https://stockanalysis.com/stocks/lulu/financials/ | C7: Income statement cross-check for revenue, gross profit, operating income, EPS, shares. | D7: 2026-05-27
A8: Secondary financials | B8: https://stockanalysis.com/stocks/lulu/financials/balance-sheet/ | C8: Cash, leases/debt and balance-sheet cross-check. | D8: 2026-05-27
A9: Secondary financials | B9: https://stockanalysis.com/stocks/lulu/financials/cash-flow-statement/ | C9: Operating cash flow, capex, FCF, SBC and D&A cross-check. | D9: 2026-05-27
A10: Secondary financials | B10: https://www.macrotrends.net/stocks/charts/LULU/lululemon-athletica-inc/revenue | C10: Annual revenue cross-check. | D10: 2026-05-27
A11: Secondary financials | B11: https://www.macrotrends.net/stocks/charts/LULU/lululemon-athletica-inc/gross-profit | C11: Annual gross profit cross-check. | D11: 2026-05-27
A12: Secondary financials | B12: https://www.macrotrends.net/stocks/charts/LULU/lululemon-athletica-inc/operating-income | C12: Annual operating income cross-check. | D12: 2026-05-27
... A15: Guidance / news cross-check | B15: https://www.cnbc.com/2026/03/17/lululemon-lulu-earnings-q4-2025.html | C15: Public cross-check of weak FY2026 outlook and tariff / Americas discussion. | D15: 2026-05-27
A18: Model limitation | B18: The quote is intraday and will drift. Macrotrends FCF was blank for FY2025 at collection time; model uses SEC OCF less capex and StockAnalysis as the latest FCF cross-check.
A19: Disclaimer | B19: Research support only; not personalized financial advice.
