Workbook

Sheet Valuation
A1: The Trade Desk DCF Model
A2: Ticker | B2: TTD | D2: Current price | E2: 22.29
A3: Exchange | B3: Nasdaq | D3: Shares out | E3: 470.11
A4: CIK | B4: 0001671933 | D4: Market cap | E4: =E2*E3
A5: Model date | B5: 2026-05-28 | D5: Cash & ST investments | E5: 1405.915
A6: Quote used | B6: 2026-05-27 close | D6: Lease/debt | E6: 423.575
A7: Currency / units | B7: USD millions except per-share | D7: Net cash | E7: =E5-E6
D8: Enterprise value | E8: =E4+E6-E5
D9: TTM revenue | E9: 2969.12
D10: EV / TTM revenue | E10: =E8/E9
D11: EV / TTM reported FCF | E11: =E8/H37
D12: EV / TTM owner FCF | E12: =E8/H40
D13: P/E TTM | E13: =E4/H30
A14: Historical Actuals and Base Forecast
B16: FY2020 | C16: FY2021 | D16: FY2022 | E16: FY2023 | F16: FY2024 | G16: FY2025 | H16: TTM 3/31/26 | I16: FY2026E | J16: FY2027E | K16: FY2028E | L16: FY2029E | M16: FY2030E | N16: FY2031E | O16: FY2032E | P16: FY2033E | Q16: FY2034E | R16: FY2035E
A18: Revenue | B18: 836.033 | C18: 1196.467 | D18: 1577.795 | E18: 1946.12 | F18: 2444.831 | G18: 2896.284 | H18: 2969.12 | I18: =G18*(1+I49) | J18: =I18*(1+J49) | K18: =J18*(1+K49) | L18: =K18*(1+L49) | M18: =L18*(1+M49) | N18: =M18*(1+N49) | O18: =N18*(1+O49) | P18: =O18*(1+P49) | Q18: =P18*(1+Q49) | R18: =Q18*(1+R49)
A19: YoY growth | C19: =C18/B18-1 | D19: =D18/C18-1 | E19: =E18/D18-1 | F19: =F18/E18-1 | G19: =G18/F18-1 | H19: =H18/G18-1 | I19: =I18/G18-1 | J19: =J18/I18-1 | K19: =K18/J18-1 | L19: =L18/K18-1 | M19: =M18/L18-1 | N19: =N18/M18-1 | O19: =O18/N18-1 | P19: =P18/O18-1 | Q19: =Q18/P18-1 | R19: =R18/Q18-1
A20: Cost of revenue | B20: 178.812 | C20: 221.554 | D20: 281.123 | E20: 365.598 | F20: 472.012 | G20: 619.067 | H20: 658.198
A21: Gross profit | B21: =B18-B20 | C21: =C18-C20 | D21: =D18-D20 | E21: =E18-E20 | F21: =F18-F20 | G21: =G18-G20 | H21: =H18-H20
A22: Gross margin | B22: =B21/B18 | C22: =C21/C18 | D22: =D21/D18 | E22: =E21/E18 | F22: =F21/F18 | G22: =G21/G18 | H22: =H21/H18
A23: R&D | B23: 166.654 | C23: 226.137 | D23: 319.876 | E23: 411.794 | F23: 463.319 | G23: 525.141 | H23: 535.459
A24: Sales & marketing | B24: 174.742 | C24: 249.298 | D24: 337.975 | E24: 447.97 | F24: 546.517 | G24: 644.3 | H24: 663.736
A25: G&A | B25: 171.617 | C25: 374.661 | D25: 525.167 | E25: 520.278 | F25: 535.816 | G25: 518.455 | H25: 510.211
A26: Operating income | B26: 144.208 | C26: 124.817 | D26: 113.654 | E26: 200.48 | F26: 427.167 | G26: 589.321 | H26: 601.516
A27: Operating margin | B27: =B26/B18 | C27: =C26/C18 | D27: =D26/D18 | E27: =E26/E18 | F27: =F26/F18 | G27: =G26/G18 | H27: =H26/H18
A28: Pretax income | B28: 143.903 | C28: 122.036 | D28: 127.37 | E28: 267.995 | F28: 507.302 | G28: 658.755 | H28: 661.944
A29: Tax expense | B29: -98.414 | C29: -15.726 | D29: 73.985 | E29: 89.055 | F29: 114.226 | G29: 215.451 | H29: 229.321
A30: Net income | B30: 242.317 | C30: 137.762 | D30: 53.385 | E30: 178.94 | F30: 393.076 | G30: 443.304 | H30: 432.623
A31: Net margin | B31: =B30/B18 | C31: =C30/C18 | D31: =D30/D18 | E31: =E30/E18 | F31: =F30/F18 | G31: =G30/G18 | H31: =H30/H18
A32: Diluted EPS | B32: 0.49 | C32: 0.28 | D32: 0.11 | E32: 0.36 | F32: 0.78 | G32: 0.9 | H32: 0.88
A33: Diluted shares | B33: 489.881 | C33: 498.54 | D33: 499.925 | E33: 500.182 | F33: 501.924 | G33: 493.551 | H33: 487.092
A35: Operating cash flow | B35: 405.069 | C35: 378.513 | D35: 548.734 | E35: 598.322 | F35: 739.456 | G35: 992.721 | H35: 1093.093
A36: Capex | B36: 74.061 | C36: 54.804 | D36: 84.16 | E36: 46.79 | F36: 98.238 | G36: 197.011 | H36: 250.639
A37: Reported FCF | B37: 331.008 | C37: 323.709 | D37: 464.574 | E37: 551.532 | F37: 641.218 | G37: 795.71 | H37: 842.454
A38: Reported FCF margin | B38: =B37/B18 | C38: =C37/C18 | D38: =D37/D18 | E38: =E37/E18 | F38: =F37/F18 | G38: =G37/G18 | H38: =H37/H18
A39: Stock-based comp | B39: 111.775 | C39: 337.413 | D39: 498.642 | E39: 491.621 | F39: 494.699 | G39: 490.627 | H39: 471.42
A40: Owner FCF after SBC | B40: 219.233 | C40: -13.704 | D40: -34.068 | E40: 59.911 | F40: 146.519 | G40: 305.083 | H40: 371.034 | I40: =I18*I50 | J40: =J18*J50 | K40: =K18*K50 | L40: =L18*L50 | M40: =M18*M50 | N40: =N18*N50 | O40: =O18*O50 | P40: =P18*P50 | ... R40: =R18*R50
A41: Owner FCF margin | B41: =B40/B18 | C41: =C40/C18 | D41: =D40/D18 | E41: =E40/E18 | F41: =F40/F18 | G41: =G40/G18 | H41: =H40/H18 | I41: =I40/I18 | ... R41: =R40/R18
A42: D&A | B42: 28.632 | C42: 42.219 | D42: 54.425 | E42: 80.418 | F42: 87.49 | G42: 115.784 | H42: 123.23
A44: Cash & ST investments | B44: 624.038 | C44: 958.779 | D44: 1446.586 | E44: 1380.288 | F44: 1921.489 | G44: 1303.057 | H44: 1405.915
...

Sheet WACC
A1: WACC / Discount Rate
A2: Risk-free rate | B2: 0.045 | C2: FRED DGS10, 2026-05-26 observation.
A3: Equity risk premium | B3: 0.05 | C3: Public-market ERP assumption; rounded for model use.
A4: Beta | B4: 1.1 | C4: StockAnalysis/Yahoo quote snapshot, 5Y monthly beta.
A5: Cost of equity | B5: =B2+B3*B4 | C5: Risk-free rate + beta * ERP.
A6: Pre-tax lease/debt cost | B6: 0.05 | C6: Judgmental lease/debt financing cost; TTD has no conventional net debt in model bridge.
A7: Tax rate | B7: 0.21 | C7: Normalized statutory-like cash tax assumption.
A8: Market value equity | B8: =Valuation!E4 | C8: Valuation!E4.
A9: Lease/debt | B9: =Valuation!E6 | C9: Valuation!E6.
A10: Equity weight | B10: =B8/(B8+B9) | C10: Market equity / enterprise capital.
A11: Debt weight | B11: =B9/(B8+B9) | C11: Lease/debt / enterprise capital.
A12: Mechanical WACC | B12: =B10*B5+B11*B6*(1-B7) | C12: Cost of equity and after-tax debt weighted by market values.
A13: Selected discount rate | B13: 0.105 | C13: Rounded above mechanical WACC to reflect ad-tech competition, growth-duration, and margin execution risk.

Sheet Scenarios
A1: Bear / Base / Bull Scenario Summary
A3: Current price | B3: =Valuation!$E$2
A4: Current shares | B4: =Valuation!$E$3
A5: Current net cash | B5: =Valuation!$E$7
B7: Bear | C7: Base | D7: Bull | E7: Scenario interpretation
A8: Narrative | B8: Below-plan operating case: growth stays below the old algorithm, but TTD still compounds from a scaled CTV/open-internet base and keeps healthy owner earnings. | C8: TTD stabilizes after slower Q1/Q2, grows high single digits to low teens, and owner FCF margin improves but remains below reported FCF margin. | D8: Open internet, CTV, and retail-data execution restore better growth and modest multiple support, without assuming a full return to peak sentiment. | E8: The CAGR rows annualize from the May 27, 2026 closing price to the FY2030 target-price output.
A9: FY2026 revenue growth | B9: 0.11 | C9: 0.13 | D9: 0.15
A10: FY2027-FY2030 revenue CAGR | B10: 0.085 | C10: 0.105 | D10: 0.12
A11: FY2030 revenue | B11: =Valuation!$G$18*(1+B9)*(1+B10)^4 | C11: =Valuation!$G$18*(1+C9)*(1+C10)^4 | D11: =Valuation!$G$18*(1+D9)*(1+D10)^4
A12: FY2030 owner FCF margin | B12: 0.18 | C12: 0.21 | D12: 0.23
A13: FY2030 owner FCF | B13: =B11*B12 | C13: =C11*C12 | D13: =D11*D12
A14: Exit owner FCF yield | B14: 0.065 | C14: 0.0575 | D14: 0.0525
A15: Exit enterprise value | B15: =B13/B14 | C15: =C13/C14 | D15: =D13/D14
A16: Net cash bridge | B16: =$B$5 | C16: =$B$5 | D16: =$B$5
A17: FY2030 shares | B17: =$B$4*(1+-0.0025)^5 | C17: =$B$4*(1+-0.01)^5 | D17: =$B$4*(1+-0.0125)^5
A18: FY2030 target price | B18: =(B15+B16)/B17 | C18: =(C15+C16)/C17 | D18: =(D15+D16)/D17
A19: 5Y CAGR from current | B19: =(B18/$B$3)^(1/5)-1 | C19: =(C18/$B$3)^(1/5)-1 | D19: =(D18/$B$3)^(1/5)-1
A22: Scenario Drivers
A24: Metric | B24: Bear | C24: Base | D24: Bull
A25: Competitive pressure | B25: Walled gardens pressure growth, but TTD remains a scaled independent DSP | C25: TTD remains relevant and returns to low-teens growth | D25: Open internet, CTV, audio, and retail data improve buyer ROI
A26: Margin/SBC treatment | B26: Owner FCF margin reaches the high teens | C26: Owner FCF margin reaches low 20s | D26: Scale and lower SBC intensity lift owner FCF margin into low-to-mid 20s
A27: Valuation exit | B27: 15.4x owner FCF | C27: 17.4x owner FCF | D27: 19.0x owner FCF

Sheet Actuals Source Audit
A1: Line item | B1: Period | C1: Model value | D1: Unit | E1: Primary value | F1: Primary source | G1: Secondary value | H1: Secondary source | I1: Difference / resolution | J1: Model cell | K1: Notes
A2: Revenue | B2: FY2023 | C2: 1946.12 | D2: USD mm | E2: 1946.12 | F2: SEC companyfacts / 2025 10-K | G2: 1946.12 | H2: StockAnalysis financial tables | I2: Ties within rounding; SEC/companyfacts used as source of truth. | J2: Valuation!E18 | K2: Amounts are USD millions unless share rows. TTM is FY2025 + Q1 2026 - Q1 2025.
A3: Revenue | B3: FY2024 | C3: 2444.831 | D3: USD mm | E3: 2444.831 | F3: SEC companyfacts / 2025 10-K | G3: 2444.83 | H3: StockAnalysis financial tables | I3: Ties within rounding; SEC/companyfacts used as source of truth. | J3: Valuation!F18 | K3: Amounts are USD millions unless share rows. TTM is FY2025 + Q1 2026 - Q1 2025.
A4: Revenue | B4: FY2025 | C4: 2896.284 | D4: USD mm | E4: 2896.284 | F4: SEC companyfacts / 2025 10-K | G4: 2896.28 | H4: StockAnalysis financial tables | I4: Ties within rounding; SEC/companyfacts used as source of truth. | J4: Valuation!G18 | K4: Amounts are USD millions unless share rows. TTM is FY2025 + Q1 2026 - Q1 2025.
A5: Revenue | B5: TTM 3/31/26 | C5: 2969.12 | D5: USD mm | E5: 2969.12 | F5: SEC companyfacts / Q1 2026 10-Q plus FY2025 less Q1 2025 | G5: 2969.12 | H5: StockAnalysis financial tables | I5: Ties within rounding; SEC/companyfacts used as source of truth. | J5: Valuation!H18 | K5: Amounts are USD millions unless share rows. TTM is FY2025 + Q1 2026 - Q1 2025.
A6: Operating income | B6: FY2023 | C6: 200.48 | D6: USD mm | E6: 200.48 | F6: SEC companyfacts / 2025 10-K | G6: 200.48 | H6: StockAnalysis financial tables | I6: Ties within rounding; SEC/companyfacts used as source of truth. | J6: Valuation!E26 | K6: Amounts are USD millions unless share rows. TTM is FY2025 + Q1 2026 - Q1 2025.
A7: Operating income | B7: FY2024 | C7: 427.167 | D7: USD mm | E7: 427.167 | F7: SEC companyfacts / 2025 10-K | G7: 427.17 | H7: StockAnalysis financial tables | I7: Ties within rounding; SEC/companyfacts used as source of truth. | J7: Valuation!F26 | K7: Amounts are USD millions unless share rows. TTM is FY2025 + Q1 2026 - Q1 2025.
A8: Operating income | B8: FY2025 | C8: 589.321 | D8: USD mm | E8: 589.321 | F8: SEC companyfacts / 2025 10-K | G8: 589.32 | H8: StockAnalysis financial tables | I8: Ties within rounding; SEC/companyfacts used as source of truth. | J8: Valuation!G26 | K8: Amounts are USD millions unless share rows. TTM is FY2025 + Q1 2026 - Q1 2025.
A9: Operating income | B9: TTM 3/31/26 | C9: 601.516 | D9: USD mm | E9: 601.516 | F9: SEC companyfacts / Q1 2026 10-Q plus FY2025 less Q1 2025 | G9: 601.52 | H9: StockAnalysis financial tables | I9: Ties within rounding; SEC/companyfacts used as source of truth. | J9: Valuation!H26 | K9: Amounts are USD millions unless share rows. TTM is FY2025 + Q1 2026 - Q1 2025.
A10: Net income | B10: FY2023 | C10: 178.94 | D10: USD mm | E10: 178.94 | F10: SEC companyfacts / 2025 10-K | G10: 178.94 | H10: StockAnalysis financial tables | I10: Ties within rounding; SEC/companyfacts used as source of truth. | J10: Valuation!E30 | K10: Amounts are USD millions unless share rows. TTM is FY2025 + Q1 2026 - Q1 2025.
A11: Net income | B11: FY2024 | C11: 393.076 | D11: USD mm | E11: 393.076 | F11: SEC companyfacts / 2025 10-K | G11: 393.08 | H11: StockAnalysis financial tables | I11: Ties within rounding; SEC/companyfacts used as source of truth. | J11: Valuation!F30 | K11: Amounts are USD millions unless share rows. TTM is FY2025 + Q1 2026 - Q1 2025.
A12: Net income | B12: FY2025 | C12: 443.304 | D12: USD mm | E12: 443.304 | F12: SEC companyfacts / 2025 10-K | G12: 443.3 | H12: StockAnalysis financial tables | I12: Ties within rounding; SEC/companyfacts used as source of truth. | J12: Valuation!G30 | K12: Amounts are USD millions unless share rows. TTM is FY2025 + Q1 2026 - Q1 2025.
A13: Net income | B13: TTM 3/31/26 | C13: 432.623 | D13: USD mm | E13: 432.623 | F13: SEC companyfacts / Q1 2026 10-Q plus FY2025 less Q1 2025 | G13: 432.62 | H13: StockAnalysis financial tables | I13: Ties within rounding; SEC/companyfacts used as source of truth. | J13: Valuation!H30 | K13: Amounts are USD millions unless share rows. TTM is FY2025 + Q1 2026 - Q1 2025.
... A33: Diluted shares | B33: TTM 3/31/26 | C33: 487.092 | D33: mm shares | E33: 487.092 | F33: SEC companyfacts / Q1 2026 10-Q plus FY2025 less Q1 2025 | G33: 487.09 | H33: StockAnalysis financial tables | I33: Ties within rounding; SEC/companyfacts used as source of truth. | J33: Valuation!H33 | K33: Amounts are USD millions unless share rows. TTM is FY2025 + Q1 2026 - Q1 2025.
A35: Data limitations
A36: Yahoo Finance query endpoint returned Too Many Requests; Macrotrends pages were Cloudflare-blocked. Market quote was cross-checked with StockAnalysis and Stooq.

Sheet Questions
A1: Q Bank
A2: 1 | B2: Is the Q1 2026 growth deceleration temporary, or evidence that Amazon, Google, and agency shifts are structurally reducing TTD's incremental share?
A3: 2 | B3: How much of reported free cash flow is owner earnings after stock-based compensation and repurchase needs?
A4: 3 | B4: Can Unified ID, retail media data, CTV/audio, and OpenPath/OpenAds restore a durable growth premium?
A5: 4 | B5: Does the Q2 2026 guide imply conservatism, macro softness, or continued competitive pressure?
A6: 5 | B6: What happens to take-rate and gross margin if large agencies press for lower fees or more direct integrations?
A7: 6 | B7: Will buybacks more than offset SBC dilution over the next five years without consuming strategic flexibility?
A8: 7 | B8: What valuation multiple is justified if owner FCF growth normalizes to high single digits?
A9: 8 | B9: Which leading indicators should be monitored: retention, CTV spend, agency wallet share, retail data integrations, and SBC as a percentage of revenue?

Sheet Sources
A1: Source | B1: Type | C1: Date / as-of | D1: Usage | E1: URL / note
A2: SEC companyfacts API | B2: Primary filing data | C2: Pulled 2026-05-28 | D2: Historical actuals and TTM roll-forward. | E2: https://data.sec.gov/api/xbrl/companyfacts/CIK0001671933.json
A3: TTD FY2025 Form 10-K | B3: Primary filing | C3: Filed 2026-02-27 | D3: FY2025 actuals, balance sheet, cash flow, leases, share count. | E3: https://www.sec.gov/Archives/edgar/data/1671933/000167193326000014/ttd-20251231.htm
A4: TTD Q1 2026 Form 10-Q | B4: Primary filing | C4: Filed 2026-05-07 | D4: Q1 2026 actuals and TTM roll-forward. | E4: https://www.sec.gov/Archives/edgar/data/1671933/000167193326000054/ttd-20260331.htm
A5: TTD Q1 2026 Exhibit 99.1 | B5: Company release | C5: 2026-05-07 | D5: Q1 headline revenue, adjusted EBITDA, Q2 revenue and adjusted EBITDA guidance. | E5: https://www.sec.gov/Archives/edgar/data/1671933/000167193326000053/ttd-20260507x8kexx991.htm
A6: StockAnalysis overview | B6: Market data | C6: 2026-05-27 close / 2026-05-28 pre-market page | D6: Price, shares, market cap, beta, TTM revenue and secondary financial checks. | E6: https://stockanalysis.com/stocks/ttd/
A7: StockAnalysis financials | B7: Secondary financials | C7: Updated 2026-05-07 | D7: Revenue, income statement, cash-flow, balance-sheet cross-checks. | E7: https://stockanalysis.com/stocks/ttd/financials/
A8: Stooq quote CSV | B8: Market data | C8: 2026-05-27 close | D8: Independent close-price check: 22.29. | E8: https://stooq.com/q/l/?s=ttd.us&f=sd2t2ohlcv&h&e=csv
A9: FRED DGS10 | B9: Rate source | C9: 2026-05-26 | D9: 10-year Treasury risk-free rate: 4.50%. | E9: https://fred.stlouisfed.org/series/DGS10
A10: Blocked/limited sources | B10: Data limitation | C10: 2026-05-28 | D10: Yahoo quote endpoint returned Too Many Requests; Macrotrends pages were Cloudflare-blocked. | E10: Recorded as a limitation; no numbers were taken from blocked pages.
