Workbook

Sheet Model
B2: PayPal Holdings, Inc. (NASDAQ: PYPL) | E2: PYPL Model refreshed from [2023-07-03] workbook; USD millions except per-share data
B3: Model date | C3: 2026-05-29 | F3: FY2021 | G3: FY2022 | H3: FY2023 | I3: FY2024 | J3: FY2025 | K3: TTM 3/31/26 | L3: FY2026E | M3: FY2027E | N3: FY2028E | O3: FY2029E | P3: FY2030E | Q3: FY2031E | R3: FY2032E | S3: FY2033E | T3: FY2034E | U3: FY2035E
B4: Price | C4: 44.46 | E4: Revenue | F4: 25371 | G4: 27518 | H4: 29771 | I4: 31797 | J4: 33172 | K4: 33734 | L4: =J4*(1+L5) | M4: =L4*(1+M5) | N4: =M4*(1+N5) | O4: =N4*(1+O5) | P4: =O4*(1+P5) | Q4: =P4*(1+Q5) | R4: =Q4*(1+R5) | S4: =R4*(1+S5) | T4: =S4*(1+T5) | U4: =T4*(1+U5)
B5: Quote date | C5: 2026-05-28 close; StockAnalysis pre-market snapshot 2026-05-29 8:30 ET | E5: Revenue Growth | G5: =G4/F4-1 | H5: =H4/G4-1 | I5: =I4/H4-1 | J5: =J4/I4-1 | K5: =K4/J4-1 | L5: 0.047 | M5: 0.052 | N5: 0.052 | O5: 0.05 | P5: 0.048 | Q5: 0.045 | R5: 0.042 | S5: 0.039 | T5: 0.036 | U5: 0.033
B6: Current shares out, mm | C6: 882.10549 | E6: Cost of Revenue | F6: 11375 | G6: 13745 | H6: 16067 | I6: 17139 | J6: 17707 | K6: 18175 | L6: =L4-L8 | M6: =M4-M8 | N6: =N4-N8 | O6: =O4-O8 | P6: =P4-P8 | Q6: =Q4-Q8 | R6: =R4-R8 | S6: =S4-S8 | ... U6: =U4-U8
B7: Market cap, $m | C7: =C4*C6 | E7: Gross Margin | F7: 0.551653 | G7: 0.500509 | H7: 0.460314 | I7: 0.460987 | J7: 0.466206 | K7: 0.461226 | L7: 0.462 | M7: 0.464 | N7: 0.466 | O7: 0.468 | P7: 0.47 | Q7: 0.472 | R7: 0.474 | S7: 0.476 | T7: 0.478 | U7: 0.48
B8: Cash + ST investments, $m | C8: 9342 | E8: Gross Profit | F8: 13996 | G8: 13773 | H8: 13704 | I8: 14658 | J8: 15465 | K8: 15559 | L8: =L4*L7 | M8: =M4*M7 | N8: =N4*N7 | O8: =O4*O7 | P8: =P4*P7 | Q8: =Q4*Q7 | R8: =R4*R7 | S8: =S4*S7 | ... U8: =U4*U7
B9: Long-term investments, $m | C9: 4125
B10: Debt, $m | C10: 11670 | E10: R&D | F10: 3038 | G10: 3253 | H10: 2973 | I10: 2979 | J10: 3103 | K10: 3165 | L10: =L4*L11 | M10: =M4*M11 | N10: =N4*N11 | O10: =O4*O11 | P10: =P4*P11 | Q10: =Q4*Q11 | R10: =R4*R11 | S10: =S4*S11 | ... U10: =U4*U11
B11: Operating leases, $m | C11: 652 | E11: R&D % Revenue | F11: =F10/F4 | G11: =G10/G4 | H11: =H10/H4 | I11: =I10/I4 | J11: =J10/J4 | K11: =K10/K4 | L11: 0.092 | M11: 0.091 | N11: 0.091 | O11: 0.09 | P11: 0.09 | Q11: 0.089 | R11: 0.089 | S11: 0.088 | T11: 0.088 | U11: 0.088
B12: Net debt used, $m | C12: =C10-C8 -> 2328 | E12: SG&A | F12: 6634 | G12: 6476 | H12: 5787 | I12: 5916 | J12: 5966 | K12: 6032 | L12: =L4*L13 | M12: =M4*M13 | N12: =N4*N13 | O12: =O4*O13 | P12: =P4*P13 | Q12: =Q4*Q13 | R12: =R4*R13 | S12: =S4*S13 | ... U12: =U4*U13
B13: Enterprise value, $m | C13: =C7+C12 -> 41546.41 | E13: SG&A % Revenue | F13: =F12/F4 | G13: =G12/G4 | H13: =H12/H4 | I13: =I12/I4 | J13: =J12/J4 | K13: =K12/K4 | L13: 0.177 | M13: 0.174 | N13: 0.171 | O13: 0.168 | P13: 0.165 | Q13: 0.163 | R13: 0.161 | S13: 0.16 | T13: 0.159 | U13: 0.158
B14: EV incl LT investments as cash, $m | C14: =C7+C10-C8-C9 -> 37421.41 | E14: Other OpEx | F14: 62 | G14: 207 | H14: -84 | I14: 438 | J14: 331 | K14: 339 | L14: =L4*0.01 | M14: =M4*0.01 | N14: =N4*0.01 | O14: =O4*0.01 | P14: =P4*0.009 | Q14: =Q4*0.009 | R14: =R4*0.009 | S14: =S4*0.009 | T14: =T4*0.009 | U14: =U4*0.009
B15: EV / TTM revenue | C15: =C13/K4 | E15: Operating Expenses | F15: =F6+F10+F12+F14 | G15: =G6+G10+G12+G14 | H15: =H6+H10+H12+H14 | I15: =I6+I10+I12+I14 | J15: =J6+J10+J12+J14 | K15: =K6+K10+K12+K14 | L15: =L6+L10+L12+L14 | M15: =M6+M10+M12+M14 | ... U15: =U6+U10+U12+U14
B16: EV / TTM owner FCF | C16: =C13/K31 | E16: Operating Income | F16: 4262 | G16: 3837 | H16: 5028 | I16: 5325 | J16: 6065 | K16: 6023 | L16: =L4-L15 | M16: =M4-M15 | N16: =N4-N15 | O16: =O4-O15 | P16: =P4-P15 | Q16: =Q4-Q15 | R16: =R4-R15 | S16: =S4-S15 | ... U16: =U4-U15
B17: Headline DCF implied price | C17: =C59 | E17: Operating Margin | F17: =F16/F4 | G17: =G16/G4 | H17: =H16/H4 | I17: =I16/I4 | J17: =J16/J4 | K17: =K16/K4 | L17: =L16/L4 | M17: =M16/M4 | ... U17: =U16/U4
B18: Margin of safety | C18: =C59/C4-1 | E18: Other Income / Expense | F18: -163 | G18: -471 | H18: 383 | I18: 4 | J18: 227 | K18: 59 | L18: 0 | M18: 0 | N18: 0 | O18: 0 | P18: 0 | Q18: 0 | R18: 0 | S18: 0 | T18: 0 | U18: 0
B19: Source note | C19: Uses May 28 close; May 29 pre-market was 44.58 on StockAnalysis. EV bridge conservatively subtracts cash/ST only; Q1 release reported cash/equivalents/investments of approx. $13.5B. | E19: Pretax Income | F19: 4099 | G19: 3366 | H19: 5411 | I19: 5329 | J19: 6292 | K19: 6082 | L19: =L16+L18 | M19: =M16+M18 | N19: =N16+N18 | O19: =O16+O18 | P19: =P16+P18 | Q19: =Q16+Q18 | R19: =R16+R18 | S19: =S16+S18 | ... U19: =U16+U18
E20: Taxes | F20: -70 | G20: 947 | H20: 1165 | I20: 1182 | J20: 1059 | K20: 1023 | L20: =L19*L21 | M20: =M19*M21 | N20: =N19*N21 | O20: =O19*O21 | P20: =P19*P21 | Q20: =Q19*Q21 | R20: =R19*R21 | S20: =S19*S21 | ... U20: =U19*U21
E21: Tax Rate | F21: =F20/F19 | G21: =G20/G19 | H21: =H20/H19 | I21: =I20/I19 | J21: =J20/J19 | K21: =K20/K19 | L21: 0.18 | M21: 0.18 | N21: 0.18 | O21: 0.18 | P21: 0.18 | Q21: 0.18 | R21: 0.18 | S21: 0.18 | T21: 0.18 | U21: 0.18
E22: Net Income | F22: 4169 | G22: 2419 | H22: 4246 | I22: 4147 | J22: 5233 | K22: 5059 | L22: =L19-L20 | M22: =M19-M20 | N22: =N19-N20 | O22: =O19-O20 | P22: =P19-P20 | Q22: =Q19-Q20 | R22: =R19-R20 | S22: =S19-S20 | ... U22: =U19-U20
E23: Net Margin | F23: =F22/F4 | G23: =G22/G4 | H23: =H22/H4 | I23: =I22/I4 | J23: =J22/J4 | K23: =K22/K4 | L23: =L22/L4 | M23: =M22/M4 | ... U23: =U22/U4
E24: Diluted Shares | F24: 1186 | G24: 1158 | H24: 1107 | I24: 1039 | J24: 968 | K24: 949 | L24: 882.10549 | M24: =L24*(1+-0.018) | N24: =M24*(1+-0.016) | O24: =N24*(1+-0.014) | P24: =O24*(1+-0.012) | Q24: =P24*(1+-0.01) | R24: =Q24*(1+-0.008) | S24: =R24*(1+-0.006) | T24: =S24*(1+-0.005) | U24: =T24*(1+-0.005)
E25: EPS | F25: 3.52 | G25: 2.09 | H25: 3.84 | I25: 3.99 | J25: 5.41 | K25: 5.33 | L25: =L22/L24 | M25: =M22/M24 | N25: =N22/N24 | O25: =O22/O24 | P25: =P22/P24 | Q25: =Q22/Q24 | R25: =R22/R24 | S25: =S22/S24 | ... U25: =U22/U24
E27: Operating Cash Flow | F27: 5797 | G27: 5813 | H27: 4843 | I27: 7450 | J27: 6416 | K27: 6390 | L27: =L29-L28 | M27: =M29-M28 | N27: =N29-N28 | O27: =O29-O28 | P27: =P29-P28 | Q27: =Q29-Q28 | R27: =R29-R28 | S27: =S29-S28 | ... U27: =U29-U28
E28: Capex | F28: -908 | G28: -706 | H28: -623 | I28: -683 | J28: -852 | K28: -887 | L28: =-L4*0.026 | M28: =-M4*0.026 | N28: =-N4*0.0255 | O28: =-O4*0.025 | P28: =-P4*0.0245 | Q28: =-Q4*0.024 | R28: =-R4*0.024 | S28: =-S4*0.024 | T28: =-T4*0.024 | U28: =-U4*0.024
E29: Free Cash Flow | F29: 4889 | G29: 5107 | H29: 4220 | I29: 6767 | J29: 5564 | K29: 5503 | L29: =L33+L31 | M29: =M33+M31 | N29: =N33+N31 | O29: =O33+O31 | P29: =P33+P31 | Q29: =Q33+Q31 | R29: =R33+R31 | S29: =S33+S31 | ... U29: =U33+U31
E30: FCF Margin | F30: =F29/F4 | G30: =G29/G4 | H30: =H29/H4 | I30: =I29/I4 | J30: =J29/J4 | K30: =K29/K4 | L30: =L29/L4 | M30: =M29/M4 | ... U30: =U29/U4
E31: Stock-Based Compensation | F31: 1376 | G31: 1261 | H31: 1475 | I31: 1230 | J31: 1002 | K31: 1012 | L31: =L4*L32 | M31: =M4*M32 | N31: =N4*N32 | O31: =O4*O32 | P31: =P4*P32 | Q31: =Q4*Q32 | R31: =R4*R32 | S31: =S4*S32 | ... U31: =U4*U32
E32: SBC % Revenue | F32: =F31/F4 | G32: =G31/G4 | H32: =H31/H4 | I32: =I31/I4 | J32: =J31/J4 | K32: =K31/K4 | L32: 0.03 | M32: 0.029 | N32: 0.028 | O32: 0.027 | P32: 0.026 | Q32: 0.025 | R32: 0.024 | S32: 0.0235 | T32: 0.023 | U32: 0.023
E33: Owner FCF After SBC | F33: 3513 | G33: 3846 | H33: 2745 | I33: 5537 | J33: 4562 | K33: 4491 | L33: =L4*L34 | M33: =M4*M34 | N33: =N4*N34 | O33: =O4*O34 | P33: =P4*P34 | Q33: =Q4*Q34 | R33: =R4*R34 | S33: =S4*S34 | ... U33: =U4*U34
E34: Owner FCF Margin | F34: =F33/F4 | G34: =G33/G4 | H34: =H33/H4 | I34: =I33/I4 | J34: =J33/J4 | K34: =K33/K4 | L34: 0.142 | M34: 0.148 | N34: 0.152 | O34: 0.156 | P34: 0.16 | Q34: 0.162 | R34: 0.164 | S34: 0.165 | T34: 0.166 | U34: 0.166
E36: Cash + ST Investments | F36: 9500 | G36: 10868 | H36: 14060 | I36: 10924 | J36: 10422 | K36: 9342
E37: Long-term Investments | F37: 6797 | G37: 5018 | H37: 3273 | I37: 4583 | J37: 4330 | K37: 4125
E38: Debt | F38: 8049 | G38: 10417 | H38: 9676 | I38: 9879 | J38: 9987 | K38: 11670
E39: Operating Lease Liabilities | K39: 652
E40: Net Debt / (Cash) | F40: =F38-F36 | G40: =G38-G36 | H40: =H38-H36 | I40: =I38-I36 | J40: =J38-J36 | K40: =K38-K36
E42: TPV ($B) | F42: 1250 | G42: 1360 | H42: 1530 | I42: 1670 | J42: 1790 | K42: 1826
E43: Payment Transactions (B) | F43: 19.3 | G43: 22.3 | H43: 24.4 | I43: 26.5 | J43: 25.4 | K43: 25.8
E44: Active Accounts (mm) | F44: 426 | G44: 435 | H44: 426 | I44: 434 | J44: 439 | K44: 439
...

Sheet WACC
A1: WACC / Required Return Inputs
A2: Risk-free rate | B2: 0.0448 | C2: FRED DGS10 2026-05-27 observation.
A3: Equity risk premium | B3: 0.05 | C3: Rounded public-market ERP assumption.
A4: Beta | B4: 1.394 | C4: StockAnalysis 5Y beta snapshot.
A5: Cost of equity | B5: =B2+B3*B4 -> 0.1145 | C5: CAPM: risk-free + beta * ERP.
A6: Pre-tax debt cost | B6: 0.045 | C6: Judgmental blended funding cost below current coupon stack; current credit quality and fixed notes.
A7: Tax rate | B7: 0.18 | C7: Normalized around recent effective cash/GAAP tax rate.
A8: Market value equity, $m | B8: =Model!C7 -> 39218.41 | C8: May 28 close * current shares.
A9: Debt, $m | B9: =Model!C10 -> 11670 | C9: Q1 2026 company release / market-data debt bridge.
A10: Equity weight | B10: =B8/(B8+B9) -> 0.7706747 | C10: Market equity / enterprise capital.
A11: Debt weight | B11: =B9/(B8+B9) -> 0.2293253 | C11: Debt / enterprise capital.
A12: Mechanical WACC | B12: =B10*B5+B11*B6*(1-B7) -> 0.096704357 | C12: Tax-adjusted blended cost of capital.
A13: Selected discount rate | B13: 0.105 | C13: Rounded above mechanical WACC for branded-checkout turnaround, competition, execution, and consumer-credit/BNPL timing risk.

Sheet Scenarios
A1: Bear / Base / Bull Scenario Summary
B3: Bear | C3: Base | D3: Bull | E3: Scenario interpretation
A4: Narrative | B4: Turnaround stalls; branded checkout and Venmo improvements do not offset competitive pressure and capital return slows. | C4: Modest growth recovery, steady account base, and owner FCF margin rebuild from cost discipline and mix. | D4: Better branded checkout, Venmo monetization, and PSP mix convert TPV into higher transaction margin dollars. | E4: Five-year target-price outputs use an owner-FCF exit yield rather than terminal-growth DCF.
A5: FY2026 revenue growth | B5: 0.025 | C5: 0.047 | D5: 0.065
A6: FY2027-FY2030 revenue CAGR | B6: 0.02 | C6: 0.05 | D6: 0.07
A7: FY2030 revenue | B7: =Model!J4*(1+B5)*(1+B6)^4 | C7: =Model!J4*(1+C5)*(1+C6)^4 | D7: =Model!J4*(1+D5)*(1+D6)^4
A8: FY2030 owner FCF margin | B8: 0.125 | C8: 0.158 | D8: 0.18
A9: FY2030 owner FCF | B9: =B7*B8 | C9: =C7*C8 | D9: =D7*D8
A10: Exit owner FCF yield | B10: 0.09 | C10: 0.075 | D10: 0.065
A11: Exit enterprise value | B11: =B9/B10 | C11: =C9/C10 | D11: =D9/D10
A12: Net debt bridge | B12: =Model!$C$12 | C12: =Model!$C$12 | D12: =Model!$C$12
A13: FY2030 shares | B13: =Model!$C$6*(1-0.005)^5 | C13: =Model!$C$6*(1-0.015)^5 | D13: =Model!$C$6*(1-0.02)^5
A14: FY2030 target price | B14: =(B11-B12)/B13 | C14: =(C11-C12)/C13 | D14: =(D11-D12)/D13
A15: 5Y CAGR from current | B15: =(B14/Model!$C$4)^(1/5)-1 | C15: =(C14/Model!$C$4)^(1/5)-1 | D15: =(D14/Model!$C$4)^(1/5)-1
A19: Scenario Drivers
A21: Metric | B21: Bear | C21: Base | D21: Bull
A22: Branded checkout / Venmo | B22: Low conversion gains; account growth flat. | C22: Checkout UX and rewards help stabilize engagement. | D22: Higher conversion and wallet utility drive better selection.
A23: Transaction margin dollars | B23: TM$ lags TPV; PSP/Braintree mix remains dilutive. | C23: TM$ grows low-to-mid single digits with better mix. | D23: TM$ grows ahead of revenue as pricing/mix improves.
A24: Capital return | B24: Buybacks slow after dividend and leverage/cash needs. | C24: Buybacks offset dilution and reduce shares about 1-2% annually. | D24: FCF supports larger repurchases without raising balance-sheet risk.
A25: Valuation exit | B25: 11.1x owner FCF. | C25: 13.3x owner FCF. | D25: 15.4x owner FCF.

Sheet Actuals Source Audit
A1: Line item | B1: Period | C1: Model value | D1: Unit | E1: Primary value | F1: Primary source | G1: Secondary value | H1: Secondary source | I1: Second secondary / note | J1: Resolution | K1: Model cell
A2: Revenue | B2: FY2023 | C2: 29771 | D2: USD mm | E2: 29771 | F2: SEC companyfacts / FY2025 Form 10-K, filed 2026-02-03 | G2: 29771 | H2: StockAnalysis financial tables, updated 2026-05-05 | I2: CompaniesMarketCap provides revenue and pretax-income cross-checks; other lines use StockAnalysis as visible secondary financial table. | J2: Used StockAnalysis visible table where SEC taxonomy grouping differs. | K2: Model!H4
A3: Revenue | B3: FY2024 | C3: 31797 | D3: USD mm | E3: 31797 | F3: SEC companyfacts / FY2025 Form 10-K, filed 2026-02-03 | G3: 31797 | H3: StockAnalysis financial tables, updated 2026-05-05 | I3: CompaniesMarketCap provides revenue and pretax-income cross-checks; other lines use StockAnalysis as visible secondary financial table. | J3: Used StockAnalysis visible table where SEC taxonomy grouping differs. | K3: Model!I4
A4: Revenue | B4: FY2025 | C4: 33172 | D4: USD mm | E4: 33172 | F4: SEC companyfacts / FY2025 Form 10-K, filed 2026-02-03 | G4: 33172 | H4: StockAnalysis financial tables, updated 2026-05-05 | I4: CompaniesMarketCap provides revenue and pretax-income cross-checks; other lines use StockAnalysis as visible secondary financial table. | J4: Used StockAnalysis visible table where SEC taxonomy grouping differs. | K4: Model!J4
A5: Revenue | B5: TTM 3/31/26 | C5: 33734 | D5: USD mm | E5: 33734 | F5: SEC companyfacts / Q1 2026 Form 10-Q, filed 2026-05-05; TTM = FY2025 + Q1 2026 - Q1 2025 | G5: 33734 | H5: StockAnalysis financial tables, updated 2026-05-05 | I5: CompaniesMarketCap provides revenue and pretax-income cross-checks; other lines use StockAnalysis as visible secondary financial table. | J5: Used StockAnalysis visible table where SEC taxonomy grouping differs. | K5: Model!K4
A6: Operating income | B6: FY2023 | C6: 5028 | D6: USD mm | E6: 5028 | F6: SEC companyfacts / FY2025 Form 10-K, filed 2026-02-03 | G6: 5028 | H6: StockAnalysis financial tables, updated 2026-05-05 | I6: Second visible secondary unavailable or not used for this line; Yahoo endpoint returned Too Many Requests and Macrotrends was Cloudflare-blocked. | J6: Ties within rounding; SEC/company filings used as source of truth. | K6: Model!H16
A7: Operating income | B7: FY2024 | C7: 5325 | D7: USD mm | E7: 5325 | F7: SEC companyfacts / FY2025 Form 10-K, filed 2026-02-03 | G7: 5325 | H7: StockAnalysis financial tables, updated 2026-05-05 | I7: Second visible secondary unavailable or not used for this line; Yahoo endpoint returned Too Many Requests and Macrotrends was Cloudflare-blocked. | J7: Ties within rounding; SEC/company filings used as source of truth. | K7: Model!I16
A8: Operating income | B8: FY2025 | C8: 6065 | D8: USD mm | E8: 6065 | F8: SEC companyfacts / FY2025 Form 10-K, filed 2026-02-03 | G8: 6065 | H8: StockAnalysis financial tables, updated 2026-05-05 | I8: Second visible secondary unavailable or not used for this line; Yahoo endpoint returned Too Many Requests and Macrotrends was Cloudflare-blocked. | J8: Ties within rounding; SEC/company filings used as source of truth. | K8: Model!J16
A9: Operating income | B9: TTM 3/31/26 | C9: 6023 | D9: USD mm | E9: 6023 | F9: SEC companyfacts / Q1 2026 Form 10-Q, filed 2026-05-05; TTM = FY2025 + Q1 2026 - Q1 2025 | G9: 6023 | H9: StockAnalysis financial tables, updated 2026-05-05 | I9: Second visible secondary unavailable or not used for this line; Yahoo endpoint returned Too Many Requests and Macrotrends was Cloudflare-blocked. | J9: Ties within rounding; SEC/company filings used as source of truth. | K9: Model!K16
A10: Pretax income | B10: FY2023 | C10: 5411 | D10: USD mm | E10: 5411 | F10: SEC companyfacts / FY2025 Form 10-K, filed 2026-02-03 | G10: 5411 | H10: StockAnalysis financial tables, updated 2026-05-05 | I10: CompaniesMarketCap provides revenue and pretax-income cross-checks; other lines use StockAnalysis as visible secondary financial table. | J10: Used StockAnalysis visible table where SEC taxonomy grouping differs. | K10: Model!H19
A11: Pretax income | B11: FY2024 | C11: 5329 | D11: USD mm | E11: 5329 | F11: SEC companyfacts / FY2025 Form 10-K, filed 2026-02-03 | G11: 5329 | H11: StockAnalysis financial tables, updated 2026-05-05 | I11: CompaniesMarketCap provides revenue and pretax-income cross-checks; other lines use StockAnalysis as visible secondary financial table. | J11: Used StockAnalysis visible table where SEC taxonomy grouping differs. | K11: Model!I19
A12: Pretax income | B12: FY2025 | C12: 6292 | D12: USD mm | E12: 6292 | F12: SEC companyfacts / FY2025 Form 10-K, filed 2026-02-03 | G12: 6292 | H12: StockAnalysis financial tables, updated 2026-05-05 | I12: CompaniesMarketCap provides revenue and pretax-income cross-checks; other lines use StockAnalysis as visible secondary financial table. | J12: Used StockAnalysis visible table where SEC taxonomy grouping differs. | K12: Model!J19
A13: Pretax income | B13: TTM 3/31/26 | C13: 6082 | D13: USD mm | E13: 6082 | F13: SEC companyfacts / Q1 2026 Form 10-Q, filed 2026-05-05; TTM = FY2025 + Q1 2026 - Q1 2025 | G13: 6082 | H13: StockAnalysis financial tables, updated 2026-05-05 | I13: CompaniesMarketCap provides revenue and pretax-income cross-checks; other lines use StockAnalysis as visible secondary financial table. | J13: Used StockAnalysis visible table where SEC taxonomy grouping differs. | K13: Model!K19
... A37: Diluted shares | B37: TTM 3/31/26 | C37: 949 | D37: mm shares | E37: 949 | F37: SEC companyfacts / Q1 2026 Form 10-Q, filed 2026-05-05; TTM = FY2025 + Q1 2026 - Q1 2025 | G37: 949 | H37: StockAnalysis financial tables, updated 2026-05-05 | I37: Second visible secondary unavailable or not used for this line; Yahoo endpoint returned Too Many Requests and Macrotrends was Cloudflare-blocked. | J37: Ties within rounding; SEC/company filings used as source of truth. | K37: Model!K24
A38: Cash + ST investments | B38: Latest quarter | C38: 9342 | D38: USD mm | E38: 9342 | F38: StockAnalysis financial tables, updated 2026-05-05 | G38: 9.34B | H38: StockAnalysis stats/balance sheet | I38: Q1 release reported cash, cash equivalents, and investments of approx. $13.5B including longer-term investments. | J38: Conservative EV bridge subtracts cash/ST only. | K38: Model!C8
A39: Long-term investments | B39: Latest quarter | C39: 4125 | D39: USD mm | E39: 4125 | F39: Q1 2026 Form 10-Q / StockAnalysis balance sheet | G39: 4.13B | H39: StockAnalysis balance sheet | I39: Used as memorandum line, not subtracted in headline EV. | J39: Recorded separately to show alternate EV bridge. | K39: Model!C9
A40: Debt | B40: Latest quarter | C40: 11670 | D40: USD mm | E40: 11670 | F40: PayPal Q1 2026 earnings release, filed as 8-K Exhibit 99.1 on 2026-05-05 | G40: 11.67B | H40: StockAnalysis stats | I40: Market-data EV bridge rounds to $11.67B; Q1 release rounds to $11.6B. | J40: Uses market-data rounded value for EV bridge. | K40: Model!C10
A41: Market cap | B41: Latest quote | C41: 39218.41 | D41: USD mm | E41: 39218.41 | F41: Stooq / StockAnalysis quote snapshot | G41: 39.21B | H41: CompaniesMarketCap / Nasdaq retrieval shown on page | I41: May 28 close used; May 29 pre-market noted. | J41: Ties within rounding. | K41: Model!C7
A42: Shares outstanding | B42: Latest quote | C42: 882.10549 | D42: mm shares | E42: 882.10549 | F42: StockAnalysis statistics page | G42: 882.11M | H42: StockAnalysis statistics page | I42: Current share-class count used for per-share valuation, not diluted average shares. | J42: Ties within rounding. | K42: Model!C6
A43: Q1 2026 net revenues | B43: Q1 2026 | C43: 8353 | D43: USD mm | E43: 8353 | F43: PayPal Q1 2026 earnings release, filed as 8-K Exhibit 99.1 on 2026-05-05 | G43: 8.4B | H43: PayPal Q1 release summary | I43: Company release reports 7% growth / 5% FX-neutral. | J43: Used for TTM roll-forward support. | K43: Sources!A4
A44: Q1 2026 TPV | B44: Q1 2026 | C44: 464000 | D44: USD mm | E44: 464000 | F44: PayPal Q1 2026 earnings release, filed as 8-K Exhibit 99.1 on 2026-05-05 | G44: 464.0B | H44: PayPal Q1 release summary | I44: TPV grew 11%; 8% FX-neutral. | J44: Used as business driver, not DCF line item. | K44: Model!K42
A45: Q1 2026 active accounts | B45: Q1 2026 | C45: 439 | D45: mm accounts | E45: 439 | F45: PayPal Q1 2026 earnings release, filed as 8-K Exhibit 99.1 on 2026-05-05 | G45: 439M | H45: PayPal Q1 release summary | I45: Active accounts increased 1%; sequentially down 0.2M. | J45: Used as business driver, not DCF line item. | K45: Model!K44
A46: Dividend | B46: Q1 2026 | C46: 0.14 | D46: USD/share | E46: 0.14 | F46: PayPal Q1 2026 earnings release, filed as 8-K Exhibit 99.1 on 2026-05-05 | G46: 0.14 | H46: PayPal Q1 release summary | I46: First cash dividend payable 2026-06-25 to holders as of 2026-06-04. | J46: Recorded for capital-return context. | K46: Questions!B8
A48: Data limitations
A49: Yahoo quoteSummary endpoint returned Too Many Requests; Macrotrends was Cloudflare-blocked. No paid analyst consensus source was used; forecast assumptions are explicit model assumptions, not consensus.

Sheet Questions
A1: Q Bank
A2: 1 | B2: Is branded checkout actually improving conversion and selection, or is TPV growth increasingly PSP/Braintree mix with weaker unit economics?
A3: 2 | B3: Can transaction margin dollars grow faster than revenue after excluding interest on customer balances?
A4: 3 | B4: Are Venmo, PayPal Rewards, debit/credit cards, and omnichannel wallet usage creating daily-use engagement, or only subsidized activity?
A5: 4 | B5: How should BNPL receivable sale timing be normalized when converting reported FCF into owner earnings?
A6: 5 | B6: Does the dividend plus buyback cadence constrain reinvestment, or is the balance sheet still overcapitalized after customer-funds separation?
A7: 6 | B7: What evidence would show that new leadership is improving execution rather than just taking cost out?
A8: 7 | B8: What is the normalized owner FCF margin after SBC, credit losses, transaction expense, and customer-balance interest normalize?
A9: 8 | B9: Which metrics should be watched quarterly: branded checkout TPV, TM$ ex-interest, active accounts, TPA ex-PSP, Venmo monetization, and share count?
A10: 9 | B10: At what exit owner FCF yield does the stock stop being cheap if revenue grows only low single digits?
A11: 10 | B11: How much strategic-investment / crypto mark-to-market noise should be ignored in EPS and WACC assumptions?

Sheet Sources
A1: Source | B1: Type | C1: Date / as-of | D1: Usage | E1: URL / note
A2: SEC companyfacts API | B2: Primary filing data | C2: Pulled 2026-05-29 | D2: Historical actuals and TTM roll-forward | E2: https://data.sec.gov/api/xbrl/companyfacts/CIK0001633917.json
A3: PayPal FY2025 Form 10-K | B3: Primary filing | C3: Filed 2026-02-03 | D3: FY2025 annual actuals, historical comparative table, key metrics, liquidity and debt notes | E3: https://www.sec.gov/Archives/edgar/data/1633917/000163391726000024/pypl-20251231.htm
A4: PayPal Q1 2026 Form 10-Q | B4: Primary filing | C4: Filed 2026-05-05 | D4: Q1 2026 actuals and TTM roll-forward | E4: https://www.sec.gov/Archives/edgar/data/1633917/000163391726000067/pypl-20260331.htm
A5: PayPal Q1 2026 earnings release | B5: Company release | C5: Filed 2026-05-05 as 8-K Exhibit 99.1 | D5: Q1 headline metrics, TM$, TPV, active accounts, FCF, cash/debt, dividend, guidance | E5: https://www.sec.gov/Archives/edgar/data/1633917/000163391726000065/pypl1q-26earningsrelease.htm
A6: StockAnalysis overview/statistics/financials | B6: Market and secondary financial data | C6: May 28 close / updated 2026-05-05 | D6: Quote, shares, market cap, EV bridge, beta, financial statement cross-checks | E6: https://stockanalysis.com/stocks/pypl/
A7: Stooq quote CSV | B7: Market quote | C7: 2026-05-28 close | D7: Independent close-price check: 44.46 | E7: https://stooq.com/q/l/?s=pypl.us&f=sd2t2ohlcv&h&e=csv
A8: CompaniesMarketCap revenue/earnings/market cap | B8: Secondary financial / market check | C8: May 2026 | D8: Revenue, pretax income, market-cap cross-check | E8: https://companiesmarketcap.com/paypal/revenue/
A9: FRED DGS10 | B9: Rate source | C9: 2026-05-27 | D9: 10-year Treasury risk-free rate: 4.48% | E9: https://fred.stlouisfed.org/series/DGS10
A10: Blocked / limited sources | B10: Data limitation | C10: 2026-05-29 | D10: Yahoo quoteSummary endpoint returned Too Many Requests; Macrotrends Cloudflare-blocked. | E10: No values were taken from blocked pages.
