Workbook

Sheet Valuation
B2: Salesforce, Inc. (NYSE: CRM) | E2: Salesforce | F2: Fiscal years ending Jan. 31; USD millions except per-share data | V2: Key limitations
B3: Model date | C3: 2026-05-25 | F3: FY2022 | G3: FY2023 | H3: FY2024 | I3: FY2025 | J3: FY2026 | K3: FY2027E | L3: FY2028E | M3: FY2029E | N3: FY2030E | O3: FY2031E | P3: FY2032E | Q3: FY2033E | R3: FY2034E | S3: FY2035E | T3: FY2036E | V3: No Q1 FY2027 report was available by the 2026-05-25 model date; next scheduled earnings update was 2026-05-27 after market close.
B4: Price | C4: 180.07 | E4: Revenue | F4: 26492 | G4: 31352 | H4: 34857 | I4: 37895 | J4: 41525 | K4: =J4*(1+K5) | L4: =K4*(1+L5) | M4: =L4*(1+M5) | N4: =M4*(1+N5) | O4: =N4*(1+O5) | P4: =O4*(1+P5) | Q4: =P4*(1+Q5) | R4: =Q4*(1+R5) | ... T4: =S4*(1+T5) | V4: Share count is provisional because the March 2026 ASR has initial delivery and final settlement expected later in calendar 2026.
B5: Quote date | C5: 2026-05-22 close | E5: Revenue Growth | G5: =G4/F4-1 | H5: =H4/G4-1 | I5: =I4/H4-1 | J5: =J4/I4-1 | K5: 0.108 | L5: 0.085 | M5: 0.075 | N5: 0.065 | O5: 0.058 | P5: 0.052 | Q5: 0.047 | R5: 0.043 | S5: 0.04 | T5: 0.038 | V5: The headline DCF subtracts 100% of SBC from reported FCF. The reported FCF DCF is shown separately as an upside cross-check, not as the primary value.
B6: Diluted shares, mm | C6: 818.05 | E6: Cost of Revenue | F6: 7026 | G6: 8360 | H6: 8541 | I6: 8643 | J6: 9270 | K6: =K4-K8 | L6: =L4-L8 | M6: =M4-M8 | N6: =N4-N8 | O6: =O4-O8 | P6: =P4-P8 | Q6: =Q4-Q8 | R6: =R4-R8 | ... T6: =T4-T8 | V6: Macrotrends was stale/missing for some FY2026 cash-flow and balance-sheet lines; SEC and StockAnalysis were used where Macrotrends was unavailable.
B7: Market cap, $m | C7: =C4*C6 | E7: Gross Margin | F7: =F8/F4 | G7: =G8/G4 | H7: =H8/H4 | I7: =I8/I4 | J7: =J8/J4 | K7: 0.778 | L7: 0.78 | M7: 0.782 | N7: 0.784 | O7: 0.786 | P7: 0.788 | Q7: 0.79 | R7: 0.79 | S7: 0.79 | T7: 0.79
B8: Cash + ST investments, $m | C8: 9565 | E8: Gross Profit | F8: 19466 | G8: 22992 | H8: 26316 | I8: 29252 | J8: 32255 | K8: =K4*K7 | L8: =L4*L7 | M8: =M4*M7 | N8: =N4*N7 | O8: =O4*O7 | P8: =P4*P7 | Q8: =Q4*Q7 | R8: =R4*R7 | ... T8: =T4*T7
B9: Gross debt pro forma, $m | C9: 39500 | E9: R&D | F9: 4465 | G9: 5055 | H9: 4906 | I9: 5493 | J9: 5993 | K9: =K4*K10 | L9: =L4*L10 | M9: =M4*M10 | N9: =N4*N10 | O9: =O4*O10 | P9: =P4*P10 | Q9: =Q4*Q10 | R9: =R4*R10 | ... T9: =T4*T10
B10: Operating leases, $m | C10: 2737 | E10: R&D % Revenue | F10: =F9/F4 | G10: =G9/G4 | H10: =H9/H4 | I10: =I9/I4 | J10: =J9/J4 | K10: 0.144 | L10: 0.142 | M10: 0.14 | N10: 0.138 | O10: 0.136 | P10: 0.134 | Q10: 0.133 | R10: 0.132 | S10: 0.131 | T10: 0.13
B11: Net debt incl leases, $m | C11: =C9+C10-C8 | E11: Sales & Marketing | F11: 11855 | G11: 13526 | H11: 12877 | I11: 13257 | J11: 14345 | K11: =K4*K12 | L11: =L4*L12 | M11: =M4*M12 | N11: =N4*N12 | O11: =O4*O12 | P11: =P4*P12 | Q11: =Q4*Q12 | R11: =R4*R12 | ... T11: =T4*T12
B12: Enterprise value, $m | C12: =C7+C11 | E12: S&M % Revenue | F12: =F11/F4 | G12: =G11/G4 | H12: =H11/H4 | I12: =I11/I4 | J12: =J11/J4 | K12: 0.34 | L12: 0.335 | M12: 0.33 | N12: 0.324 | O12: 0.318 | P12: 0.314 | Q12: 0.31 | R12: 0.306 | S12: 0.303 | T12: 0.3
B13: EV / FY2026 revenue | C13: =C12/J4 | E13: G&A | F13: 2598 | G13: 2553 | H13: 2534 | I13: 2836 | J13: 3000 | K13: =K4*K14 | L13: =L4*L14 | M13: =M4*M14 | N13: =N4*N14 | O13: =O4*O14 | P13: =P4*P14 | Q13: =Q4*Q14 | R13: =R4*R14 | ... T13: =T4*T14
B14: EV / FY2026 FCF | C14: =C12/J29 | E14: G&A % Revenue | F14: =F13/F4 | G14: =G13/G4 | H14: =H13/H4 | I14: =I13/I4 | J14: =J13/J4 | K14: 0.071 | L14: 0.07 | M14: 0.069 | N14: 0.068 | O14: 0.067 | P14: 0.066 | Q14: 0.065 | R14: 0.064 | S14: 0.063 | T14: 0.062
B15: EV / FY2026 owner FCF | C15: =C12/J33 | E15: Operating Expenses | F15: =F6+F9+F11+F13 | G15: =G6+G9+G11+G13 | H15: =H6+H9+H11+H13 | I15: =I6+I9+I11+I13 | J15: =J6+J9+J11+J13 | K15: =K6+K9+K11+K13 | L15: =L6+L9+L11+L13 | M15: =M6+M9+M11+M13 | ... T15: =T6+T9+T11+T13
B16: Headline DCF implied price | C16: =C53 | E16: Operating Income | F16: 548 | G16: 1030 | H16: 5011 | I16: 7205 | J16: 8331 | K16: =K4-K15 | L16: =L4-L15 | M16: =M4-M15 | N16: =N4-N15 | O16: =O4-O15 | P16: =P4-P15 | Q16: =Q4-Q15 | R16: =R4-R15 | ... T16: =T4-T15
B17: Margin of safety | C17: =C53/C4-1 | E17: Operating Margin | F17: =F16/F4 | G17: =G16/G4 | H17: =H16/H4 | I17: =I16/I4 | J17: =J16/J4 | K17: =K16/K4 | L17: =L16/L4 | M17: =M16/M4 | ... T17: =T16/T4
B18: Source note | C18: Uses May 22 close because model date is a U.S. market holiday; ASR share count is provisional until final settlement. | E18: Interest Expense | F18: 216 | G18: 300 | H18: 283 | I18: 272 | J18: 324 | K18: 2050 | L18: 2050 | M18: 2000 | N18: 1950 | O18: 1900 | P18: 1875 | Q18: 1850 | R18: 1825 | S18: 1800 | T18: 1775
E19: Other Non-Operating Income | F19: -227 | G19: -131 | H19: 216 | I19: 354 | J19: 172 | K19: 0 | L19: 0 | M19: 0 | N19: 0 | O19: 0 | P19: 0 | Q19: 0 | R19: 0 | S19: 0 | T19: 0
E20: Pretax Income | F20: 1532 | G20: 660 | H20: 4950 | I20: 7438 | J20: 9520 | K20: =K16-K18+K19 | L20: =L16-L18+L19 | M20: =M16-M18+M19 | N20: =N16-N18+N19 | O20: =O16-O18+O19 | P20: =P16-P18+P19 | Q20: =Q16-Q18+Q19 | R20: =R16-R18+R19 | ... T20: =T16-T18+T19
E21: Taxes | F21: 88 | G21: 452 | H21: 814 | I21: 1241 | J21: 2063 | K21: =K20*K22 | L21: =L20*L22 | M21: =M20*M22 | N21: =N20*N22 | O21: =O20*O22 | P21: =P20*P22 | Q21: =Q20*Q22 | R21: =R20*R22 | ... T21: =T20*T22
E22: Tax Rate | F22: =F21/F20 | G22: =G21/G20 | H22: =H21/H20 | I22: =I21/I20 | J22: =J21/J20 | K22: 0.24 | L22: 0.24 | M22: 0.24 | N22: 0.24 | O22: 0.24 | P22: 0.24 | Q22: 0.24 | R22: 0.24 | S22: 0.24 | T22: 0.24
E23: Net Income | F23: 1444 | G23: 208 | H23: 4136 | I23: 6197 | J23: 7457 | K23: =K20-K21 | L23: =L20-L21 | M23: =M20-M21 | N23: =N20-N21 | O23: =O20-O21 | P23: =P20-P21 | Q23: =Q20-Q21 | R23: =R20-R21 | ... T23: =T20-T21
E24: Net Margin | F24: =F23/F4 | G24: =G23/G4 | H24: =H23/H4 | I24: =I23/I4 | J24: =J23/J4 | K24: =K23/K4 | L24: =L23/L4 | M24: =M23/M4 | ... T24: =T23/T4
E25: Diluted Shares | F25: 974 | G25: 997 | H25: 984 | I25: 974 | J25: 956 | K25: 818.05 | L25: 815 | M25: 812 | N25: 809 | O25: 806 | P25: 803 | Q25: 800 | R25: 798 | S25: 796 | T25: 794
E26: EPS | F26: =F23/F25 | G26: =G23/G25 | H26: =H23/H25 | I26: =I23/I25 | J26: =J23/J25 | K26: =K23/K25 | L26: =L23/L25 | M26: =M23/M25 | ... T26: =T23/T25
E27: Operating Cash Flow | F27: 6000 | G27: 7111 | H27: 10234 | I27: 13092 | J27: 14996 | K27: =K29-K28 | L27: =L29-L28 | M27: =M29-M28 | N27: =N29-N28 | O27: =O29-O28 | P27: =P29-P28 | Q27: =Q29-Q28 | R27: =R29-R28 | ... T27: =T29-T28
E28: Capex | F28: -717 | G28: -798 | H28: -736 | I28: -658 | J28: -594 | K28: =-K4*0.015 | L28: =-L4*0.015 | M28: =-M4*0.0148 | N28: =-N4*0.0147 | O28: =-O4*0.0146 | P28: =-P4*0.0145 | Q28: =-Q4*0.0145 | R28: =-R4*0.0145 | S28: =-S4*0.0145 | T28: =-T4*0.0145
E29: Free Cash Flow | F29: =F27+F28 | G29: =G27+G28 | H29: =H27+H28 | I29: =I27+I28 | J29: =J27+J28 | K29: =K4*K30 | L29: =L4*L30 | M29: =M4*M30 | N29: =N4*N30 | O29: =O4*O30 | P29: =P4*P30 | Q29: =Q4*Q30 | R29: =R4*R30 | ... T29: =T4*T30
E30: FCF Margin | F30: =F29/F4 | G30: =G29/G4 | H30: =H29/H4 | I30: =I29/I4 | J30: =J29/J4 | K30: 0.34 | L30: 0.342 | M30: 0.344 | N30: 0.346 | O30: 0.348 | P30: 0.35 | Q30: 0.35 | R30: 0.35 | S30: 0.35 | T30: 0.35
E31: Stock-Based Compensation | F31: 2779 | G31: 3279 | H31: 2787 | I31: 3183 | J31: 3509 | K31: =K4*K32 | L31: =L4*L32 | M31: =M4*M32 | N31: =N4*N32 | O31: =O4*O32 | P31: =P4*P32 | Q31: =Q4*Q32 | R31: =R4*R32 | ... T31: =T4*T32
E32: SBC % Revenue | F32: =F31/F4 | G32: =G31/G4 | H32: =H31/H4 | I32: =I31/I4 | J32: =J31/J4 | K32: 0.081 | L32: 0.077 | M32: 0.073 | N32: 0.069 | O32: 0.066 | P32: 0.063 | Q32: 0.061 | R32: 0.06 | S32: 0.06 | T32: 0.06
E33: Owner FCF After SBC | F33: =F29-F31 | G33: =G29-G31 | H33: =H29-H31 | I33: =I29-I31 | J33: =J29-J31 | K33: =K29-K31 | L33: =L29-L31 | M33: =M29-M31 | ... T33: =T29-T31
E34: Owner FCF Margin | F34: =F33/F4 | G34: =G33/G4 | H34: =H33/H4 | I34: =I33/I4 | J34: =J33/J4 | K34: =K33/K4 | L34: =L33/L4 | M34: =M33/M4 | ... T34: =T33/T4
E35: Cash + Short-Term Investments | F35: 10537 | G35: 12508 | H35: 14194 | I35: 14032 | J35: 9565
E36: Gross Debt | F36: 10596 | G36: 10601 | H36: 9426 | I36: 8433 | J36: 14439
E37: Operating Lease Liabilities | F37: 3389 | G37: 3487 | H37: 3162 | I37: 2959 | J37: 2737
E38: Net Debt Incl Leases | F38: =F36+F37-F35 | G38: =G36+G37-G35 | H38: =H36+H37-H35 | I38: =I36+I37-I35 | J38: =J36+J37-J35
B43: DCF: Owner FCF After SBC
B44: WACC | C44: =WACC!B13
B45: Terminal growth | C45: 0.03
...

Sheet WACC
A1: WACC / Required Return Inputs
A2: Risk-free rate | B2: 0.0457 | C2: U.S. Treasury / FRED 10-year Treasury near model date; latest available May 22, 2026.
A3: Equity risk premium | B3: 0.05 | C3: Kroll/Damodaran public ERP cross-check; rounded to 5.0% for current U.S. large-cap equity risk.
A4: Beta | B4: 1.14 | C4: StockAnalysis/Yahoo current beta cross-check.
A5: Cost of equity | B5: =B2+B3*B4 | C5: CAPM = risk-free + beta x ERP.
A6: Pre-tax cost of debt | B6: 0.05 | C6: Rounded pro forma debt cost; March 2026 $25B notes had 5.361% weighted coupon, existing debt partly lower.
A7: Tax rate | B7: 0.23 | C7: Normalized U.S. software tax rate; near FY2026 cash/effective tax but not a one-year artifact.
A8: After-tax cost of debt | B8: =B6*(1-B7) | C8: Formula.
A9: Market cap, $m | B9: 147306.26 | C9: May 22, 2026 close price x StockAnalysis shares outstanding.
A10: Gross debt pro forma, $m | B10: 39500 | C10: FY2026 debt plus March 2026 $25B senior notes for ASR.
A11: Equity weight | B11: =B9/(B9+B10) | C11: Market value capital structure.
A12: Debt weight | B12: =B10/(B9+B10) | C12: Gross debt weight.
A13: Calculated WACC | B13: =B11*B5+B12*B8 | C13: Used in base DCF.
A14: Rounded WACC sanity check | B14: 0.09 | C14: Base sensitivity center.

Sheet Scenarios
B2: Bull / Base / Bear Scenario DCFs (full SBC haircut)
O4: Scenario | P4: Implied Price | Q4: Notes
O5: Bear | P5: 96.214471 | Q5: AI seat pressure, weak organic growth, lower FCF conversion; full SBC haircut.
O6: Base | P6: 287.3368 | Q6: FY27 guide midpoint, gradual organic fade, stable high FCF margin; full SBC haircut.
O7: Bull | P7: 521.01658 | Q7: Agentforce/Data 360 reacceleration with durable high incremental margins; full SBC haircut.
B10: Bear Case
C11: FY2026A | D11: FY2027E | E11: FY2028E | F11: FY2029E | G11: FY2030E | H11: FY2031E | I11: FY2032E | J11: FY2033E | K11: FY2034E | L11: FY2035E | M11: FY2036E
B12: Revenue growth | D12: 0.07 | E12: 0.05 | F12: 0.04 | G12: 0.035 | H12: 0.03 | I12: 0.03 | J12: 0.025 | K12: 0.025 | L12: 0.02 | M12: 0.02
B13: Revenue | C13: 41525 | D13: =C13*(1+D12) | E13: =D13*(1+E12) | F13: =E13*(1+F12) | G13: =F13*(1+G12) | H13: =G13*(1+H12) | I13: =H13*(1+I12) | J13: =I13*(1+J12) | K13: =J13*(1+K12) | ... M13: =L13*(1+M12)
B14: Reported FCF margin | D14: 0.3 | E14: 0.292 | F14: 0.285 | G14: 0.275 | H14: 0.27 | I14: 0.265 | J14: 0.262 | K14: 0.26 | L14: 0.26 | M14: 0.26
B15: Reported FCF | D15: =D13*D14 | E15: =E13*E14 | F15: =F13*F14 | G15: =G13*G14 | H15: =H13*H14 | I15: =I13*I14 | J15: =J13*J14 | K15: =K13*K14 | ... M15: =M13*M14
B16: SBC % revenue | D16: 0.085 | E16: 0.083 | F16: 0.08 | G16: 0.078 | H16: 0.075 | I16: 0.072 | J16: 0.07 | K16: 0.068 | L16: 0.065 | M16: 0.065
B17: SBC | D17: =D13*D16 | E17: =E13*E16 | F17: =F13*F16 | G17: =G13*G16 | H17: =H13*H16 | I17: =I13*I16 | J17: =J13*J16 | K17: =K13*K16 | ... M17: =M13*M16
B18: Owner FCF | D18: =D15-D17 | E18: =E15-E17 | F18: =F15-F17 | G18: =G15-G17 | H18: =H15-H17 | I18: =I15-I17 | J18: =J15-J17 | K18: =K15-K17 | ... M18: =M15-M17
B19: Discount factor | D19: =1/(1+D22)^1 | E19: =1/(1+D22)^2 | F19: =1/(1+D22)^3 | G19: =1/(1+D22)^4 | H19: =1/(1+D22)^5 | I19: =1/(1+D22)^6 | J19: =1/(1+D22)^7 | K19: =1/(1+D22)^8 | L19: =1/(1+D22)^9 | M19: =1/(1+D22)^10
B20: PV owner FCF | D20: =D18*D19 | E20: =E18*E19 | F20: =F18*F19 | G20: =G18*G19 | H20: =H18*H19 | I20: =I18*I19 | J20: =J18*J19 | K20: =K18*K19 | ... M20: =M18*M19
B21: Terminal growth | D21: 0.02
B22: WACC | D22: 0.105
B23: Terminal value | D23: =M18*(1+D21)/(D22-D21)
B24: Enterprise value | D24: =SUM(D20:M20)+D23/(1+D22)^10
B25: Equity value | D25: =D24-Valuation!$C$11
B26: Implied price | D26: =D25/Valuation!$C$6
B28: Base Case
C29: FY2026A | D29: FY2027E | E29: FY2028E | F29: FY2029E | G29: FY2030E | H29: FY2031E | I29: FY2032E | J29: FY2033E | K29: FY2034E | L29: FY2035E | M29: FY2036E
B30: Revenue growth | D30: 0.108 | E30: 0.085 | F30: 0.075 | G30: 0.065 | H30: 0.058 | I30: 0.052 | J30: 0.047 | K30: 0.043 | L30: 0.04 | M30: 0.038
B31: Revenue | C31: 41525 | D31: =C31*(1+D30) | E31: =D31*(1+E30) | F31: =E31*(1+F30) | G31: =F31*(1+G30) | H31: =G31*(1+H30) | I31: =H31*(1+I30) | J31: =I31*(1+J30) | K31: =J31*(1+K30) | ... M31: =L31*(1+M30)
B32: Reported FCF margin | D32: 0.34 | E32: 0.342 | F32: 0.344 | G32: 0.346 | H32: 0.348 | I32: 0.35 | J32: 0.35 | K32: 0.35 | L32: 0.35 | M32: 0.35
B33: Reported FCF | D33: =D31*D32 | E33: =E31*E32 | F33: =F31*F32 | G33: =G31*G32 | H33: =H31*H32 | I33: =I31*I32 | J33: =J31*J32 | K33: =K31*K32 | ... M33: =M31*M32
B34: SBC % revenue | D34: 0.081 | E34: 0.077 | F34: 0.073 | G34: 0.069 | H34: 0.066 | I34: 0.063 | J34: 0.061 | K34: 0.06 | L34: 0.06 | M34: 0.06
B35: SBC | D35: =D31*D34 | E35: =E31*E34 | F35: =F31*F34 | G35: =G31*G34 | H35: =H31*H34 | I35: =I31*I34 | J35: =J31*J34 | K35: =K31*K34 | ... M35: =M31*M34
B36: Owner FCF | D36: =D33-D35 | E36: =E33-E35 | F36: =F33-F35 | G36: =G33-G35 | H36: =H33-H35 | I36: =I33-I35 | J36: =J33-J35 | K36: =K33-K35 | ... M36: =M33-M35
B37: Discount factor | D37: =1/(1+D40)^1 | E37: =1/(1+D40)^2 | F37: =1/(1+D40)^3 | G37: =1/(1+D40)^4 | H37: =1/(1+D40)^5 | I37: =1/(1+D40)^6 | J37: =1/(1+D40)^7 | K37: =1/(1+D40)^8 | L37: =1/(1+D40)^9 | M37: =1/(1+D40)^10
B38: PV owner FCF | D38: =D36*D37 | E38: =E36*E37 | F38: =F36*F37 | G38: =G36*G37 | H38: =H36*H37 | I38: =I36*I37 | J38: =J36*J37 | K38: =K36*K37 | ... M38: =M36*M37
B39: Terminal growth | D39: 0.03
B40: WACC | D40: 0.089124973
B41: Terminal value | D41: =M36*(1+D39)/(D40-D39)
B42: Enterprise value | D42: =SUM(D38:M38)+D41/(1+D40)^10
B43: Equity value | D43: =D42-Valuation!$C$11
B44: Implied price | D44: =D43/Valuation!$C$6
B46: Bull Case
...

Sheet Actuals Source Audit
A1: Line item | B1: Fiscal period | C1: Model value | D1: Unit | E1: Primary SEC value | F1: Primary source | G1: SEC concept / accession | H1: StockAnalysis value | I1: StockAnalysis URL | J1: Macrotrends value | K1: Macrotrends URL | L1: Difference / discrepancy | M1: Resolution note | N1: Model cell
A2: Revenue | B2: FY2022 | C2: 26492 | D2: USD $m | E2: 26492 | F2: SEC company facts / Form 10-K | G2: RevenueFromContractWithCustomerExcludingAssessedTax; 0001108524-26-000060 for latest 10-K | H2: 26492 | I2: https://stockanalysis.com/stocks/crm/financials/ | J2: 26492 | K2: https://www.macrotrends.net/stocks/charts/CRM/salesforce/revenue | L2: 0 | M2: Matches SEC/StockAnalysis/Macrotrends. | N2: Valuation!F4
A3: Revenue | B3: FY2023 | C3: 31352 | D3: USD $m | E3: 31352 | F3: SEC company facts / Form 10-K | G3: RevenueFromContractWithCustomerExcludingAssessedTax; 0001108524-26-000060 for latest 10-K | H3: 31352 | I3: https://stockanalysis.com/stocks/crm/financials/ | J3: 31352 | K3: https://www.macrotrends.net/stocks/charts/CRM/salesforce/revenue | L3: 0 | M3: Matches SEC/StockAnalysis/Macrotrends. | N3: Valuation!G4
A4: Revenue | B4: FY2024 | C4: 34857 | D4: USD $m | E4: 34857 | F4: SEC company facts / Form 10-K | G4: RevenueFromContractWithCustomerExcludingAssessedTax; 0001108524-26-000060 for latest 10-K | H4: 34857 | I4: https://stockanalysis.com/stocks/crm/financials/ | J4: 34857 | K4: https://www.macrotrends.net/stocks/charts/CRM/salesforce/revenue | L4: 0 | M4: Matches SEC/StockAnalysis/Macrotrends. | N4: Valuation!H4
A5: Revenue | B5: FY2025 | C5: 37895 | D5: USD $m | E5: 37895 | F5: SEC company facts / Form 10-K | G5: RevenueFromContractWithCustomerExcludingAssessedTax; 0001108524-26-000060 for latest 10-K | H5: 37895 | I5: https://stockanalysis.com/stocks/crm/financials/ | J5: 37895 | K5: https://www.macrotrends.net/stocks/charts/CRM/salesforce/revenue | L5: 0 | M5: Matches SEC/StockAnalysis/Macrotrends. | N5: Valuation!I4
A6: Revenue | B6: FY2026 | C6: 41525 | D6: USD $m | E6: 41525 | F6: SEC company facts / Form 10-K | G6: RevenueFromContractWithCustomerExcludingAssessedTax; 0001108524-26-000060 for latest 10-K | H6: 41525 | I6: https://stockanalysis.com/stocks/crm/financials/ | J6: 41525 | K6: https://www.macrotrends.net/stocks/charts/CRM/salesforce/revenue | L6: 0 | M6: Matches SEC/StockAnalysis/Macrotrends. | N6: Valuation!J4
A7: Gross Profit | B7: FY2022 | C7: 19466 | D7: USD $m | E7: 19466 | F7: SEC company facts / Form 10-K | G7: GrossProfit; 0001108524-26-000060 for latest 10-K | H7: 19466 | I7: https://stockanalysis.com/stocks/crm/financials/ | J7: 19466 | K7: https://www.macrotrends.net/stocks/charts/CRM/salesforce/gross-profit | L7: 0 | M7: Matches SEC/StockAnalysis/Macrotrends. | N7: Valuation!F8
A8: Gross Profit | B8: FY2023 | C8: 22992 | D8: USD $m | E8: 22992 | F8: SEC company facts / Form 10-K | G8: GrossProfit; 0001108524-26-000060 for latest 10-K | H8: 22992 | I8: https://stockanalysis.com/stocks/crm/financials/ | J8: 22992 | K8: https://www.macrotrends.net/stocks/charts/CRM/salesforce/gross-profit | L8: 0 | M8: Matches SEC/StockAnalysis/Macrotrends. | N8: Valuation!G8
A9: Gross Profit | B9: FY2024 | C9: 26316 | D9: USD $m | E9: 26316 | F9: SEC company facts / Form 10-K | G9: GrossProfit; 0001108524-26-000060 for latest 10-K | H9: 26316 | I9: https://stockanalysis.com/stocks/crm/financials/ | J9: 26316 | K9: https://www.macrotrends.net/stocks/charts/CRM/salesforce/gross-profit | L9: 0 | M9: Matches SEC/StockAnalysis/Macrotrends. | N9: Valuation!H8
A10: Gross Profit | B10: FY2025 | C10: 29252 | D10: USD $m | E10: 29252 | F10: SEC company facts / Form 10-K | G10: GrossProfit; 0001108524-26-000060 for latest 10-K | H10: 29252 | I10: https://stockanalysis.com/stocks/crm/financials/ | J10: 29252 | K10: https://www.macrotrends.net/stocks/charts/CRM/salesforce/gross-profit | L10: 0 | M10: Matches SEC/StockAnalysis/Macrotrends. | N10: Valuation!I8
A11: Gross Profit | B11: FY2026 | C11: 32255 | D11: USD $m | E11: 32255 | F11: SEC company facts / Form 10-K | G11: GrossProfit; 0001108524-26-000060 for latest 10-K | H11: 32255 | I11: https://stockanalysis.com/stocks/crm/financials/ | J11: 32255 | K11: https://www.macrotrends.net/stocks/charts/CRM/salesforce/gross-profit | L11: 0 | M11: Matches SEC/StockAnalysis/Macrotrends. | N11: Valuation!J8
A12: Operating Income | B12: FY2022 | C12: 548 | D12: USD $m | E12: 548 | F12: SEC company facts / Form 10-K | G12: OperatingIncomeLoss; 0001108524-26-000060 for latest 10-K | H12: 548 | I12: https://stockanalysis.com/stocks/crm/financials/ | J12: 548 | K12: https://www.macrotrends.net/stocks/charts/CRM/salesforce/operating-income | L12: 0 | M12: Matches SEC/StockAnalysis/Macrotrends. | N12: Valuation!F16
A13: Operating Income | B13: FY2023 | C13: 1030 | D13: USD $m | E13: 1030 | F13: SEC company facts / Form 10-K | G13: OperatingIncomeLoss; 0001108524-26-000060 for latest 10-K | H13: 1030 | I13: https://stockanalysis.com/stocks/crm/financials/ | J13: 1030 | K13: https://www.macrotrends.net/stocks/charts/CRM/salesforce/operating-income | L13: 0 | M13: Matches SEC/StockAnalysis/Macrotrends. | N13: Valuation!G16
... A21: Net Income | B21: FY2026 | C21: 7457 | D21: USD $m | E21: 7457 | F21: SEC company facts / Form 10-K | G21: NetIncomeLoss; 0001108524-26-000060 for latest 10-K | H21: 7457 | I21: https://stockanalysis.com/stocks/crm/financials/ | J21: 7457 | K21: https://www.macrotrends.net/stocks/charts/CRM/salesforce/net-income | L21: 0 | M21: Matches SEC/StockAnalysis/Macrotrends. | N21: Valuation!J23
A22: Operating Cash Flow | B22: FY2022 | C22: 6000 | D22: USD $m | E22: 6000 | F22: SEC company facts / Form 10-K | G22: NetCashProvidedByUsedInOperatingActivities; 0001108524-26-000060 for latest 10-K | H22: 6000 | I22: https://stockanalysis.com/stocks/crm/financials/cash-flow-statement/ | J22: N/A | K22: N/A | L22: N/A | M22: Primary SEC and StockAnalysis used; secondary source unavailable or stale for this line. | N22: Valuation!F27
A23: Operating Cash Flow | B23: FY2023 | C23: 7111 | D23: USD $m | E23: 7111 | F23: SEC company facts / Form 10-K | G23: NetCashProvidedByUsedInOperatingActivities; 0001108524-26-000060 for latest 10-K | H23: 7111 | I23: https://stockanalysis.com/stocks/crm/financials/cash-flow-statement/ | J23: N/A | K23: N/A | L23: N/A | M23: Primary SEC and StockAnalysis used; secondary source unavailable or stale for this line. | N23: Valuation!G27
A24: Operating Cash Flow | B24: FY2024 | C24: 10234 | D24: USD $m | E24: 10234 | F24: SEC company facts / Form 10-K | G24: NetCashProvidedByUsedInOperatingActivities; 0001108524-26-000060 for latest 10-K | H24: 10234 | I24: https://stockanalysis.com/stocks/crm/financials/cash-flow-statement/ | J24: N/A | K24: N/A | L24: N/A | M24: Primary SEC and StockAnalysis used; secondary source unavailable or stale for this line. | N24: Valuation!H27
A25: Operating Cash Flow | B25: FY2025 | C25: 13092 | D25: USD $m | E25: 13092 | F25: SEC company facts / Form 10-K | G25: NetCashProvidedByUsedInOperatingActivities; 0001108524-26-000060 for latest 10-K | H25: 13092 | I25: https://stockanalysis.com/stocks/crm/financials/cash-flow-statement/ | J25: N/A | K25: N/A | L25: N/A | M25: Primary SEC and StockAnalysis used; secondary source unavailable or stale for this line. | N25: Valuation!I27
A26: Operating Cash Flow | B26: FY2026 | C26: 14996 | D26: USD $m | E26: 14996 | F26: SEC company facts / Form 10-K | G26: NetCashProvidedByUsedInOperatingActivities; 0001108524-26-000060 for latest 10-K | H26: 14996 | I26: https://stockanalysis.com/stocks/crm/financials/cash-flow-statement/ | J26: N/A | K26: N/A | L26: N/A | M26: Primary SEC and StockAnalysis used; secondary source unavailable or stale for this line. | N26: Valuation!J27
A27: Capex | B27: FY2022 | C27: -717 | D27: USD $m | E27: 717 | F27: SEC company facts / Form 10-K | G27: PaymentsToAcquirePropertyPlantAndEquipment; 0001108524-26-000060 for latest 10-K | H27: -717 | I27: https://stockanalysis.com/stocks/crm/financials/cash-flow-statement/ | J27: N/A | K27: N/A | L27: Sign convention only. | M27: Model stores capex as a cash outflow sign; SEC payments tag is positive. | N27: Valuation!F28
A28: Capex | B28: FY2023 | C28: -798 | D28: USD $m | E28: 798 | F28: SEC company facts / Form 10-K | G28: PaymentsToAcquirePropertyPlantAndEquipment; 0001108524-26-000060 for latest 10-K | H28: -798 | I28: https://stockanalysis.com/stocks/crm/financials/cash-flow-statement/ | J28: N/A | K28: N/A | L28: Sign convention only. | M28: Model stores capex as a cash outflow sign; SEC payments tag is positive. | N28: Valuation!G28
A29: Capex | B29: FY2024 | C29: -736 | D29: USD $m | E29: 736 | F29: SEC company facts / Form 10-K | G29: PaymentsToAcquirePropertyPlantAndEquipment; 0001108524-26-000060 for latest 10-K | H29: -736 | I29: https://stockanalysis.com/stocks/crm/financials/cash-flow-statement/ | J29: N/A | K29: N/A | L29: Sign convention only. | M29: Model stores capex as a cash outflow sign; SEC payments tag is positive. | N29: Valuation!H28
A30: Capex | B30: FY2025 | C30: -658 | D30: USD $m | E30: 658 | F30: SEC company facts / Form 10-K | G30: PaymentsToAcquirePropertyPlantAndEquipment; 0001108524-26-000060 for latest 10-K | H30: -658 | I30: https://stockanalysis.com/stocks/crm/financials/cash-flow-statement/ | J30: N/A | K30: N/A | L30: Sign convention only. | M30: Model stores capex as a cash outflow sign; SEC payments tag is positive. | N30: Valuation!I28
A31: Capex | B31: FY2026 | C31: -594 | D31: USD $m | E31: 594 | F31: SEC company facts / Form 10-K | G31: PaymentsToAcquirePropertyPlantAndEquipment; 0001108524-26-000060 for latest 10-K | H31: -594 | I31: https://stockanalysis.com/stocks/crm/financials/cash-flow-statement/ | J31: N/A | K31: N/A | L31: Sign convention only. | M31: Model stores capex as a cash outflow sign; SEC payments tag is positive. | N31: Valuation!J28
A32: Free Cash Flow | B32: FY2022 | C32: 5283 | D32: USD $m | E32: 5283 | F32: SEC company facts / Form 10-K | G32: OCF less capex; 0001108524-26-000060 for latest 10-K | H32: 5283 | I32: https://stockanalysis.com/stocks/crm/financials/cash-flow-statement/ | J32: 5283 | K32: https://www.macrotrends.net/stocks/charts/CRM/salesforce/free-cash-flow | L32: 0 | M32: Matches SEC/StockAnalysis/Macrotrends. | N32: Valuation!F29
A33: Free Cash Flow | B33: FY2023 | C33: 6313 | D33: USD $m | E33: 6313 | F33: SEC company facts / Form 10-K | G33: OCF less capex; 0001108524-26-000060 for latest 10-K | H33: 6313 | I33: https://stockanalysis.com/stocks/crm/financials/cash-flow-statement/ | J33: 6313 | K33: https://www.macrotrends.net/stocks/charts/CRM/salesforce/free-cash-flow | L33: 0 | M33: Matches SEC/StockAnalysis/Macrotrends. | N33: Valuation!G29
A34: Free Cash Flow | B34: FY2024 | C34: 9498 | D34: USD $m | E34: 9498 | F34: SEC company facts / Form 10-K | G34: OCF less capex; 0001108524-26-000060 for latest 10-K | H34: 9498 | I34: https://stockanalysis.com/stocks/crm/financials/cash-flow-statement/ | J34: 9498 | K34: https://www.macrotrends.net/stocks/charts/CRM/salesforce/free-cash-flow | L34: 0 | M34: Matches SEC/StockAnalysis/Macrotrends. | N34: Valuation!H29
A35: Free Cash Flow | B35: FY2025 | C35: 12434 | D35: USD $m | E35: 12434 | F35: SEC company facts / Form 10-K | G35: OCF less capex; 0001108524-26-000060 for latest 10-K | H35: 12434 | I35: https://stockanalysis.com/stocks/crm/financials/cash-flow-statement/ | J35: 12434 | K35: https://www.macrotrends.net/stocks/charts/CRM/salesforce/free-cash-flow | L35: 0 | M35: Matches SEC/StockAnalysis/Macrotrends. | N35: Valuation!I29
A36: Free Cash Flow | B36: FY2026 | C36: 14402 | D36: USD $m | E36: 14402 | F36: SEC company facts / Form 10-K | G36: OCF less capex; 0001108524-26-000060 for latest 10-K | H36: 14402 | I36: https://stockanalysis.com/stocks/crm/financials/cash-flow-statement/ | J36: N/A | K36: https://www.macrotrends.net/stocks/charts/CRM/salesforce/free-cash-flow | L36: N/A | M36: Primary SEC and StockAnalysis used; secondary source unavailable or stale for this line. | N36: Valuation!J29
A37: Stock-Based Compensation | B37: FY2022 | C37: 2779 | D37: USD $m | E37: 2779 | F37: SEC company facts / Form 10-K | G37: ShareBasedCompensation; 0001108524-26-000060 for latest 10-K | H37: 2779 | I37: https://stockanalysis.com/stocks/crm/financials/cash-flow-statement/ | J37: N/A | K37: N/A | L37: N/A | M37: Primary SEC and StockAnalysis used; secondary source unavailable or stale for this line. | N37: Valuation!F31
A38: Stock-Based Compensation | B38: FY2023 | C38: 3279 | D38: USD $m | E38: 3279 | F38: SEC company facts / Form 10-K | G38: ShareBasedCompensation; 0001108524-26-000060 for latest 10-K | H38: 3279 | I38: https://stockanalysis.com/stocks/crm/financials/cash-flow-statement/ | J38: N/A | K38: N/A | L38: N/A | M38: Primary SEC and StockAnalysis used; secondary source unavailable or stale for this line. | N38: Valuation!G31
A39: Stock-Based Compensation | B39: FY2024 | C39: 2787 | D39: USD $m | E39: 2787 | F39: SEC company facts / Form 10-K | G39: ShareBasedCompensation; 0001108524-26-000060 for latest 10-K | H39: 2787 | I39: https://stockanalysis.com/stocks/crm/financials/cash-flow-statement/ | J39: N/A | K39: N/A | L39: N/A | M39: Primary SEC and StockAnalysis used; secondary source unavailable or stale for this line. | N39: Valuation!H31
A40: Stock-Based Compensation | B40: FY2025 | C40: 3183 | D40: USD $m | E40: 3183 | F40: SEC company facts / Form 10-K | G40: ShareBasedCompensation; 0001108524-26-000060 for latest 10-K | H40: 3183 | I40: https://stockanalysis.com/stocks/crm/financials/cash-flow-statement/ | J40: N/A | K40: N/A | L40: N/A | M40: Primary SEC and StockAnalysis used; secondary source unavailable or stale for this line. | N40: Valuation!I31
A41: Stock-Based Compensation | B41: FY2026 | C41: 3509 | D41: USD $m | E41: 3509 | F41: SEC company facts / Form 10-K | G41: ShareBasedCompensation; 0001108524-26-000060 for latest 10-K | H41: 3509 | I41: https://stockanalysis.com/stocks/crm/financials/cash-flow-statement/ | J41: N/A | K41: N/A | L41: N/A | M41: Primary SEC and StockAnalysis used; secondary source unavailable or stale for this line. | N41: Valuation!J31
A42: Diluted Shares | B42: FY2022 | C42: 974 | D42: mm shares | E42: 974 | F42: SEC company facts / Form 10-K | G42: WeightedAverageNumberOfDilutedSharesOutstanding; 0001108524-26-000060 for latest 10-K | H42: 974 | I42: https://stockanalysis.com/stocks/crm/financials/ | J42: N/A | K42: N/A | L42: N/A | M42: Primary SEC and StockAnalysis used; secondary source unavailable or stale for this line. | N42: Valuation!F25
A43: Diluted Shares | B43: FY2023 | C43: 997 | D43: mm shares | E43: 997 | F43: SEC company facts / Form 10-K | G43: WeightedAverageNumberOfDilutedSharesOutstanding; 0001108524-26-000060 for latest 10-K | H43: 997 | I43: https://stockanalysis.com/stocks/crm/financials/ | J43: N/A | K43: N/A | L43: N/A | M43: Primary SEC and StockAnalysis used; secondary source unavailable or stale for this line. | N43: Valuation!G25
A44: Diluted Shares | B44: FY2024 | C44: 984 | D44: mm shares | E44: 984 | F44: SEC company facts / Form 10-K | G44: WeightedAverageNumberOfDilutedSharesOutstanding; 0001108524-26-000060 for latest 10-K | H44: 984 | I44: https://stockanalysis.com/stocks/crm/financials/ | J44: N/A | K44: N/A | L44: N/A | M44: Primary SEC and StockAnalysis used; secondary source unavailable or stale for this line. | N44: Valuation!H25
A45: Diluted Shares | B45: FY2025 | C45: 974 | D45: mm shares | E45: 974 | F45: SEC company facts / Form 10-K | G45: WeightedAverageNumberOfDilutedSharesOutstanding; 0001108524-26-000060 for latest 10-K | H45: 974 | I45: https://stockanalysis.com/stocks/crm/financials/ | J45: N/A | K45: N/A | L45: N/A | M45: Primary SEC and StockAnalysis used; secondary source unavailable or stale for this line. | N45: Valuation!I25
A46: Diluted Shares | B46: FY2026 | C46: 956 | D46: mm shares | E46: 956 | F46: SEC company facts / Form 10-K | G46: WeightedAverageNumberOfDilutedSharesOutstanding; 0001108524-26-000060 for latest 10-K | H46: 956 | I46: https://stockanalysis.com/stocks/crm/financials/ | J46: N/A | K46: N/A | L46: N/A | M46: Primary SEC and StockAnalysis used; secondary source unavailable or stale for this line. | N46: Valuation!J25
A47: Cash + Short-Term Investments | B47: FY2022 | C47: 10537 | D47: USD $m | E47: 10537 | F47: SEC company facts / Form 10-K | G47: Cash + AvailableForSaleSecuritiesDebtSecuritiesCurrent; 0001108524-26-000060 for latest 10-K | H47: 10537 | I47: https://stockanalysis.com/stocks/crm/financials/balance-sheet/ | J47: 10537 | K47: https://www.macrotrends.net/stocks/charts/CRM/salesforce/cash-on-hand | L47: 0 | M47: Matches SEC/StockAnalysis/Macrotrends. | N47: Valuation!F35
...

Sheet Questions
B3: Questions
B5: What are Agentforce and Data 360 doing that Microsoft, ServiceNow, Snowflake, Databricks, and AI-native vendors cannot bundle away?
B6: Does Agentforce ARR convert into high-quality usage revenue, or is deal count ahead of economic adoption?
B7: Will AI agents expand customer workflow value or reduce the number/value of human CRM seats?
B8: Can organic cRPO and subscription growth reaccelerate in H2 FY2027 after stripping out Informatica?
B9: Is the March 2026 debt-funded ASR value-accretive, or did it reduce balance-sheet flexibility before the AI transition is proven?
B10: How much of free cash flow is owner cash flow after full SBC, restructuring, acquisition costs, and integration spend?
B11: Will Salesforce continue to improve GAAP operating margin without starving product velocity?
B12: How should investors value strategic investments and acquired intangible amortization when measuring owner economics?
B13: What would prove that Slack, MuleSoft, Tableau, and Informatica are increasing platform lock-in rather than adding complexity?
B14: What evidence would make the bear case decisive: seat pressure, cRPO deceleration, churn, Data 360 weakness, or FCF margin reversal?

Sheet Sources
A1: Category | B1: Source | C1: Date / as-of | D1: Use in model
A2: Primary filing | B2: https://www.sec.gov/Archives/edgar/data/1108524/000110852426000060/crm-20260131.htm | C2: Filed 2026-03-02 | D2: FY2026 Form 10-K; historical statements and balance sheet.
A3: Primary XBRL | B3: https://data.sec.gov/api/xbrl/companyfacts/CIK0001108524.json | C3: Fetched 2026-05-25 | D3: SEC company facts extraction for actuals and audit values.
A4: Company release | B4: https://www.salesforce.com/news/press-releases/2026/02/25/fy26-q4-earnings/ | C4: 2026-02-25 | D4: FY2026 results highlights, FY2027 guidance, RPO, Agentforce ARR, Data 360 metrics.
A5: SEC 424B2 | B5: https://www.sec.gov/Archives/edgar/data/1108524/000119312526104301/d29877d424b2.htm | C5: Filed 2026-03-12 | D5: March 2026 $25B senior notes; coupon schedule and use of proceeds for ASR.
A6: SEC 8-K | B6: https://www.sec.gov/Archives/edgar/data/1108524/000119312526104282/d887348d8k.htm | C6: Filed 2026-03-12 | D6: ASR agreement terms and 80% initial delivery mechanics.
A7: Market data | B7: https://stockanalysis.com/stocks/crm/ | C7: As of 2026-05-22 close | D7: Price, shares outstanding, market cap, beta, quote timestamp.
A8: Secondary financials | B8: https://stockanalysis.com/stocks/crm/financials/ | C8: Pulled 2026-05-25 | D8: Income statement and headline FCF cross-check.
A9: Secondary financials | B9: https://stockanalysis.com/stocks/crm/financials/cash-flow-statement/ | C9: Pulled 2026-05-25 | D9: Operating cash flow, capex, FCF cross-check.
A10: Secondary financials | B10: https://stockanalysis.com/stocks/crm/financials/balance-sheet/ | C10: Pulled 2026-05-25 | D10: Cash, short-term investments, debt cross-check.
A11: Secondary financials | B11: https://www.macrotrends.net/stocks/charts/CRM/salesforce/revenue | C11: Pulled 2026-05-25 | D11: Revenue cross-check.
A12: Secondary financials | B12: https://www.macrotrends.net/stocks/charts/CRM/salesforce/gross-profit | C12: Pulled 2026-05-25 | D12: Gross profit cross-check.
... A16: ERP | B16: https://www.kroll.com/en/insights/publications/cost-of-capital/recommended-us-equity-risk-premium-and-corresponding-risk-free-rates | C16: 2026 public update | D16: U.S. ERP sanity check; rounded to 5.0%.
