Workbook

Sheet Valuation
B2: FactSet Research Systems Inc. (NYSE: FDS) | E2: FactSet | F2: Fiscal years ending Aug. 31; USD millions except per-share data | V2: Key limitations
B3: Model date | C3: 2026-05-26 | F3: FY2021 | G3: FY2022 | H3: FY2023 | I3: FY2024 | J3: FY2025 | K3: TTM 2/28/26 | L3: FY2026E | M3: FY2027E | N3: FY2028E | O3: FY2029E | P3: FY2030E | Q3: FY2031E | R3: FY2032E | S3: FY2033E | T3: FY2034E | U3: FY2035E
B4: Price | C4: 232 | E4: Revenue | F4: 1591.445 | G4: 1843.892 | H4: 2085.508 | I4: 2203.056 | J4: 2321.748 | K4: 2401.061 | L4: 2460 | M4: =L4*(1+M5) | N4: =M4*(1+N5) | O4: =N4*(1+O5) | P4: =O4*(1+P5) | Q4: =P4*(1+Q5) | R4: =Q4*(1+R5) | S4: =R4*(1+S5) | T4: =S4*(1+T5) | U4: =T4*(1+U5) | V4: Latest clean regular-session quote available in the public pages used here is 2026-05-22; U.S. market was closed 2026-05-25.
B5: Quote date | C5: 2026-05-22 close | E5: Revenue Growth | G5: =G4/F4-1 | H5: =H4/G4-1 | I5: =I4/H4-1 | J5: =J4/I4-1 | K5: =K4/J4-1 | L5: 0.059546514 | M5: 0.067479675 | N5: 0.055 | O5: 0.05 | P5: 0.046 | Q5: 0.043 | R5: 0.04 | S5: 0.038 | T5: 0.036 | U5: 0.034 | V5: Latest filed quarterly actuals are Q2 FY2026 for the quarter ended 2026-02-28; Q3 FY2026 was not filed as of the 2026-05-26 model date.
B6: Diluted / current shares, mm | C6: 36.431127 | E6: Cost of Revenue | F6: 786.395 | G6: 871.102 | H6: 973.208 | I6: 1011.956 | J6: 1097.748 | K6: 1154.061 | L6: =L4-L8 | M6: =M4-M8 | N6: =N4-N8 | O6: =O4-O8 | P6: =P4-P8 | Q6: =Q4-Q8 | R6: =R4-R8 | S6: =S4-S8 | ... U6: =U4-U8 | V6: TTM values use StockAnalysis / filing-based trailing figures where available; SEC filings remain the source of truth for annual reported actuals.
B7: Market cap, $m | C7: =C4*C6 | E7: Gross Margin | F7: =F8/F4 | G7: =G8/G4 | H7: =H8/H4 | I7: =I8/I4 | J7: =J8/J4 | K7: =K8/K4 | L7: 0.52 | M7: 0.522 | N7: 0.525 | O7: 0.527 | P7: 0.529 | Q7: 0.53 | R7: 0.53 | S7: 0.531 | T7: 0.531 | U7: 0.531 | V7: Headline DCF subtracts 100% of SBC from FCF. Reported FCF DCF is shown as an upside cross-check, not the primary owner-earnings view.
B8: Cash + ST investments, $m | C8: 285.267 | E8: Gross Profit | F8: 805.05 | G8: 972.79 | H8: 1112.3 | I8: 1191.1 | J8: 1224 | K8: 1247 | L8: =L4*L7 | M8: =M4*M7 | N8: =N4*N7 | O8: =O4*O7 | P8: =P4*P7 | Q8: =Q4*Q7 | R8: =R4*R7 | S8: =S4*S7 | ... U8: =U4*U7 | V8: FDS reports cost of services and SG&A; this model does not invent a Salesforce-style R&D / S&M / G&A split.
B9: Gross debt, $m | C9: 1369.216 | E9: SG&A / Other OpEx | F9: 331.009 | G9: 497.308 | H9: 483.093 | I9: 489.801 | J9: 475.697 | K9: 498.492 | L9: =L8-L16 | M9: =M8-M16 | N9: =N8-N16 | O9: =O8-O16 | P9: =P8-P16 | Q9: =Q8-Q16 | R9: =R8-R16 | S9: =S8-S16 | ... U9: =U8-U16 | V9: Internal-control material weakness in ITGCs supporting revenue, A/R, and deferred revenue remains an underwriting risk until remediated.
B10: Operating leases, $m | C10: 184.441 | E10: OpEx % Revenue | F10: =F9/F4 | G10: =G9/G4 | H10: =H9/H4 | I10: =I9/I4 | J10: =J9/J4 | K10: =K9/K4 | L10: =L9/L4 | M10: =M9/M4 | ... U10: =U9/U4
B11: Net debt incl leases, $m | C11: =C9+C10-C8 | E11: Adjusted Operating Income | F11: =F16 | G11: =G16 | H11: =H16 | I11: =I16 | J11: =J16 | K11: =K16 | L11: =L16+70 | M11: =M16+75 | N11: =N16+75 | O11: =O16+75 | P11: =P16+75 | Q11: =Q16+75 | R11: =R16+75 | S11: =S16+75 | T11: =T16+75 | U11: =U16+75
B12: Enterprise value, $m | C12: =C7+C11 | E12: Adjusted Operating Margin | F12: =F11/F4 | G12: =G11/G4 | H12: =H11/H4 | I12: =I11/I4 | J12: =J11/J4 | K12: =K11/K4 | L12: =L11/L4 | M12: =M11/M4 | ... U12: =U11/U4
B13: EV / TTM revenue | C13: =C12/K4 | E13: Total Operating Costs | F13: =F6+F9 | G13: =G6+G9 | H13: =H6+H9 | I13: =I6+I9 | J13: =J6+J9 | K13: =K6+K9 | L13: =L6+L9 | M13: =M6+M9 | ... U13: =U6+U9
B14: EV / TTM FCF | C14: =C12/K29 | E14: Total Operating Cost % Revenue | F14: =F13/F4 | G14: =G13/G4 | H14: =H13/H4 | I14: =I13/I4 | J14: =J13/J4 | K14: =K13/K4 | L14: =L13/L4 | M14: =M13/M4 | ... U14: =U13/U4
B15: EV / TTM owner FCF | C15: =C12/K33
B16: Headline DCF implied price | C16: =C53 | E16: Operating Income | F16: 474.041 | G16: 475.482 | H16: 629.207 | I16: 701.299 | J16: 748.303 | K16: 748.508 | L16: =L4*0.305 | M16: =M4*0.31 | N16: =N4*0.313 | O16: =O4*0.316 | P16: =P4*0.318 | Q16: =Q4*0.32 | R16: =R4*0.321 | S16: =S4*0.322 | T16: =T4*0.323 | U16: =U4*0.324
B17: Margin of safety | C17: =C53/C4-1 | E17: Operating Margin | F17: =F16/F4 | G17: =G16/G4 | H17: =H16/H4 | I17: =I16/I4 | J17: =J16/J4 | K17: =K16/K4 | L17: =L16/L4 | M17: =M16/M4 | ... U17: =U16/U4
B18: Source note | C18: Price from public quote pages / Stooq close; capital structure from Q2 FY2026 10-Q. | E18: Interest Expense | F18: 8.2 | G18: 35.7 | H18: 66.32 | I18: 65.78 | J18: 56.32 | K18: 54.46 | L18: 55 | M18: 54 | N18: 53 | O18: 52 | P18: 51 | Q18: 50 | R18: 49 | S18: 48 | T18: 47 | U18: 46
E19: Other Non-Operating Income | F19: 1.78 | G19: 3.81 | H19: 21.07 | I19: 15.99 | J19: 28.98 | K19: 26.07 | L19: 10 | M19: 10 | N19: 10 | O19: 10 | P19: 10 | Q19: 10 | R19: 10 | S19: 10 | T19: 10 | U19: 10
E20: Pretax Income | F20: 467.617 | G20: 443.594 | H20: 583.954 | I20: 651.503 | J20: 720.958 | K20: 720.12 | L20: =L16-L18+L19 | M20: =M16-M18+M19 | N20: =N16-N18+N19 | O20: =O16-O18+O19 | P20: =P16-P18+P19 | Q20: =Q16-Q18+Q19 | R20: =R16-R18+R19 | S20: =S16-S18+S19 | ... U20: =U16-U18+U19
E21: Taxes | F21: 68.027 | G21: 46.677 | H21: 115.781 | I21: 114.377 | J21: 123.918 | K21: 132.33 | L21: =L20*L22 | M21: =M20*M22 | N21: =N20*N22 | O21: =O20*O22 | P21: =P20*P22 | Q21: =Q20*Q22 | R21: =R20*R22 | S21: =S20*S22 | ... U21: =U20*U22
E22: Tax Rate | F22: =F21/F20 | G22: =G21/G20 | H22: =H21/H20 | I22: =I21/I20 | J22: =J21/J20 | K22: =K21/K20 | L22: 0.185 | M22: 0.19 | N22: 0.19 | O22: 0.19 | P22: 0.19 | Q22: 0.19 | R22: 0.19 | S22: 0.19 | T22: 0.19 | U22: 0.19
E23: Net Income | F23: 399.59 | G23: 396.917 | H23: 468.173 | I23: 537.126 | J23: 597.04 | K23: 587.794 | L23: =L20-L21 | M23: =M20-M21 | N23: =N20-N21 | O23: =O20-O21 | P23: =P20-P21 | Q23: =Q20-Q21 | R23: =R20-R21 | S23: =S20-S21 | ... U23: =U20-U21
E24: Net Margin | F24: =F23/F4 | G24: =G23/G4 | H24: =H23/H4 | I24: =I23/I4 | J24: =J23/J4 | K24: =K23/K4 | L24: =L23/L4 | M24: =M23/M4 | ... U24: =U23/U4
E25: Diluted Shares | F25: 38.57 | G25: 38.736 | H25: 38.898 | I25: 38.618 | J25: 38.385 | K25: 37.84 | L25: 36.43 | M25: 36.05 | N25: 35.65 | O25: 35.25 | P25: 34.85 | Q25: 34.5 | R25: 34.15 | S25: 33.85 | T25: 33.55 | U25: 33.25
E26: EPS | F26: =F23/F25 | G26: =G23/G25 | H26: =H23/H25 | I26: =I23/I25 | J26: =J23/J25 | K26: =K23/K25 | L26: =L23/L25 | M26: =M23/M25 | ... U26: =U23/U25
E27: Operating Cash Flow | F27: 555.226 | G27: 538.277 | H27: 645.573 | I27: 700.338 | J27: 726.26 | K27: 798.905 | L27: =L29-L28 | M27: =M29-M28 | N27: =N29-N28 | O27: =O29-O28 | P27: =P29-P28 | Q27: =Q29-Q28 | R27: =R29-R28 | S27: =S29-S28 | ... U27: =U29-U28
E28: Capex / productive assets | F28: -61.325 | G28: -51.156 | H28: -60.786 | I28: -85.681 | J28: -108.806 | K28: -116.04 | L28: =-L4*0.045 | M28: =-M4*0.044 | N28: =-N4*0.043 | O28: =-O4*0.042 | P28: =-P4*0.041 | Q28: =-Q4*0.04 | R28: =-R4*0.04 | S28: =-S4*0.04 | T28: =-T4*0.04 | U28: =-U4*0.04
E29: Free Cash Flow | F29: 493.901 | G29: 487.121 | H29: 584.787 | I29: 614.657 | J29: 617.454 | K29: 682.865 | L29: =L4*L30 | M29: =M4*M30 | N29: =N4*N30 | O29: =O4*O30 | P29: =P4*P30 | Q29: =Q4*Q30 | R29: =R4*R30 | S29: =S4*S30 | ... U29: =U4*U30
E30: FCF Margin | F30: =F29/F4 | G30: =G29/G4 | H30: =H29/H4 | I30: =I29/I4 | J30: =J29/J4 | K30: =K29/K4 | L30: 0.28 | M30: 0.285 | N30: 0.288 | O30: 0.29 | P30: 0.292 | Q30: 0.294 | R30: 0.295 | S30: 0.295 | T30: 0.295 | U30: 0.295
E31: Stock-Based Compensation | F31: 45.065 | G31: 56.003 | H31: 62.038 | I31: 63.501 | J31: 61.229 | K31: 70.414 | L31: =L4*L32 | M31: =M4*M32 | N31: =N4*N32 | O31: =O4*O32 | P31: =P4*P32 | Q31: =Q4*Q32 | R31: =R4*R32 | S31: =S4*S32 | ... U31: =U4*U32
E32: SBC % Revenue | F32: =F31/F4 | G32: =G31/G4 | H32: =H31/H4 | I32: =I31/I4 | J32: =J31/J4 | K32: =K31/K4 | L32: 0.03 | M32: 0.029 | N32: 0.028 | O32: 0.027 | P32: 0.0265 | Q32: 0.026 | R32: 0.0255 | S32: 0.025 | T32: 0.025 | U32: 0.025
E33: Owner FCF After SBC | F33: 448.836 | G33: 431.118 | H33: 522.749 | I33: 551.156 | J33: 556.225 | K33: 612.451 | L33: =L29-L31 | M33: =M29-M31 | N33: =N29-N31 | O33: =O29-O31 | P33: =P29-P31 | Q33: =Q29-Q31 | R33: =R29-R31 | S33: =S29-S31 | ... U33: =U29-U31
E34: Owner FCF Margin | F34: =F33/F4 | G34: =G33/G4 | H34: =H33/H4 | I34: =I33/I4 | J34: =J33/J4 | K34: =K33/K4 | L34: =L33/L4 | M34: =M33/M4 | ... U34: =U33/U4
E35: Cash + ST Investments | F35: 681.9 | G35: 503.3 | H35: 425.4 | I35: 423 | J35: 355.1 | K35: 285.267
E36: Gross Debt | F36: 574.5 | G36: 1982.4 | H36: 1612.7 | I36: 1366 | J36: 1368.3 | K36: 1369.216
E37: Operating Lease Liabilities | F37: 291.6 | G37: 237.8 | H37: 227.2 | I37: 208.6 | J37: 190.2 | K37: 184.441
E38: Net Debt Incl Leases | F38: 184.2 | G38: 1716.9 | H38: 1414.5 | I38: 1151.6 | J38: 1203.4 | K38: 1268.39
B43: DCF: Owner FCF After SBC
B44: Required return / WACC | C44: =WACC!B15
B45: Terminal growth | C45: 0.025
...

Sheet WACC
A1: WACC / Required Return Inputs
A2: Risk-free rate | B2: 0.0457 | C2: U.S. 10-year Treasury / FRED near model date; latest available close in run was May 22, 2026.
A3: Equity risk premium | B3: 0.05 | C3: Rounded U.S. ERP input; cross-check to Damodaran/Kroll style public ERP references.
A4: Beta | B4: 0.69 | C4: StockAnalysis/Yahoo beta cross-check; low beta does not capture AI/terminal relevance risk by itself.
A5: Company-specific risk premium | B5: 0.006 | C5: Judgmental premium for AI/workflow disruption and margin reset uncertainty.
A6: Cost of equity | B6: =B2+B3*B4+B5 | C6: CAPM plus company-specific premium.
A7: Pre-tax cost of debt | B7: 0.044 | C7: Blend of fixed notes and term facility; rounded from disclosed coupons/current borrowing cost.
A8: Tax rate | B8: 0.19 | C8: Normalized near management FY2026 guide of 18%-19%.
A9: After-tax cost of debt | B9: =B7*(1-B8) | C9: Formula.
A10: Market cap, $m | B10: 8452.0215 | C10: May 22, 2026 close price x 36.431M shares.
A11: Gross debt, $m | B11: 1369.216 | C11: Q2 FY2026 10-Q debt carrying value / principal bridge.
A12: Equity weight | B12: =B10/(B10+B11) | C12: Market value capital structure.
A13: Debt weight | B13: =B11/(B10+B11) | C13: Gross debt weight.
A14: Calculated WACC | B14: =B12*B6+B13*B9 | C14: Calculated result before rounding.
A15: Rounded required return | B15: 0.08 | C15: Used in base DCF; keeps the model conservative vs low observed beta.

Sheet Scenarios
B2: Bull / Base / Bear Scenario DCFs (full SBC haircut)
O4: Scenario | P4: Implied Price | Q4: 10Y Price CAGR | R4: Notes
O5: Bear | P5: =D26 | Q5: =D27 | R5: AI/seat pressure, low ASV growth, weaker FCF conversion; full SBC haircut.
O6: Base | P6: =D45 | Q6: =D46 | R6: Management FY26 guide, FY27 consensus, gradual fade, stable FCF margin; full SBC haircut.
O7: Bull | P7: =D64 | Q7: =D65 | R7: AI/data/workflow products extend ASV growth and incremental margins; full SBC haircut.
B10: Bear Case
C11: FY2025A | D11: FY2026E | E11: FY2027E | F11: FY2028E | G11: FY2029E | H11: FY2030E | I11: FY2031E | J11: FY2032E | K11: FY2033E | L11: FY2034E | M11: FY2035E
B12: Revenue growth | D12: 0.05 | E12: 0.04 | F12: 0.035 | G12: 0.03 | H12: 0.025 | I12: 0.023 | J12: 0.02 | K12: 0.02 | L12: 0.018 | M12: 0.015
B13: Revenue | C13: 2321.748 | D13: =C13*(1+D12) | E13: =D13*(1+E12) | F13: =E13*(1+F12) | G13: =F13*(1+G12) | H13: =G13*(1+H12) | I13: =H13*(1+I12) | J13: =I13*(1+J12) | K13: =J13*(1+K12) | ... M13: =L13*(1+M12)
B14: Reported FCF margin | D14: 0.26 | E14: 0.258 | F14: 0.256 | G14: 0.255 | H14: 0.255 | I14: 0.258 | J14: 0.26 | K14: 0.262 | L14: 0.264 | M14: 0.265
B15: Reported FCF | D15: =D13*D14 | E15: =E13*E14 | F15: =F13*F14 | G15: =G13*G14 | H15: =H13*H14 | I15: =I13*I14 | J15: =J13*J14 | K15: =K13*K14 | ... M15: =M13*M14
B16: SBC % revenue | D16: 0.035 | E16: 0.035 | F16: 0.034 | G16: 0.034 | H16: 0.033 | I16: 0.033 | J16: 0.032 | K16: 0.032 | L16: 0.031 | M16: 0.031
B17: SBC | D17: =D13*D16 | E17: =E13*E16 | F17: =F13*F16 | G17: =G13*G16 | H17: =H13*H16 | I17: =I13*I16 | J17: =J13*J16 | K17: =K13*K16 | ... M17: =M13*M16
B18: Owner FCF | D18: =D15-D17 | E18: =E15-E17 | F18: =F15-F17 | G18: =G15-G17 | H18: =H15-H17 | I18: =I15-I17 | J18: =J15-J17 | K18: =K15-K17 | ... M18: =M15-M17
B19: Discount factor | D19: =1/(1+$D$22)^1 | E19: =1/(1+$D$22)^2 | F19: =1/(1+$D$22)^3 | G19: =1/(1+$D$22)^4 | H19: =1/(1+$D$22)^5 | I19: =1/(1+$D$22)^6 | J19: =1/(1+$D$22)^7 | K19: =1/(1+$D$22)^8 | L19: =1/(1+$D$22)^9 | M19: =1/(1+$D$22)^10
B20: PV owner FCF | D20: =D18*D19 | E20: =E18*E19 | F20: =F18*F19 | G20: =G18*G19 | H20: =H18*H19 | I20: =I18*I19 | J20: =J18*J19 | K20: =K18*K19 | ... M20: =M18*M19
B21: Terminal growth | D21: 0.015
B22: Required return | D22: 0.095
B23: Terminal value | D23: =M18*(1+D21)/(D22-D21)
B24: Enterprise value | D24: =SUM(D20:M20)+D23/(1+D22)^10
B25: Equity value | D25: =D24-Valuation!$C$11
B26: Implied price | D26: =D25/Valuation!$C$6
B27: 10Y price CAGR vs current price | D27: =POWER(D26/Valuation!$C$4,1/10)-1
B29: Base Case
C30: FY2025A | D30: FY2026E | E30: FY2027E | F30: FY2028E | G30: FY2029E | H30: FY2030E | I30: FY2031E | J30: FY2032E | K30: FY2033E | L30: FY2034E | M30: FY2035E
B31: Revenue growth | D31: 0.059546514 | E31: 0.067479675 | F31: 0.055 | G31: 0.05 | H31: 0.046 | I31: 0.043 | J31: 0.04 | K31: 0.038 | L31: 0.036 | M31: 0.034
B32: Revenue | C32: 2321.748 | D32: =C32*(1+D31) | E32: =D32*(1+E31) | F32: =E32*(1+F31) | G32: =F32*(1+G31) | H32: =G32*(1+H31) | I32: =H32*(1+I31) | J32: =I32*(1+J31) | K32: =J32*(1+K31) | ... M32: =L32*(1+M31)
B33: Reported FCF margin | D33: 0.28 | E33: 0.285 | F33: 0.288 | G33: 0.29 | H33: 0.292 | I33: 0.294 | J33: 0.295 | K33: 0.295 | L33: 0.295 | M33: 0.295
B34: Reported FCF | D34: =D32*D33 | E34: =E32*E33 | F34: =F32*F33 | G34: =G32*G33 | H34: =H32*H33 | I34: =I32*I33 | J34: =J32*J33 | K34: =K32*K33 | ... M34: =M32*M33
B35: SBC % revenue | D35: 0.03 | E35: 0.029 | F35: 0.028 | G35: 0.027 | H35: 0.0265 | I35: 0.026 | J35: 0.0255 | K35: 0.025 | L35: 0.025 | M35: 0.025
B36: SBC | D36: =D32*D35 | E36: =E32*E35 | F36: =F32*F35 | G36: =G32*G35 | H36: =H32*H35 | I36: =I32*I35 | J36: =J32*J35 | K36: =K32*K35 | ... M36: =M32*M35
B37: Owner FCF | D37: =D34-D36 | E37: =E34-E36 | F37: =F34-F36 | G37: =G34-G36 | H37: =H34-H36 | I37: =I34-I36 | J37: =J34-J36 | K37: =K34-K36 | ... M37: =M34-M36
B38: Discount factor | D38: =1/(1+$D$41)^1 | E38: =1/(1+$D$41)^2 | F38: =1/(1+$D$41)^3 | G38: =1/(1+$D$41)^4 | H38: =1/(1+$D$41)^5 | I38: =1/(1+$D$41)^6 | J38: =1/(1+$D$41)^7 | K38: =1/(1+$D$41)^8 | L38: =1/(1+$D$41)^9 | M38: =1/(1+$D$41)^10
B39: PV owner FCF | D39: =D37*D38 | E39: =E37*E38 | F39: =F37*F38 | G39: =G37*G38 | H39: =H37*H38 | I39: =I37*I38 | J39: =J37*J38 | K39: =K37*K38 | ... M39: =M37*M38
B40: Terminal growth | D40: 0.025
B41: Required return | D41: 0.08
B42: Terminal value | D42: =M37*(1+D40)/(D41-D40)
B43: Enterprise value | D43: =SUM(D39:M39)+D42/(1+D41)^10
B44: Equity value | D44: =D43-Valuation!$C$11
B45: Implied price | D45: =D44/Valuation!$C$6
...

Sheet Actuals Source Audit
A1: Line item | B1: Fiscal period | C1: Model value | D1: Unit | E1: Primary SEC / company value | F1: Primary source | G1: SEC concept / accession | H1: StockAnalysis value | I1: StockAnalysis URL | J1: Other secondary value | K1: Other secondary URL | L1: Difference / discrepancy | M1: Resolution note | N1: Model cell
A2: Revenue | B2: FY2021 | C2: 1591.445 | D2: USD $m | E2: 1591.445 | F2: SEC company facts / 10-K / 10-Q | G2: RevenueFromContractWithCustomerExcludingAssessedTax | H2: 1591.445 | I2: https://stockanalysis.com/stocks/fds/financials/ | J2: 1591.445 | K2: https://www.macrotrends.net/ | L2: 0 or immaterial rounding. | M2: SEC/company filing used as source of truth; StockAnalysis used as secondary cross-check. | N2: Valuation!F4
A3: Revenue | B3: FY2022 | C3: 1843.892 | D3: USD $m | E3: 1843.892 | F3: SEC company facts / 10-K / 10-Q | G3: RevenueFromContractWithCustomerExcludingAssessedTax | H3: 1843.892 | I3: https://stockanalysis.com/stocks/fds/financials/ | J3: 1843.892 | K3: https://www.macrotrends.net/ | L3: 0 or immaterial rounding. | M3: SEC/company filing used as source of truth; StockAnalysis used as secondary cross-check. | N3: Valuation!G4
A4: Revenue | B4: FY2023 | C4: 2085.508 | D4: USD $m | E4: 2085.508 | F4: SEC company facts / 10-K / 10-Q | G4: RevenueFromContractWithCustomerExcludingAssessedTax | H4: 2085.508 | I4: https://stockanalysis.com/stocks/fds/financials/ | J4: 2085.508 | K4: https://www.macrotrends.net/ | L4: 0 or immaterial rounding. | M4: SEC/company filing used as source of truth; StockAnalysis used as secondary cross-check. | N4: Valuation!H4
A5: Revenue | B5: FY2024 | C5: 2203.056 | D5: USD $m | E5: 2203.056 | F5: SEC company facts / 10-K / 10-Q | G5: RevenueFromContractWithCustomerExcludingAssessedTax | H5: 2203.056 | I5: https://stockanalysis.com/stocks/fds/financials/ | J5: 2203.056 | K5: https://www.macrotrends.net/ | L5: 0 or immaterial rounding. | M5: SEC/company filing used as source of truth; StockAnalysis used as secondary cross-check. | N5: Valuation!I4
A6: Revenue | B6: FY2025 | C6: 2321.748 | D6: USD $m | E6: 2321.748 | F6: SEC company facts / 10-K / 10-Q | G6: RevenueFromContractWithCustomerExcludingAssessedTax | H6: 2321.748 | I6: https://stockanalysis.com/stocks/fds/financials/ | J6: 2321.748 | K6: https://www.macrotrends.net/ | L6: 0 or immaterial rounding. | M6: SEC/company filing used as source of truth; StockAnalysis used as secondary cross-check. | N6: Valuation!J4
A7: Revenue | B7: TTM 2/28/26 | C7: 2401.061 | D7: USD $m | E7: 2401.061 | F7: SEC company facts / 10-K / 10-Q | G7: RevenueFromContractWithCustomerExcludingAssessedTax | H7: 2401.061 | I7: https://stockanalysis.com/stocks/fds/financials/ | J7: 2401.061 | K7: https://www.macrotrends.net/ | L7: 0 or immaterial rounding. | M7: SEC/company filing used as source of truth; StockAnalysis used as secondary cross-check. | N7: Valuation!K4
A8: Gross Profit | B8: FY2021 | C8: 805.05 | D8: USD $m | E8: 805.05 | F8: SEC filings / StockAnalysis | G8: Revenue less cost of services; gross profit calculated where not explicitly tagged | H8: 805.05 | I8: https://stockanalysis.com/stocks/fds/financials/ | J8: 805.05 | K8: https://www.macrotrends.net/ | L8: 0 or immaterial rounding. | M8: SEC/company filing used as source of truth; StockAnalysis used as secondary cross-check. | N8: Valuation!F8
A9: Gross Profit | B9: FY2022 | C9: 972.79 | D9: USD $m | E9: 972.79 | F9: SEC filings / StockAnalysis | G9: Revenue less cost of services; gross profit calculated where not explicitly tagged | H9: 972.79 | I9: https://stockanalysis.com/stocks/fds/financials/ | J9: 972.79 | K9: https://www.macrotrends.net/ | L9: 0 or immaterial rounding. | M9: SEC/company filing used as source of truth; StockAnalysis used as secondary cross-check. | N9: Valuation!G8
A10: Gross Profit | B10: FY2023 | C10: 1112.3 | D10: USD $m | E10: 1112.3 | F10: SEC filings / StockAnalysis | G10: Revenue less cost of services; gross profit calculated where not explicitly tagged | H10: 1112.3 | I10: https://stockanalysis.com/stocks/fds/financials/ | J10: 1112.3 | K10: https://www.macrotrends.net/ | L10: 0 or immaterial rounding. | M10: SEC/company filing used as source of truth; StockAnalysis used as secondary cross-check. | N10: Valuation!H8
A11: Gross Profit | B11: FY2024 | C11: 1191.1 | D11: USD $m | E11: 1191.1 | F11: SEC filings / StockAnalysis | G11: Revenue less cost of services; gross profit calculated where not explicitly tagged | H11: 1191.1 | I11: https://stockanalysis.com/stocks/fds/financials/ | J11: 1191.1 | K11: https://www.macrotrends.net/ | L11: 0 or immaterial rounding. | M11: SEC/company filing used as source of truth; StockAnalysis used as secondary cross-check. | N11: Valuation!I8
A12: Gross Profit | B12: FY2025 | C12: 1224 | D12: USD $m | E12: 1224 | F12: SEC filings / StockAnalysis | G12: Revenue less cost of services; gross profit calculated where not explicitly tagged | H12: 1224 | I12: https://stockanalysis.com/stocks/fds/financials/ | J12: 1224 | K12: https://www.macrotrends.net/ | L12: 0 or immaterial rounding. | M12: SEC/company filing used as source of truth; StockAnalysis used as secondary cross-check. | N12: Valuation!J8
A13: Gross Profit | B13: TTM 2/28/26 | C13: 1247 | D13: USD $m | E13: 1247 | F13: SEC filings / StockAnalysis | G13: Revenue less cost of services; gross profit calculated where not explicitly tagged | H13: 1247 | I13: https://stockanalysis.com/stocks/fds/financials/ | J13: 1247 | K13: https://www.macrotrends.net/ | L13: 0 or immaterial rounding. | M13: SEC/company filing used as source of truth; StockAnalysis used as secondary cross-check. | N13: Valuation!K8
... A55: Diluted Shares | B55: TTM 2/28/26 | C55: 37.84 | D55: mm shares | E55: 37.84 | F55: SEC company facts; TTM estimated from EPS | G55: WeightedAverageNumberOfDilutedSharesOutstanding | H55: 37.84 | I55: https://stockanalysis.com/stocks/fds/financials/ | J55: 37.84 | K55: https://www.macrotrends.net/ | L55: 0 or immaterial rounding. | M55: SEC/company filing used as source of truth; StockAnalysis used as secondary cross-check. | N55: Valuation!K25
A56: Cash + ST Investments | B56: FY2021 | C56: 681.9 | D56: USD $m | E56: 681.9 | F56: SEC balance sheet | G56: CashAndCashEquivalentsAtCarryingValue plus short-term investments where available | H56: 681.9 | I56: https://stockanalysis.com/stocks/fds/financials/balance-sheet/ | J56: N/A | K56: N/A | L56: 0 or immaterial rounding. | M56: SEC/company filing used as source of truth; StockAnalysis used as secondary cross-check. | N56: Valuation!F35
A57: Cash + ST Investments | B57: FY2022 | C57: 503.3 | D57: USD $m | E57: 503.3 | F57: SEC balance sheet | G57: CashAndCashEquivalentsAtCarryingValue plus short-term investments where available | H57: 503.3 | I57: https://stockanalysis.com/stocks/fds/financials/balance-sheet/ | J57: N/A | K57: N/A | L57: 0 or immaterial rounding. | M57: SEC/company filing used as source of truth; StockAnalysis used as secondary cross-check. | N57: Valuation!G35
A58: Cash + ST Investments | B58: FY2023 | C58: 425.4 | D58: USD $m | E58: 425.4 | F58: SEC balance sheet | G58: CashAndCashEquivalentsAtCarryingValue plus short-term investments where available | H58: 425.4 | I58: https://stockanalysis.com/stocks/fds/financials/balance-sheet/ | J58: N/A | K58: N/A | L58: 0 or immaterial rounding. | M58: SEC/company filing used as source of truth; StockAnalysis used as secondary cross-check. | N58: Valuation!H35
A59: Cash + ST Investments | B59: FY2024 | C59: 423 | D59: USD $m | E59: 423 | F59: SEC balance sheet | G59: CashAndCashEquivalentsAtCarryingValue plus short-term investments where available | H59: 423 | I59: https://stockanalysis.com/stocks/fds/financials/balance-sheet/ | J59: N/A | K59: N/A | L59: 0 or immaterial rounding. | M59: SEC/company filing used as source of truth; StockAnalysis used as secondary cross-check. | N59: Valuation!I35
A60: Cash + ST Investments | B60: FY2025 | C60: 355.1 | D60: USD $m | E60: 355.1 | F60: SEC balance sheet | G60: CashAndCashEquivalentsAtCarryingValue plus short-term investments where available | H60: 355.1 | I60: https://stockanalysis.com/stocks/fds/financials/balance-sheet/ | J60: N/A | K60: N/A | L60: 0 or immaterial rounding. | M60: SEC/company filing used as source of truth; StockAnalysis used as secondary cross-check. | N60: Valuation!J35
A61: Cash + ST Investments | B61: TTM 2/28/26 | C61: 285.267 | D61: USD $m | E61: 285.267 | F61: SEC balance sheet | G61: CashAndCashEquivalentsAtCarryingValue plus short-term investments where available | H61: 285.267 | I61: https://stockanalysis.com/stocks/fds/financials/balance-sheet/ | J61: N/A | K61: N/A | L61: 0 or immaterial rounding. | M61: SEC/company filing used as source of truth; StockAnalysis used as secondary cross-check. | N61: Valuation!K35
A62: Gross Debt | B62: FY2021 | C62: 574.5 | D62: USD $m | E62: 574.5 | F62: SEC balance sheet and debt footnote | G62: LongTermDebtCurrent plus LongTermDebtNoncurrent / debt tables | H62: 574.5 | I62: https://stockanalysis.com/stocks/fds/financials/balance-sheet/ | J62: N/A | K62: N/A | L62: 0 or immaterial rounding. | M62: SEC/company filing used as source of truth; StockAnalysis used as secondary cross-check. | N62: Valuation!F36
A63: Gross Debt | B63: FY2022 | C63: 1982.4 | D63: USD $m | E63: 1982.4 | F63: SEC balance sheet and debt footnote | G63: LongTermDebtCurrent plus LongTermDebtNoncurrent / debt tables | H63: 1982.4 | I63: https://stockanalysis.com/stocks/fds/financials/balance-sheet/ | J63: N/A | K63: N/A | L63: 0 or immaterial rounding. | M63: SEC/company filing used as source of truth; StockAnalysis used as secondary cross-check. | N63: Valuation!G36
A64: Gross Debt | B64: FY2023 | C64: 1612.7 | D64: USD $m | E64: 1612.7 | F64: SEC balance sheet and debt footnote | G64: LongTermDebtCurrent plus LongTermDebtNoncurrent / debt tables | H64: 1612.7 | I64: https://stockanalysis.com/stocks/fds/financials/balance-sheet/ | J64: N/A | K64: N/A | L64: 0 or immaterial rounding. | M64: SEC/company filing used as source of truth; StockAnalysis used as secondary cross-check. | N64: Valuation!H36
A65: Gross Debt | B65: FY2024 | C65: 1366 | D65: USD $m | E65: 1366 | F65: SEC balance sheet and debt footnote | G65: LongTermDebtCurrent plus LongTermDebtNoncurrent / debt tables | H65: 1366 | I65: https://stockanalysis.com/stocks/fds/financials/balance-sheet/ | J65: N/A | K65: N/A | L65: 0 or immaterial rounding. | M65: SEC/company filing used as source of truth; StockAnalysis used as secondary cross-check. | N65: Valuation!I36
A66: Gross Debt | B66: FY2025 | C66: 1368.3 | D66: USD $m | E66: 1368.3 | F66: SEC balance sheet and debt footnote | G66: LongTermDebtCurrent plus LongTermDebtNoncurrent / debt tables | H66: 1368.3 | I66: https://stockanalysis.com/stocks/fds/financials/balance-sheet/ | J66: N/A | K66: N/A | L66: 0 or immaterial rounding. | M66: SEC/company filing used as source of truth; StockAnalysis used as secondary cross-check. | N66: Valuation!J36
A67: Gross Debt | B67: TTM 2/28/26 | C67: 1369.216 | D67: USD $m | E67: 1369.216 | F67: SEC balance sheet and debt footnote | G67: LongTermDebtCurrent plus LongTermDebtNoncurrent / debt tables | H67: 1369.216 | I67: https://stockanalysis.com/stocks/fds/financials/balance-sheet/ | J67: N/A | K67: N/A | L67: 0 or immaterial rounding. | M67: SEC/company filing used as source of truth; StockAnalysis used as secondary cross-check. | N67: Valuation!K36
... A73: Operating Lease Liabilities | B73: TTM 2/28/26 | C73: 184.441 | D73: USD $m | E73: 184.441 | F73: SEC lease footnote / balance sheet | G73: OperatingLeaseLiability | H73: 184.441 | I73: https://stockanalysis.com/stocks/fds/financials/balance-sheet/ | J73: N/A | K73: N/A | L73: 0 or immaterial rounding. | M73: SEC/company filing used as source of truth; StockAnalysis used as secondary cross-check. | N73: Valuation!K37

Sheet Questions
B3: Questions
B5: Can FactSet sustain organic ASV growth above 6% after the Q2 FY2026 acceleration, or was it a temporary rebound?
B6: Will AI-enabled search and workflow tools expand paid usage, or will AI reduce the value of traditional workstation seats?
B7: Can GAAP operating margin return above 31%-32% while funding AI, cloud infrastructure, content, and product modernization?
B8: How much of reported free cash flow is true owner cash flow after capitalized internal-use software and stock-based compensation?
B9: Will LiquidityBook and Irwin deepen workflow lock-in, or will they mainly add amortization and integration complexity?
B10: Does CUSIP / market infrastructure remain a durable profit pool under legal, customer, and regulatory pressure?
B11: Can capital allocation improve after H1 FY2026 buybacks and dividends exceeded free cash flow?
B12: Will the new CEO/CFO team keep buybacks disciplined while handling 2027 and 2028 debt maturities?
B13: When will the IT general controls material weakness supporting revenue, A/R, and deferred revenue be fully remediated?
B14: What evidence would prove the bear case: ASV below 5%, flat users, margin compression, weak owner FCF, or AI cannibalization?

Sheet Sources
A1: Category | B1: Source | C1: Date / as-of | D1: Use in model
A2: Primary filing | B2: https://www.sec.gov/Archives/edgar/data/1013237/000162828025045769/fds-20250831.htm | C2: Filed 2025-10-22 | D2: FY2025 Form 10-K; annual statements, debt, leases, risks, controls.
A3: Primary filing | B3: https://www.sec.gov/Archives/edgar/data/1013237/000162828026022873/fds-20260228.htm | C3: Filed 2026-04-02 | D3: Q2 FY2026 Form 10-Q; latest balance sheet, H1 cash flow, debt, shares.
A4: Company release | B4: https://www.sec.gov/Archives/edgar/data/1013237/000162828026022203/fdsq22026earningsrelease.htm | C4: 2026-03-31 | D4: Q2 FY2026 release; ASV, guidance, adjusted margins, FCF definition.
A5: Primary XBRL | B5: https://data.sec.gov/api/xbrl/companyfacts/CIK0001013237.json | C5: Fetched 2026-05-26 | D5: SEC company facts extraction for annual actuals.
A6: Market data | B6: https://stockanalysis.com/stocks/fds/ | C6: As of 2026-05-22 close | D6: Price, quote timestamp, market cap, shares, analyst target.
A7: Secondary financials | B7: https://stockanalysis.com/stocks/fds/financials/ | C7: Pulled 2026-05-26 | D7: Income statement, TTM financials, margins, EPS cross-check.
A8: Secondary financials | B8: https://stockanalysis.com/stocks/fds/statistics/ | C8: Pulled 2026-05-26 | D8: EV, beta, valuation ratios, short interest, ROIC cross-check.
A9: Secondary financials | B9: https://stockanalysis.com/stocks/fds/forecast/ | C9: Pulled 2026-05-26 | D9: FY2026/FY2027 consensus revenue and EPS, price targets.
A10: Quote cross-check | B10: https://stooq.com/q/l/?s=fds.us&f=sd2t2ohlcv&h&e=csv | C10: Pulled 2026-05-26 | D10: Latest clean regular-session close: $232.00 on 2026-05-22.
A11: Rates | B11: https://fred.stlouisfed.org/series/DGS10 | C11: Latest available May 2026 observation | D11: 10-year Treasury / risk-free input cross-check.
A12: ERP | B12: https://pages.stern.nyu.edu/~adamodar/New_Home_Page/datafile/ctryprem.html | C12: Jan. 2026 public data | D12: Equity risk premium sanity check.
