Workbook

Sheet Valuation
A1: NIKE, Inc. (NKE) DCF Valuation Model
A2: USD in millions except per-share data; fiscal year ends May 31.
A3: Ticker | B3: NKE | D3: Company | E3: NIKE, Inc.
A4: Model date | B4: 2026-06-01 | D4: Current quote snapshot | E4: Yahoo Finance intraday, June 1, 2026, 11:16:24 AM EDT
A5: Primary filing anchor | B5: FY2025 10-K and Q3 FY2026 10-Q / earnings release | D5: Latest reported quarter | E5: Q3 FY2026, quarter ended Feb. 28, 2026
A8: Metric | B8: FY2021 | C8: FY2022 | D8: FY2023 | E8: FY2024 | F8: FY2025 | G8: TTM | H8: 2026E | I8: 2027E | J8: 2028E | K8: 2029E | L8: 2030E | M8: Source / formula
A9: Revenue | B9: 44538 | C9: 46710 | D9: 51217 | E9: 51362 | F9: 46309 | G9: =E44 | H9: =G9*(1+H10) | I9: =H9*(1+I10) | J9: =I9*(1+J10) | K9: =J9*(1+K10) | L9: =K9*(1+L10) | M9: SEC/company filings; TTM formula bridges FY2025 and 9M FY2026.
A10: Revenue growth | C10: =C9/B9-1 | D10: =D9/C9-1 | E10: =E9/D9-1 | F10: =F9/E9-1 | G10: =G9/F9-1 | H10: -0.01 | I10: 0.02 | J10: 0.04 | K10: 0.05 | L10: 0.05
A11: Gross profit | B11: 19962 | C11: 21479 | D11: 22292 | E11: 22887 | F11: 19790 | G11: =E45 | H11: =H9*H12 | I11: =I9*I12 | J11: =J9*J12 | K11: =K9*K12 | L11: =L9*L12 | M11: SEC/company filings; forecast margin ramps from tariff/reset trough.
A12: Gross margin | B12: =B11/B9 | C12: =C11/C9 | D12: =D11/D9 | E12: =E11/E9 | F12: =F11/F9 | G12: =G11/G9 | H12: 0.409 | I12: 0.42 | J12: 0.43 | K12: 0.437 | L12: 0.442
A13: SG&A | B13: =B11-B14 | C13: =C11-C14 | D13: =D11-D14 | E13: =E11-E14 | F13: =F11-F14 | G13: =E46 | H13: =H11-H14 | I13: =I11-I14 | J13: =J11-J14 | K13: =K11-K14 | L13: =L11-L14 | M13: Gross profit less EBIT; forecast implied by gross margin and EBIT margin.
A14: EBIT / operating income | B14: 6937 | C14: 6675 | D14: 5915 | E14: 6311 | F14: 3702 | G14: =E47 | H14: =H9*H15 | I14: =I9*I15 | J14: =J9*J15 | K14: =K9*K15 | L14: =L9*L15 | M14: Historical EBIT derived as gross profit less SG&A; no non-GAAP addbacks.
A15: EBIT margin | B15: =B14/B9 | C15: =C14/C9 | D15: =D14/D9 | E15: =E14/E9 | F15: =F14/F9 | G15: =G14/G9 | H15: 0.07 | I15: 0.085 | J15: 0.098 | K15: 0.107 | L15: 0.115
A16: Cash tax rate assumption | H16: 0.19 | I16: 0.19 | J16: 0.19 | K16: 0.19 | L16: 0.19 | M16: Forecast assumption, selected near normalized statutory/geographic mix.
A17: NOPAT | H17: =H14*(1-H16) | I17: =I14*(1-I16) | J17: =J14*(1-J16) | K17: =K14*(1-K16) | L17: =L14*(1-L16)
A18: D&A | G18: =E53 | H18: =H9*H19 | I18: =I9*I19 | J18: =J9*J19 | K18: =K9*K19 | L18: =L9*L19 | M18: D&A from FY2025 and 9M FY2026 filings; forecast as % of revenue.
A19: D&A / revenue | G19: =G18/G9 | H19: 0.016 | I19: 0.016 | J19: 0.016 | K19: 0.016 | L19: 0.016
A20: Operating cash flow | B20: 6657 | C20: 5188 | D20: 5841 | E20: 7429 | F20: 3698 | G20: =E48
A21: Capital expenditures | B21: 695 | C21: 758 | D21: 969 | E21: 812 | F21: 430 | G21: =E49 | H21: =H9*H22 | I21: =I9*I22 | J21: =J9*J22 | K21: =K9*K22 | L21: =L9*L22 | M21: SEC cash-flow statement; forecast as % of revenue.
A22: Capex / revenue | B22: =B21/B9 | C22: =C21/C9 | D22: =D21/D9 | E22: =E21/E9 | F22: =F21/F9 | G22: =G21/G9 | H22: 0.018 | I22: 0.018 | J22: 0.018 | K22: 0.018 | L22: 0.018
A23: Working-capital reinvestment | H23: =(H9-G9)*H24 | I23: =(I9-H9)*I24 | J23: =(J9-I9)*J24 | K23: =(K9-J9)*K24 | L23: =(L9-K9)*L24 | M23: Forecast reinvestment based on incremental revenue, not reported FCF.
A24: WC / incremental revenue | H24: 0.06 | I24: 0.06 | J24: 0.06 | K24: 0.06 | L24: 0.06
A25: FCF / owner earnings | B25: =B20-B21 | C25: =C20-C21 | D25: =D20-D21 | E25: =E20-E21 | F25: =F20-F21 | G25: =E50 | H25: =H17+H18-H21-H23 | I25: =I17+I18-I21-I23 | J25: =J17+J18-J21-J23 | K25: =K17+K18-K21-K23 | L25: =L17+L18-L21-L23 | M25: Historical reported FCF equals OCF less capex; forecast unlevered owner earnings.
A26: FCF margin | B26: =B25/B9 | C26: =C25/C9 | D26: =D25/D9 | E26: =E25/E9 | F26: =F25/F9 | G26: =G25/G9 | H26: =H25/H9 | I26: =I25/I9 | ... L26: =L25/L9
A27: Stock-based compensation | B27: 611 | C27: 638 | D27: 755 | E27: 804 | F27: 709 | G27: =E51
A28: Diluted shares (M) | B28: 1609.4 | C28: 1610.8 | D28: 1569.8 | E28: 1529.7 | F28: 1487.6 | G28: =E52 | H28: =G28*0.998 | I28: =H28*0.998 | J28: =I28*0.998 | K28: =J28*0.998 | L28: =K28*0.998 | M28: SEC diluted average shares; market snapshot uses current class A+B count.
A29: Diluted EPS | B29: 3.56 | C29: 3.75 | D29: 3.23 | E29: 3.73 | F29: 2.16 | G29: 1.52 | H29: =H17/H28 | I29: =I17/I28 | J29: =J17/J28 | K29: =K17/K28 | L29: =L17/L28
A30: Cash and equivalents | B30: 9889 | C30: 8574 | D30: 7441 | E30: 9860 | F30: 7464 | G30: 6660 | M30: Latest balance-sheet cash at 2026-02-28.
A31: Short-term investments | B31: 3587 | C31: 4423 | D31: 3234 | E31: 1722 | F31: 1687 | G31: 1397 | M31: Latest current AFS / short-term investments at 2026-02-28.
A32: Debt excluding operating leases | B32: 9415 | C32: 9430 | D32: 8933 | E32: 8909 | F32: 7966 | G32: 8029 | M32: Current debt plus long-term debt, excluding leases.
A33: Operating lease liabilities | B33: 3305 | C33: 3227 | D33: 3214 | E33: 3219 | F33: 3052 | G33: 3149 | M33: Operating lease liabilities disclosed separately.
A34: Net debt / (cash), excluding leases | B34: =B32-B30-B31 | C34: =C32-C30-C31 | D34: =D32-D30-D31 | E34: =E32-E30-E31 | F34: =F32-F30-F31 | G34: =G32-G30-G31
A35: Lease-adjusted net debt / (cash) | B35: =B34+B33 | C35: =C34+C33 | D35: =D34+D33 | E35: =E34+E33 | F35: =F34+F33 | G35: =G34+G33
A36: Dividends paid | B36: 1638 | C36: 1837 | D36: 2012 | E36: 2169 | F36: 2300
A37: Share repurchases | B37: 608 | C37: 4014 | D37: 5480 | E37: 4250 | F37: 2985
A38: Inventories | B38: 6854 | C38: 8420 | D38: 8454 | E38: 7519 | F38: 7489 | G38: 7487 | M38: Latest balance-sheet inventory at 2026-02-28.
A39: Inventory / revenue | B39: =B38/B9 | C39: =C38/C9 | D39: =D38/D9 | E39: =E38/E9 | F39: =F38/F9 | G39: =F38/G9
A42: TTM bridge and latest-quarter anchors
A43: Metric | B43: FY2025 | C43: 9M FY2026 | D43: 9M FY2025 | E43: TTM formula | F43: Source note
A44: Revenue | B44: 46309 | C44: 35426 | D44: 35212 | E44: =B44+C44-D44 | F44: FY2025 10-K plus Q3 FY2026 10-Q / earnings-release bridge.
...

Sheet WACC
A1: WACC / Required Return
A2: The DCF uses scenario-specific required returns. Mechanical WACC is shown as a cross-check.
A4: Input | B4: Value | C4: Formula / Source | D4: Notes
A5: Risk-free rate | B5: 0.0445 | C5: FRED DGS10; latest complete observation 2026-05-28 | D5: 10Y Treasury used as U.S. discount-rate anchor.
A6: Equity risk premium | B6: 0.05 | C6: Model assumption | D6: Mature U.S./global consumer discretionary company.
A7: Levered beta | B7: 1.12 | C7: Yahoo Finance 5Y monthly beta | D7: Vendor beta used as a public cross-check.
A8: Cost of equity | B8: =B5+B6*B7 | C8: =B5+B6*B7 | D8: CAPM output.
A9: Pre-tax cost of debt | B9: 0.048 | C9: Model assumption / public debt cost proxy | D9: Rounded cost for investment-grade debt stack.
A10: Tax rate | B10: 0.19 | C10: Forecast assumption | D10: Near base-case normalized cash tax rate.
A11: After-tax cost of debt | B11: =B9*(1-B10) | C11: =B9*(1-B10) | D11: Tax-adjusted debt cost.
A12: Market value of equity | B12: ='Valuation'!$B$60 | C12: ='Valuation'!$B$60 | D12: Static quote snapshot times total shares.
A13: Debt value | B13: ='Valuation'!$B$63 | C13: ='Valuation'!$B$63 | D13: Current + long-term debt, excluding operating leases.
A14: Equity weight | B14: =B12/(B12+B13) | C14: =B12/(B12+B13) | D14: Market-value capital structure.
A15: Debt weight | B15: =B13/(B12+B13) | C15: =B13/(B12+B13) | D15: Debt as share of debt plus equity.
A16: Mechanical WACC | B16: =B8*B14+B11*B15 | C16: =B8*B14+B11*B15 | D16: Cross-check; below selected return because NIKE is mostly equity-financed.
A17: Selected base discount rate | B17: 0.095 | C17: Model judgment | D17: Used on Valuation and Base scenario.
A18: Bear required return | B18: 0.105 | C18: Model judgment | D18: Higher uncertainty / weaker recovery case.
A19: Bull required return | B19: 0.0875 | C19: Model judgment | D19: Lower uncertainty if brand momentum and margin recovery are visible.
A23: Debt and lease treatment
A24: Item | B24: Value | C24: Use in model | D24: Rationale
A25: Debt excluding leases | B25: ='Valuation'!$B$63 | C25: Included in EV bridge | D25: Debt from latest 10-Q balance sheet.
A26: Cash and short-term investments | B26: ='Valuation'!$B$61+'Valuation'!$B$62 | C26: Netted against debt | D26: Liquid balance-sheet offsets.
A27: Operating leases | B27: ='Valuation'!$B$64 | C27: Shown separately | D27: Lease-adjusted EV disclosed, but base DCF equity bridge excludes leases to avoid double counting rent expense.

Sheet Scenarios
A1: Bear / Base / Bull Scenarios
A2: Operating-case DCF scenarios using TTM revenue as the starting point and explicit 5-year forecast mechanics.
A4: Scenario | B4: 2026E growth | C4: 2027E growth | D4: 2028E growth | E4: 2029E growth | F4: 2030E growth | G4: 5Y revenue CAGR | H4: Y5 EBIT margin | I4: Tax rate | J4: D&A / revenue | K4: Capex / revenue | L4: WC / incr rev | M4: Discount rate | N4: Terminal growth | O4: Implied EV | P4: Equity value | Q4: Shares (M) | R4: Value / share | S4: Upside / downside | T4: 5Y price CAGR
A5: Bear | B5: -0.02 | C5: 0 | D5: 0.01 | E5: 0.02 | F5: 0.025 | G5: =((1+B5)*(1+C5)*(1+D5)*(1+E5)*(1+F5))^(1/5)-1 | H5: 0.07 | I5: 0.22 | J5: 0.015 | K5: 0.016 | L5: 0.08 | M5: 0.105 | N5: 0.015 | O5: =B29 | P5: =B31 | Q5: 1490 | R5: =B33 | S5: =R5/'Valuation'!$B$58-1 | T5: =(R5/'Valuation'!$B$58)^(1/5)-1
A6: Base | B6: -0.01 | C6: 0.02 | D6: 0.04 | E6: 0.05 | F6: 0.05 | G6: =((1+B6)*(1+C6)*(1+D6)*(1+E6)*(1+F6))^(1/5)-1 | H6: 0.115 | I6: 0.19 | J6: 0.016 | K6: 0.018 | L6: 0.06 | M6: 0.095 | N6: 0.025 | O6: =B53 | P6: =B55 | Q6: 1480.887 | R6: =B57 | S6: =R6/'Valuation'!$B$58-1 | T6: =(R6/'Valuation'!$B$58)^(1/5)-1
A7: Bull | B7: 0.02 | C7: 0.05 | D7: 0.07 | E7: 0.07 | F7: 0.06 | G7: =((1+B7)*(1+C7)*(1+D7)*(1+E7)*(1+F7))^(1/5)-1 | H7: 0.145 | I7: 0.18 | J7: 0.016 | K7: 0.02 | L7: 0.05 | M7: 0.0875 | N7: 0.03 | O7: =B77 | P7: =B79 | Q7: 1460 | R7: =B81 | S7: =R7/'Valuation'!$B$58-1 | T7: =(R7/'Valuation'!$B$58)^(1/5)-1
A12: Bear detailed DCF
B13: 2026E | C13: 2027E | D13: 2028E | E13: 2029E | F13: 2030E
A14: Revenue growth | B14: =$B$5 | C14: =$C$5 | D14: =$D$5 | E14: =$E$5 | F14: =$F$5
A15: Revenue | B15: ='Valuation'!$G$9*(1+B14) | C15: =B15*(1+C14) | D15: =C15*(1+D14) | E15: =D15*(1+E14) | F15: =E15*(1+F14)
A16: EBIT margin | B16: ='Valuation'!$G$15+($H$5-'Valuation'!$G$15)*1/5 | C16: ='Valuation'!$G$15+($H$5-'Valuation'!$G$15)*2/5 | D16: ='Valuation'!$G$15+($H$5-'Valuation'!$G$15)*3/5 | E16: ='Valuation'!$G$15+($H$5-'Valuation'!$G$15)*4/5 | F16: ='Valuation'!$G$15+($H$5-'Valuation'!$G$15)*5/5
A17: EBIT | B17: =B15*B16 | C17: =C15*C16 | D17: =D15*D16 | E17: =E15*E16 | F17: =F15*F16
A18: Tax rate | B18: =$I$5 | C18: =$I$5 | D18: =$I$5 | E18: =$I$5 | F18: =$I$5
A19: NOPAT | B19: =B17*(1-B18) | C19: =C17*(1-C18) | D19: =D17*(1-D18) | E19: =E17*(1-E18) | F19: =F17*(1-F18)
A20: D&A | B20: =B15*$J$5 | C20: =C15*$J$5 | D20: =D15*$J$5 | E20: =E15*$J$5 | F20: =F15*$J$5
A21: Capex | B21: =B15*$K$5 | C21: =C15*$K$5 | D21: =D15*$K$5 | E21: =E15*$K$5 | F21: =F15*$K$5
A22: Working-capital reinvestment | B22: =(B15-'Valuation'!$G$9)*$L$5 | C22: =(C15-B15)*$L$5 | D22: =(D15-C15)*$L$5 | E22: =(E15-D15)*$L$5 | F22: =(F15-E15)*$L$5
A23: Unlevered FCF | B23: =B19+B20-B21-B22 | C23: =C19+C20-C21-C22 | D23: =D19+D20-D21-D22 | E23: =E19+E20-E21-E22 | F23: =F19+F20-F21-F22
A24: Discount factor | B24: =1/(1+$M$5)^1 | C24: =1/(1+$M$5)^2 | D24: =1/(1+$M$5)^3 | E24: =1/(1+$M$5)^4 | F24: =1/(1+$M$5)^5
A25: PV FCF | B25: =B23*B24 | C25: =C23*C24 | D25: =D23*D24 | E25: =E23*E24 | F25: =F23*F24
A26: Terminal FCF | F26: =F23*(1+$N$5)
A27: Terminal value | F27: =F26/($M$5-$N$5)
A28: PV terminal value | F28: =F27*F24
A29: Implied EV | B29: =SUM(B25:F25)+F28
A30: Net debt / (cash) | B30: ='Valuation'!$B$65
A31: Equity value | B31: =B29-B30
A32: Shares | B32: =$Q$5
A33: Value / share | B33: =B31/B32
A36: Base detailed DCF
B37: 2026E | C37: 2027E | D37: 2028E | E37: 2029E | F37: 2030E
A38: Revenue growth | B38: =$B$6 | C38: =$C$6 | D38: =$D$6 | E38: =$E$6 | F38: =$F$6
A39: Revenue | B39: ='Valuation'!$G$9*(1+B38) | C39: =B39*(1+C38) | D39: =C39*(1+D38) | E39: =D39*(1+E38) | F39: =E39*(1+F38)
A40: EBIT margin | B40: ='Valuation'!$G$15+($H$6-'Valuation'!$G$15)*1/5 | C40: ='Valuation'!$G$15+($H$6-'Valuation'!$G$15)*2/5 | D40: ='Valuation'!$G$15+($H$6-'Valuation'!$G$15)*3/5 | E40: ='Valuation'!$G$15+($H$6-'Valuation'!$G$15)*4/5 | F40: ='Valuation'!$G$15+($H$6-'Valuation'!$G$15)*5/5
A41: EBIT | B41: =B39*B40 | C41: =C39*C40 | D41: =D39*D40 | E41: =E39*E40 | F41: =F39*F40
A42: Tax rate | B42: =$I$6 | C42: =$I$6 | D42: =$I$6 | E42: =$I$6 | F42: =$I$6
A43: NOPAT | B43: =B41*(1-B42) | C43: =C41*(1-C42) | D43: =D41*(1-D42) | E43: =E41*(1-E42) | F43: =F41*(1-F42)
A44: D&A | B44: =B39*$J$6 | C44: =C39*$J$6 | D44: =D39*$J$6 | E44: =E39*$J$6 | F44: =F39*$J$6
A45: Capex | B45: =B39*$K$6 | C45: =C39*$K$6 | D45: =D39*$K$6 | E45: =E39*$K$6 | F45: =F39*$K$6
A46: Working-capital reinvestment | B46: =(B39-'Valuation'!$G$9)*$L$6 | C46: =(C39-B39)*$L$6 | D46: =(D39-C39)*$L$6 | E46: =(E39-D39)*$L$6 | F46: =(F39-E39)*$L$6
A47: Unlevered FCF | B47: =B43+B44-B45-B46 | C47: =C43+C44-C45-C46 | D47: =D43+D44-D45-D46 | E47: =E43+E44-E45-E46 | F47: =F43+F44-F45-F46
...

Sheet Actuals Source Audit
A1: Actuals Source Audit
A2: Reported actuals are anchored to SEC/company filings. Secondary sources are used as cross-checks, not as source of truth.
A4: Line item | B4: FY2021 | C4: FY2022 | D4: FY2023 | E4: FY2024 | F4: FY2025 | G4: TTM / latest | H4: Q3 / 9M FY2026 | I4: Primary source | J4: Secondary check | K4: Discrepancy / note
A5: Revenue | B5: 44538 | C5: 46710 | D5: 51217 | E5: 51362 | F5: 46309 | G5: 46523 | H5: Q3 11,279; 9M 35,426 | I5: FY2025 10-K; Q3 FY2026 10-Q / release | J5: StockAnalysis financials/TTM revenue | K5: SEC wins; TTM bridges FY2025 plus 9M FY2026 less 9M FY2025.
A6: Gross profit | B6: 19962 | C6: 21479 | D6: 22292 | E6: 22887 | F6: 19790 | G6: 18987 | H6: Q3 4,530; 9M 14,518 | I6: FY2025 10-K; Q3 FY2026 release | J6: Company earnings schedules | K6: Gross margin at Q3 FY2026 remained pressured by tariffs/channel mix.
A7: Gross margin | B7: 44.8% | C7: 46.0% | D7: 43.5% | E7: 44.6% | F7: 42.7% | G7: 40.8% | H7: Q3 40.2%; 9M 41.0% | I7: Company filings / release | J7: Nike IR schedules | K7: Model uses filing values; secondary sites may round.
A8: EBIT / operating income | B8: 6937 | C8: 6675 | D8: 5915 | E8: 6311 | F8: 3702 | G8: 2807 | H8: 9M 2,486 derived | I8: Derived as gross profit less SG&A | J8: StockAnalysis income statement | K8: NIKE filing presentation emphasizes income before tax/net income; model uses GP-SG&A for EBIT consistency.
A9: Net income | B9: 5727 | C9: 6046 | D9: 5070 | E9: 5700 | F9: 3219 | G9: 2250 | H9: Q3 520; 9M 2,039 | I9: FY2025 10-K; Q3 FY2026 10-Q / release | J9: Yahoo / StockAnalysis EPS and net income | K9: TTM net income cross-check approximates vendor TTM EPS of about $1.52.
A10: Operating cash flow | B10: 6657 | C10: 5188 | D10: 5841 | E10: 7429 | F10: 3698 | G10: 1694 | H10: 9M 1,231 | I10: FY2025 10-K; Q3 FY2026 10-Q | J10: StockAnalysis cash-flow statement | K10: Working-capital timing makes TTM OCF unusually weak.
A11: Capital expenditures | B11: 695 | C11: 758 | D11: 969 | E11: 812 | F11: 430 | G11: 646 | H11: 9M 546 | I11: FY2025 10-K; Q3 FY2026 10-Q | J11: StockAnalysis cash-flow statement | K11: Reported capex, not maintenance-only capex.
A12: Free cash flow | B12: 5962 | C12: 4430 | D12: 4872 | E12: 6617 | F12: 3268 | G12: 1048 | H12: 9M 685 | I12: OCF less capex from filings | J12: StockAnalysis / company cash-flow schedules | K12: Reported FCF differs from unlevered forecast owner earnings.
A13: Stock-based compensation | B13: 611 | C13: 638 | D13: 755 | E13: 804 | F13: 709 | G13: 720 | H13: Q3 194; 9M 555 | I13: FY2025 10-K; Q3 FY2026 10-Q | J13: Company cash-flow statement | K13: SBC included as a cash-flow addback; dilution captured through shares.
A14: Diluted shares (M) | B14: 1609.4 | C14: 1610.8 | D14: 1569.8 | E14: 1529.7 | F14: 1487.6 | G14: 1480.4 | H14: Q3 1,481.6; 9M 1,480.4 | I14: FY2025 10-K; Q3 FY2026 release | J14: Yahoo / StockAnalysis shares | K14: Valuation denominator uses current Class A + Class B outstanding.
A15: Diluted EPS | B15: 3.56 | C15: 3.75 | D15: 3.23 | E15: 3.73 | F15: 2.16 | G15: 1.52 | H15: Q3 0.35; 9M 1.38 | I15: FY2025 10-K; Q3 FY2026 release | J15: Yahoo / StockAnalysis EPS | K15: Vendor EPS can differ by exact TTM denominator.
A16: Cash and equivalents | B16: 9889 | C16: 8574 | D16: 7441 | E16: 9860 | F16: 7464 | G16: 6660 | H16: Latest 6,660 | I16: Q3 FY2026 10-Q balance sheet | J16: Yahoo / StockAnalysis balance sheet | K16: Latest balance sheet used in EV bridge.
A17: Short-term investments | B17: 3587 | C17: 4423 | D17: 3234 | E17: 1722 | F17: 1687 | G17: 1397 | H17: Latest 1,397 | I17: Q3 FY2026 10-Q balance sheet | J17: SEC/company balance sheet | K17: Current AFS debt securities / short-term investments.
A18: Debt excluding leases | B18: 9415 | C18: 9430 | D18: 8933 | E18: 8909 | F18: 7966 | G18: 8029 | H18: 999 current + 7,030 long term | I18: Q3 FY2026 10-Q balance sheet | J18: Yahoo / StockAnalysis balance sheet | K18: Operating leases disclosed separately.
A19: Operating leases | B19: 3305 | C19: 3227 | D19: 3214 | E19: 3219 | F19: 3052 | G19: 3149 | H19: 493 current + 2,656 noncurrent | I19: Q3 FY2026 10-Q balance sheet | J19: SEC/company footnotes | K19: Shown as lease-adjusted EV, not base DCF net debt.
A20: Inventories | B20: 6854 | C20: 8420 | D20: 8454 | E20: 7519 | F20: 7489 | G20: 7487 | H20: Latest 7,487 | I20: Q3 FY2026 10-Q balance sheet | J20: Company balance sheet | K20: Inventory reserve/markdown risk remains central to gross-margin recovery.
A21: Dividends paid | B21: 1638 | C21: 1837 | D21: 2012 | E21: 2169 | F21: 2300 | H21: Quarterly dividend $0.41 | I21: FY2025 10-K; Yahoo dividend data | J21: Yahoo Finance | K21: Dividend sustainability depends on FCF normalization.
A22: Share repurchases | B22: 608 | C22: 4014 | D22: 5480 | E22: 4250 | F22: 2985 | H22: Buybacks slowed | I22: FY2025 10-K | J22: Company filings | K22: Buyback capacity reduced while FCF is depressed.
A23: Sales-related reserves | E23: 1282 | F23: 1834 | I23: FY2025 10-K reserve disclosures | J23: SEC filing only | K23: Important quality flag: return/markdown reserves expanded.
A24: Sales returns reserve | E24: 799 | F24: 1277 | I24: FY2025 10-K reserve disclosures | J24: SEC filing only | K24: Reserve normalization is a margin and revenue-quality question.
A25: Inventory reserve | E25: 155 | F25: 233 | I25: FY2025 10-K reserve disclosures | J25: SEC filing only | K25: Supports cautious gross-margin recovery assumptions.

Sheet Questions
A1: Underwriting Questions
A2: Questions to update before relying on the model output as an investment view.
A4: Area | B4: Question | C4: Base-case dependency | D4: KPI / evidence to watch | E4: Source
A5: Digital reset | B5: Can NIKE Brand Digital return to growth without relying on markdown-heavy traffic? | C5: Base case assumes Direct stops being a drag by FY2027. | D5: Digital revenue growth, return rates, promo cadence, app engagement. | E5: Quarterly releases / transcript
A6: Wholesale | B6: Is wholesale growth sell-through driven, or just channel refill after prior cleanup? | C6: Base case assumes healthier wholesale with limited channel stuffing. | D6: Wholesale growth vs inventories/receivables, partner commentary. | E6: 10-Q / earnings call
A7: Gross margin | B7: How much of the tariff and markdown pressure is temporary versus structural? | C7: Base case ramps gross margin from low-40s toward 44% by FY2030. | D7: Gross margin bridge, reserve movements, freight/tariff commentary. | E7: 10-Q / release
A8: Product cycle | B8: Are running, basketball, women's and Jordan product launches large enough to regain cultural momentum? | C8: Base case assumes low-single-digit revenue recovery after FY2026. | D8: Search/social data, sell-outs, athlete events, category growth. | E8: Company / channel checks
A9: China | B9: Can Greater China stabilize without a sharp price/promo tradeoff? | C9: Base case embeds stabilization, not a full China boom. | D9: China revenue, local brand share, inventory quality. | E9: Quarterly releases
A10: Converse | B10: Does Converse remain a small drag or require a deeper brand reset? | C10: Base case does not assign a separate Converse re-rating. | D10: Converse revenue declines, margin, management actions. | E10: Quarterly schedules
A11: Working capital | B11: Does FCF recover with earnings, or are inventory and AR timing issues still absorbing cash? | C11: Base case assumes modest reinvestment tied to growth. | D11: OCF conversion, inventory days, receivable days. | E11: Cash-flow statement
A12: Capital returns | B12: Is the dividend prioritized over buybacks while reported FCF is depressed? | C12: Base value does not require aggressive buybacks. | D12: Dividend coverage, repurchases, net cash/debt. | E12: 10-Q / 10-K
A13: Share count | B13: Will buybacks resume enough to offset SBC and reduce the denominator? | C13: Base model assumes slight annual dilution reduction. | D13: Average diluted shares and class A/B outstanding. | E13: SEC filings
A14: Valuation | B14: At the current market EV, is the market underwriting a 13%+ Y5 EBIT margin or faster revenue recovery? | C14: Reverse DCF says today's price needs a cleaner recovery than the base case. | D14: Forward consensus changes, margin guidance, estimate revisions. | E14: Consensus / model
A15: Competition | B15: Are Adidas, On, Hoka, Lululemon and New Balance taking permanent share in key categories? | C15: Base case assumes NIKE regains some, not all, momentum. | D15: Competitor growth, wholesale shelf space, category share. | E15: Competitor reports
A16: Accounting quality | B16: Do sales returns, sales-related reserves, and inventory reserves normalize? | C16: Base case assumes reserve pressure fades by FY2027-FY2028. | D16: Reserve balances, markdown commentary, returns allowance. | E16: 10-K footnotes

Sheet Sources
A1: Sources
A2: Primary filings govern reported actuals; secondary sources are used for market data and cross-checks.
A4: Source | B4: URL | C4: Used for | D4: Accessed / as of | E4: Notes
A5: SEC FY2025 Form 10-K | B5: https://www.sec.gov/Archives/edgar/data/320187/000032018725000047/0000320187-25-000047-index.html | C5: FY2021-FY2025 annual actuals, balance sheet, cash flow, reserves | D5: 2026-06-01 | E5: Accession 0000320187-25-000047; filed 2025-07-17; period ended 2025-05-31.
A6: SEC Q3 FY2026 Form 10-Q | B6: https://www.sec.gov/Archives/edgar/data/320187/000032018726000037/0000320187-26-000037-index.html | C6: Latest quarter, 9M FY2026, balance sheet, shares | D6: 2026-06-01 | E6: Accession 0000320187-26-000037; filed 2026-04-01; period ended 2026-02-28.
A7: NIKE Q3 FY2026 earnings release | B7: https://investors.nike.com/investors/news-events-and-reports/investor-news/investor-news-details/2026/NIKE-Inc--Reports-Fiscal-2026-Third-Quarter-Results/default.aspx | C7: Revenue, gross margin, channel commentary, Q3 EPS | D7: 2026-06-01 | E7: Company release dated 2026-03-31.
A8: NIKE Investor Relations | B8: https://investors.nike.com/investors/news-events-and-reports/default.aspx | C8: Quarterly earnings materials, annual report links, event calendar | D8: 2026-06-01 | E8: Used to verify Q4 FY2026 results were scheduled for 2026-06-30 and not yet reported as of model date.
A9: Yahoo Finance NKE quote | B9: https://finance.yahoo.com/quote/NKE/ | C9: Share price, market cap, beta, dividend, EPS, target estimate cross-check | D9: 2026-06-01 11:16:24 AM EDT snapshot | E9: Workbook uses $45.85 quote; market data is time-sensitive.
A10: MarketBeat NKE | B10: https://www.marketbeat.com/stocks/NYSE/NKE/ | C10: Secondary quote, consensus rating/target cross-check | D10: 2026-06-01 | E10: Vendor quote/market cap can differ by timestamp and share denominator.
A11: StockAnalysis NKE | B11: https://stockanalysis.com/stocks/nke/ | C11: Secondary financials, TTM revenue, market cap and analyst estimate cross-check | D11: 2026-06-01 | E11: Secondary data can lag or round; SEC/company filings prevail.
A12: FRED DGS10 | B12: https://fred.stlouisfed.org/series/DGS10/ | C12: Risk-free-rate input | D12: Latest complete observation 2026-05-28 | E12: 10Y Treasury constant maturity yield of 4.45%.
A13: Stooq NKE quote CSV | B13: https://stooq.com/q/l/?s=nke.us&f=sd2t2ohlcv&h&e=csv | C13: Quote cross-check | D13: 2026-06-01 | E13: Prior snapshot around $45.76 used as reasonableness check; workbook uses refreshed Yahoo snapshot.
A14: SEC company landing page | B14: https://www.sec.gov/edgar/browse/?CIK=0000320187 | C14: Latest filing chronology | D14: 2026-06-01 | E14: Used to verify latest 10-Q and later non-operating filings.
